{
  "version": 8,
  "blockIdVersion": 11,
  "anchorX": 0,
  "anchorY": 0,
  "anchorZ": 0,
  "blocks": [
    {
      "x": -32,
      "y": -1,
      "z": -5,
      "name": "Rock_Lime_Brick_Smooth"
    },
    {
      "x": -32,
      "y": -1,
      "z": -4,
      "name": "Rock_Lime_Brick_Smooth"
    },
    {
      "x": -32,
      "y": -1,
      "z": -3,
      "name": "Rock_Lime_Brick_Smooth"
    },
    {
      "x": -32,
      "y": -1,
      "z": -2,
      "name": "Rock_Lime_Brick_Smooth"
    },
    {
      "x": -32,
      "y": -1,
      "z": -1,
      "name": "Rock_Lime_Brick_Smooth"
    },
    {
      "x": -32,
      "y": -1,
      "z": 0,
      "name": "Rock_Lime_Brick_Smooth"
    },
    {
      "x": -32,
      "y": -1,
      "z": 1,
      "name": "Rock_Lime_Brick"
    },
    {
      "x": -32,
      "y": -1,
      "z": 2,
      "name": "Rock_Lime_Brick_Smooth"
    },
    {
      "x": -32,
      "y": -1,
      "z": 3,
      "name": "Rock_Lime_Brick"
    },
    {
      "x": -32,
      "y": -1,
      "z": 4,
      "name": "Rock_Lime_Brick_Smooth"
    },
    {
      "x": -32,
      "y": -1,
      "z": 5,
      "name": "Rock_Lime_Brick_Smooth"
    },
    {
      "x": -31,
      "y": -1,
      "z": -9,
      "name": "Rock_Lime_Brick_Smooth"
    },
    {
      "x": -31,
      "y": -1,
      "z": -8,
      "name": "Rock_Lime_Brick_Smooth"
    },
    {
      "x": -31,
      "y": -1,
      "z": -7,
      "name": "Rock_Lime_Brick_Smooth"
    },
    {
      "x": -31,
      "y": -1,
      "z": -6,
      "name": "Rock_Lime_Brick_Smooth"
    },
    {
      "x": -31,
      "y": -1,
      "z": -5,
      "name": "Rock_Lime_Brick"
    },
    {
      "x": -31,
      "y": -1,
      "z": -4,
      "name": "Rock_Lime_Brick_Smooth"
    },
    {
      "x": -31,
      "y": -1,
      "z": -3,
      "name": "Rock_Lime_Brick_Smooth"
    },
    {
      "x": -31,
      "y": -1,
      "z": -2,
      "name": "Rock_Lime_Brick_Smooth"
    },
    {
      "x": -31,
      "y": -1,
      "z": -1,
      "name": "Rock_Lime_Brick_Smooth"
    },
    {
      "x": -31,
      "y": -1,
      "z": 0,
      "name": "Rock_Lime_Brick_Smooth"
    },
    {
      "x": -31,
      "y": -1,
      "z": 1,
      "name": "Rock_Lime_Brick_Smooth"
    },
    {
      "x": -31,
      "y": -1,
      "z": 2,
      "name": "Rock_Lime_Brick_Smooth"
    },
    {
      "x": -31,
      "y": -1,
      "z": 3,
      "name": "Rock_Lime_Brick_Smooth"
    },
    {
      "x": -31,
      "y": -1,
      "z": 4,
      "name": "Rock_Lime_Brick_Smooth"
    },
    {
      "x": -31,
      "y": -1,
      "z": 5,
      "name": "Rock_Lime_Brick_Smooth"
    },
    {
      "x": -31,
      "y": -1,
      "z": 6,
      "name": "Rock_Lime_Brick_Smooth"
    },
    {
      "x": -31,
      "y": -1,
      "z": 7,
      "name": "Rock_Lime_Brick_Smooth"
    },
    {
      "x": -31,
      "y": -1,
      "z": 8,
      "name": "Rock_Lime_Brick_Smooth"
    },
    {
      "x": -31,
      "y": -1,
      "z": 9,
      "name": "Rock_Lime_Brick_Smooth"
    },
    {
      "x": -30,
      "y": -1,
      "z": -12,
      "name": "Rock_Lime_Brick_Smooth"
    },
    {
      "x": -30,
      "y": -1,
      "z": -11,
      "name": "Rock_Lime_Brick_Smooth"
    },
    {
      "x": -30,
      "y": -1,
      "z": -10,
      "name": "Rock_Lime_Brick_Smooth"
    },
    {
      "x": -30,
      "y": -1,
      "z": -9,
      "name": "Rock_Lime_Brick_Smooth"
    },
    {
      "x": -30,
      "y": -1,
      "z": -8,
      "name": "Rock_Lime_Brick_Smooth"
    },
    {
      "x": -30,
      "y": -1,
      "z": -7,
      "name": "Rock_Lime_Brick_Smooth"
    },
    {
      "x": -30,
      "y": -1,
      "z": -6,
      "name": "Rock_Lime_Brick_Smooth"
    },
    {
      "x": -30,
      "y": -1,
      "z": -5,
      "name": "Rock_Lime_Brick"
    },
    {
      "x": -30,
      "y": -1,
      "z": -4,
      "name": "Rock_Lime_Brick_Smooth"
    },
    {
      "x": -30,
      "y": -1,
      "z": -3,
      "name": "Rock_Lime_Brick_Smooth"
    },
    {
      "x": -30,
      "y": -1,
      "z": -2,
      "name": "Rock_Lime_Brick_Smooth"
    },
    {
      "x": -30,
      "y": -1,
      "z": -1,
      "name": "Rock_Lime_Brick_Smooth"
    },
    {
      "x": -30,
      "y": -1,
      "z": 0,
      "name": "Rock_Lime_Brick_Smooth"
    },
    {
      "x": -30,
      "y": -1,
      "z": 1,
      "name": "Rock_Lime_Brick_Smooth"
    },
    {
      "x": -30,
      "y": -1,
      "z": 2,
      "name": "Rock_Lime_Brick_Smooth"
    },
    {
      "x": -30,
      "y": -1,
      "z": 3,
      "name": "Rock_Lime_Brick_Smooth"
    },
    {
      "x": -30,
      "y": -1,
      "z": 4,
      "name": "Rock_Lime_Brick_Smooth"
    },
    {
      "x": -30,
      "y": -1,
      "z": 5,
      "name": "Rock_Lime_Brick_Smooth"
    },
    {
      "x": -30,
      "y": -1,
      "z": 6,
      "name": "Rock_Lime_Brick"
    },
    {
      "x": -30,
      "y": -1,
      "z": 7,
      "name": "Rock_Lime_Brick"
    },
    {
      "x": -30,
      "y": -1,
      "z": 8,
      "name": "Rock_Lime_Brick_Smooth"
    },
    {
      "x": -30,
      "y": -1,
      "z": 9,
      "name": "Rock_Lime_Brick_Smooth"
    },
    {
      "x": -30,
      "y": -1,
      "z": 10,
      "name": "Rock_Lime_Brick_Smooth"
    },
    {
      "x": -30,
      "y": -1,
      "z": 11,
      "name": "Rock_Lime_Brick_Smooth"
    },
    {
      "x": -30,
      "y": -1,
      "z": 12,
      "name": "Rock_Lime_Brick_Smooth"
    },
    {
      "x": -29,
      "y": -1,
      "z": -14,
      "name": "Rock_Lime_Brick"
    },
    {
      "x": -29,
      "y": -1,
      "z": -13,
      "name": "Rock_Lime_Brick_Smooth"
    },
    {
      "x": -29,
      "y": -1,
      "z": -12,
      "name": "Rock_Lime_Brick_Smooth"
    },
    {
      "x": -29,
      "y": -1,
      "z": -11,
      "name": "Rock_Lime_Brick_Smooth"
    },
    {
      "x": -29,
      "y": -1,
      "z": -10,
      "name": "Rock_Lime_Brick"
    },
    {
      "x": -29,
      "y": -1,
      "z": -9,
      "name": "Rock_Lime_Brick_Smooth"
    },
    {
      "x": -29,
      "y": -1,
      "z": -8,
      "name": "Rock_Lime_Brick_Smooth"
    },
    {
      "x": -29,
      "y": -1,
      "z": -7,
      "name": "Rock_Lime_Brick"
    },
    {
      "x": -29,
      "y": -1,
      "z": -6,
      "name": "Rock_Lime_Brick"
    },
    {
      "x": -29,
      "y": -1,
      "z": -5,
      "name": "Rock_Lime_Brick"
    },
    {
      "x": -29,
      "y": -1,
      "z": -4,
      "name": "Rock_Lime_Brick_Smooth"
    },
    {
      "x": -29,
      "y": -1,
      "z": -3,
      "name": "Rock_Lime_Brick_Smooth"
    },
    {
      "x": -29,
      "y": -1,
      "z": -2,
      "name": "Rock_Lime_Brick_Smooth"
    },
    {
      "x": -29,
      "y": -1,
      "z": -1,
      "name": "Rock_Lime_Brick_Smooth"
    },
    {
      "x": -29,
      "y": -1,
      "z": 0,
      "name": "Rock_Lime_Brick"
    },
    {
      "x": -29,
      "y": -1,
      "z": 1,
      "name": "Rock_Lime_Brick_Smooth"
    },
    {
      "x": -29,
      "y": -1,
      "z": 2,
      "name": "Rock_Lime_Brick_Smooth"
    },
    {
      "x": -29,
      "y": -1,
      "z": 3,
      "name": "Rock_Lime_Brick_Smooth"
    },
    {
      "x": -29,
      "y": -1,
      "z": 4,
      "name": "Rock_Lime_Brick_Smooth"
    },
    {
      "x": -29,
      "y": -1,
      "z": 5,
      "name": "Rock_Lime_Brick_Smooth"
    },
    {
      "x": -29,
      "y": -1,
      "z": 6,
      "name": "Rock_Lime_Brick_Smooth"
    },
    {
      "x": -29,
      "y": -1,
      "z": 7,
      "name": "Rock_Lime_Brick_Smooth"
    },
    {
      "x": -29,
      "y": -1,
      "z": 8,
      "name": "Rock_Lime_Brick_Smooth"
    },
    {
      "x": -29,
      "y": -1,
      "z": 9,
      "name": "Rock_Lime_Brick_Smooth"
    },
    {
      "x": -29,
      "y": -1,
      "z": 10,
      "name": "Rock_Lime_Brick_Smooth"
    },
    {
      "x": -29,
      "y": -1,
      "z": 11,
      "name": "Rock_Lime_Brick_Smooth"
    },
    {
      "x": -29,
      "y": -1,
      "z": 12,
      "name": "Rock_Lime_Brick_Smooth"
    },
    {
      "x": -29,
      "y": -1,
      "z": 13,
      "name": "Rock_Lime_Brick_Smooth"
    },
    {
      "x": -29,
      "y": -1,
      "z": 14,
      "name": "Rock_Lime_Brick_Smooth"
    },
    {
      "x": -28,
      "y": -1,
      "z": -16,
      "name": "Rock_Lime_Brick"
    },
    {
      "x": -28,
      "y": -1,
      "z": -15,
      "name": "Rock_Lime_Brick"
    },
    {
      "x": -28,
      "y": -1,
      "z": -14,
      "name": "Rock_Lime_Brick_Smooth"
    },
    {
      "x": -28,
      "y": -1,
      "z": -13,
      "name": "Rock_Lime_Brick_Smooth"
    },
    {
      "x": -28,
      "y": -1,
      "z": -12,
      "name": "Rock_Lime_Brick"
    },
    {
      "x": -28,
      "y": -1,
      "z": -11,
      "name": "Rock_Lime_Brick"
    },
    {
      "x": -28,
      "y": -1,
      "z": -10,
      "name": "Rock_Lime_Brick_Smooth"
    },
    {
      "x": -28,
      "y": -1,
      "z": -9,
      "name": "Rock_Lime_Brick_Smooth"
    },
    {
      "x": -28,
      "y": -1,
      "z": -8,
      "name": "Rock_Lime_Brick_Smooth"
    },
    {
      "x": -28,
      "y": -1,
      "z": -7,
      "name": "Rock_Lime_Brick"
    },
    {
      "x": -28,
      "y": -1,
      "z": -6,
      "name": "Rock_Lime_Brick_Smooth"
    },
    {
      "x": -28,
      "y": -1,
      "z": -5,
      "name": "Rock_Lime_Brick_Smooth"
    },
    {
      "x": -28,
      "y": -1,
      "z": -4,
      "name": "Rock_Lime_Brick"
    },
    {
      "x": -28,
      "y": 0,
      "z": -4,
      "name": "Rock_Lime_Brick_Smooth"
    },
    {
      "x": -28,
      "y": -1,
      "z": -3,
      "name": "Rock_Lime_Brick_Smooth"
    },
    {
      "x": -28,
      "y": 0,
      "z": -3,
      "name": "Rock_Lime_Brick_Smooth"
    },
    {
      "x": -28,
      "y": -1,
      "z": -2,
      "name": "Rock_Lime_Brick_Smooth"
    },
    {
      "x": -28,
      "y": 0,
      "z": -2,
      "name": "Rock_Lime_Brick_Smooth"
    },
    {
      "x": -28,
      "y": -1,
      "z": -1,
      "name": "Rock_Lime_Brick_Smooth"
    },
    {
      "x": -28,
      "y": 0,
      "z": -1,
      "name": "Rock_Lime_Brick_Smooth"
    },
    {
      "x": -28,
      "y": -1,
      "z": 0,
      "name": "Rock_Lime_Brick_Smooth"
    },
    {
      "x": -28,
      "y": 0,
      "z": 0,
      "name": "Rock_Lime_Brick_Smooth"
    },
    {
      "x": -28,
      "y": -1,
      "z": 1,
      "name": "Rock_Lime_Brick_Smooth"
    },
    {
      "x": -28,
      "y": 0,
      "z": 1,
      "name": "Rock_Lime_Brick_Smooth"
    },
    {
      "x": -28,
      "y": -1,
      "z": 2,
      "name": "Rock_Lime_Brick_Smooth"
    },
    {
      "x": -28,
      "y": 0,
      "z": 2,
      "name": "Rock_Lime_Brick"
    },
    {
      "x": -28,
      "y": -1,
      "z": 3,
      "name": "Rock_Lime_Brick_Smooth"
    },
    {
      "x": -28,
      "y": 0,
      "z": 3,
      "name": "Rock_Lime_Brick_Smooth"
    },
    {
      "x": -28,
      "y": -1,
      "z": 4,
      "name": "Rock_Lime_Brick_Smooth"
    },
    {
      "x": -28,
      "y": 0,
      "z": 4,
      "name": "Rock_Lime_Brick"
    },
    {
      "x": -28,
      "y": -1,
      "z": 5,
      "name": "Rock_Lime_Brick_Smooth"
    },
    {
      "x": -28,
      "y": -1,
      "z": 6,
      "name": "Rock_Lime_Brick_Smooth"
    },
    {
      "x": -28,
      "y": -1,
      "z": 7,
      "name": "Rock_Lime_Brick_Smooth"
    },
    {
      "x": -28,
      "y": -1,
      "z": 8,
      "name": "Rock_Lime_Brick"
    },
    {
      "x": -28,
      "y": -1,
      "z": 9,
      "name": "Rock_Lime_Brick_Smooth"
    },
    {
      "x": -28,
      "y": -1,
      "z": 10,
      "name": "Rock_Lime_Brick_Smooth"
    },
    {
      "x": -28,
      "y": -1,
      "z": 11,
      "name": "Rock_Lime_Brick_Smooth"
    },
    {
      "x": -28,
      "y": -1,
      "z": 12,
      "name": "Rock_Lime_Brick_Smooth"
    },
    {
      "x": -28,
      "y": -1,
      "z": 13,
      "name": "Rock_Lime_Brick_Smooth"
    },
    {
      "x": -28,
      "y": -1,
      "z": 14,
      "name": "Rock_Lime_Brick"
    },
    {
      "x": -28,
      "y": -1,
      "z": 15,
      "name": "Rock_Lime_Brick"
    },
    {
      "x": -28,
      "y": -1,
      "z": 16,
      "name": "Rock_Lime_Brick_Smooth"
    },
    {
      "x": -27,
      "y": -1,
      "z": -17,
      "name": "Rock_Lime_Brick"
    },
    {
      "x": -27,
      "y": -1,
      "z": -16,
      "name": "Rock_Lime_Brick_Smooth"
    },
    {
      "x": -27,
      "y": -1,
      "z": -15,
      "name": "Rock_Lime_Brick_Smooth"
    },
    {
      "x": -27,
      "y": -1,
      "z": -14,
      "name": "Rock_Lime_Brick_Smooth"
    },
    {
      "x": -27,
      "y": -1,
      "z": -13,
      "name": "Rock_Lime_Brick_Smooth"
    },
    {
      "x": -27,
      "y": -1,
      "z": -12,
      "name": "Rock_Lime_Brick"
    },
    {
      "x": -27,
      "y": -1,
      "z": -11,
      "name": "Rock_Lime_Brick_Smooth"
    },
    {
      "x": -27,
      "y": -1,
      "z": -10,
      "name": "Rock_Lime_Brick_Smooth"
    },
    {
      "x": -27,
      "y": -1,
      "z": -9,
      "name": "Rock_Lime_Brick_Smooth"
    },
    {
      "x": -27,
      "y": -1,
      "z": -8,
      "name": "Rock_Lime_Brick_Smooth"
    },
    {
      "x": -27,
      "y": 0,
      "z": -8,
      "name": "Rock_Lime_Brick_Smooth"
    },
    {
      "x": -27,
      "y": -1,
      "z": -7,
      "name": "Rock_Lime_Brick_Smooth"
    },
    {
      "x": -27,
      "y": 0,
      "z": -7,
      "name": "Rock_Lime_Brick_Smooth"
    },
    {
      "x": -27,
      "y": -1,
      "z": -6,
      "name": "Rock_Lime_Brick_Smooth"
    },
    {
      "x": -27,
      "y": 0,
      "z": -6,
      "name": "Rock_Lime_Brick_Smooth"
    },
    {
      "x": -27,
      "y": -1,
      "z": -5,
      "name": "Rock_Lime_Brick_Smooth"
    },
    {
      "x": -27,
      "y": 0,
      "z": -5,
      "name": "Rock_Lime_Brick_Smooth"
    },
    {
      "x": -27,
      "y": -1,
      "z": -4,
      "name": "Rock_Lime_Brick_Smooth"
    },
    {
      "x": -27,
      "y": 0,
      "z": -4,
      "name": "Rock_Lime_Brick_Smooth"
    },
    {
      "x": -27,
      "y": -1,
      "z": -3,
      "name": "Rock_Lime_Brick_Smooth"
    },
    {
      "x": -27,
      "y": 0,
      "z": -3,
      "name": "Rock_Lime_Brick_Smooth"
    },
    {
      "x": -27,
      "y": -1,
      "z": -2,
      "name": "Rock_Lime_Brick"
    },
    {
      "x": -27,
      "y": 0,
      "z": -2,
      "name": "Rock_Lime_Brick"
    },
    {
      "x": -27,
      "y": -1,
      "z": -1,
      "name": "Rock_Lime_Brick_Smooth"
    },
    {
      "x": -27,
      "y": 0,
      "z": -1,
      "name": "Rock_Lime_Brick_Smooth"
    },
    {
      "x": -27,
      "y": -1,
      "z": 0,
      "name": "Rock_Lime_Brick"
    },
    {
      "x": -27,
      "y": 0,
      "z": 0,
      "name": "Rock_Lime_Brick_Smooth"
    },
    {
      "x": -27,
      "y": -1,
      "z": 1,
      "name": "Rock_Lime_Brick_Smooth"
    },
    {
      "x": -27,
      "y": 0,
      "z": 1,
      "name": "Rock_Lime_Brick"
    },
    {
      "x": -27,
      "y": -1,
      "z": 2,
      "name": "Rock_Lime_Brick_Smooth"
    },
    {
      "x": -27,
      "y": 0,
      "z": 2,
      "name": "Rock_Lime_Brick"
    },
    {
      "x": -27,
      "y": -1,
      "z": 3,
      "name": "Rock_Lime_Brick_Smooth"
    },
    {
      "x": -27,
      "y": 0,
      "z": 3,
      "name": "Rock_Lime_Brick_Smooth"
    },
    {
      "x": -27,
      "y": -1,
      "z": 4,
      "name": "Rock_Lime_Brick_Smooth"
    },
    {
      "x": -27,
      "y": 0,
      "z": 4,
      "name": "Rock_Lime_Brick_Smooth"
    },
    {
      "x": -27,
      "y": -1,
      "z": 5,
      "name": "Rock_Lime_Brick_Smooth"
    },
    {
      "x": -27,
      "y": 0,
      "z": 5,
      "name": "Rock_Lime_Brick_Smooth"
    },
    {
      "x": -27,
      "y": -1,
      "z": 6,
      "name": "Rock_Lime_Brick"
    },
    {
      "x": -27,
      "y": 0,
      "z": 6,
      "name": "Rock_Lime_Brick_Smooth"
    },
    {
      "x": -27,
      "y": -1,
      "z": 7,
      "name": "Rock_Lime_Brick_Smooth"
    },
    {
      "x": -27,
      "y": 0,
      "z": 7,
      "name": "Rock_Lime_Brick_Smooth"
    },
    {
      "x": -27,
      "y": -1,
      "z": 8,
      "name": "Rock_Lime_Brick"
    },
    {
      "x": -27,
      "y": 0,
      "z": 8,
      "name": "Rock_Lime_Brick_Smooth"
    },
    {
      "x": -27,
      "y": -1,
      "z": 9,
      "name": "Rock_Lime_Brick_Smooth"
    },
    {
      "x": -27,
      "y": -1,
      "z": 10,
      "name": "Rock_Lime_Brick_Smooth"
    },
    {
      "x": -27,
      "y": -1,
      "z": 11,
      "name": "Rock_Lime_Brick_Smooth"
    },
    {
      "x": -27,
      "y": -1,
      "z": 12,
      "name": "Rock_Lime_Brick_Smooth"
    },
    {
      "x": -27,
      "y": -1,
      "z": 13,
      "name": "Rock_Lime_Brick_Smooth"
    },
    {
      "x": -27,
      "y": -1,
      "z": 14,
      "name": "Rock_Lime_Brick_Smooth"
    },
    {
      "x": -27,
      "y": -1,
      "z": 15,
      "name": "Rock_Lime_Brick_Smooth"
    },
    {
      "x": -27,
      "y": -1,
      "z": 16,
      "name": "Rock_Lime_Brick_Smooth"
    },
    {
      "x": -27,
      "y": -1,
      "z": 17,
      "name": "Rock_Lime_Brick_Smooth"
    },
    {
      "x": -26,
      "y": -1,
      "z": -19,
      "name": "Rock_Lime_Brick_Smooth"
    },
    {
      "x": -26,
      "y": -1,
      "z": -18,
      "name": "Rock_Lime_Brick_Smooth"
    },
    {
      "x": -26,
      "y": -1,
      "z": -17,
      "name": "Rock_Lime_Brick_Smooth"
    },
    {
      "x": -26,
      "y": -1,
      "z": -16,
      "name": "Rock_Lime_Brick_Smooth"
    },
    {
      "x": -26,
      "y": -1,
      "z": -15,
      "name": "Rock_Lime_Brick"
    },
    {
      "x": -26,
      "y": -1,
      "z": -14,
      "name": "Rock_Lime_Brick_Smooth"
    },
    {
      "x": -26,
      "y": -1,
      "z": -13,
      "name": "Rock_Lime_Brick_Smooth"
    },
    {
      "x": -26,
      "y": -1,
      "z": -12,
      "name": "Rock_Lime_Brick_Smooth"
    },
    {
      "x": -26,
      "y": -1,
      "z": -11,
      "name": "Rock_Lime_Brick_Smooth"
    },
    {
      "x": -26,
      "y": 0,
      "z": -11,
      "name": "Rock_Lime_Brick_Smooth"
    },
    {
      "x": -26,
      "y": -1,
      "z": -10,
      "name": "Rock_Lime_Brick_Smooth"
    },
    {
      "x": -26,
      "y": 0,
      "z": -10,
      "name": "Rock_Lime_Brick"
    },
    {
      "x": -26,
      "y": -1,
      "z": -9,
      "name": "Rock_Lime_Brick_Smooth"
    },
    {
      "x": -26,
      "y": 0,
      "z": -9,
      "name": "Rock_Lime_Brick_Smooth"
    },
    {
      "x": -26,
      "y": -1,
      "z": -8,
      "name": "Rock_Lime_Brick_Smooth"
    },
    {
      "x": -26,
      "y": 0,
      "z": -8,
      "name": "Rock_Lime_Brick"
    },
    {
      "x": -26,
      "y": -1,
      "z": -7,
      "name": "Rock_Lime_Brick"
    },
    {
      "x": -26,
      "y": 0,
      "z": -7,
      "name": "Rock_Lime_Brick"
    },
    {
      "x": -26,
      "y": -1,
      "z": -6,
      "name": "Rock_Lime_Brick_Smooth"
    },
    {
      "x": -26,
      "y": 0,
      "z": -6,
      "name": "Rock_Lime_Brick_Smooth"
    },
    {
      "x": -26,
      "y": -1,
      "z": -5,
      "name": "Rock_Lime_Brick_Smooth"
    },
    {
      "x": -26,
      "y": 0,
      "z": -5,
      "name": "Rock_Lime_Brick_Smooth"
    },
    {
      "x": -26,
      "y": -1,
      "z": -4,
      "name": "Rock_Lime_Brick_Smooth"
    },
    {
      "x": -26,
      "y": 0,
      "z": -4,
      "name": "Rock_Lime_Brick_Smooth"
    },
    {
      "x": -26,
      "y": -1,
      "z": -3,
      "name": "Rock_Lime_Brick_Smooth"
    },
    {
      "x": -26,
      "y": 0,
      "z": -3,
      "name": "Rock_Lime_Brick_Smooth"
    },
    {
      "x": -26,
      "y": -1,
      "z": -2,
      "name": "Rock_Lime_Brick_Smooth"
    },
    {
      "x": -26,
      "y": 0,
      "z": -2,
      "name": "Rock_Lime_Brick_Smooth"
    },
    {
      "x": -26,
      "y": -1,
      "z": -1,
      "name": "Rock_Lime_Brick_Smooth"
    },
    {
      "x": -26,
      "y": 0,
      "z": -1,
      "name": "Rock_Lime_Brick_Smooth"
    },
    {
      "x": -26,
      "y": -1,
      "z": 0,
      "name": "Rock_Lime_Brick_Smooth"
    },
    {
      "x": -26,
      "y": 0,
      "z": 0,
      "name": "Rock_Lime_Brick_Smooth"
    },
    {
      "x": -26,
      "y": -1,
      "z": 1,
      "name": "Rock_Lime_Brick"
    },
    {
      "x": -26,
      "y": 0,
      "z": 1,
      "name": "Rock_Lime_Brick_Smooth"
    },
    {
      "x": -26,
      "y": -1,
      "z": 2,
      "name": "Rock_Lime_Brick"
    },
    {
      "x": -26,
      "y": 0,
      "z": 2,
      "name": "Rock_Lime_Brick_Smooth"
    },
    {
      "x": -26,
      "y": -1,
      "z": 3,
      "name": "Rock_Lime_Brick_Smooth"
    },
    {
      "x": -26,
      "y": 0,
      "z": 3,
      "name": "Rock_Lime_Brick_Smooth"
    },
    {
      "x": -26,
      "y": -1,
      "z": 4,
      "name": "Rock_Lime_Brick_Smooth"
    },
    {
      "x": -26,
      "y": 0,
      "z": 4,
      "name": "Rock_Lime_Brick_Smooth"
    },
    {
      "x": -26,
      "y": -1,
      "z": 5,
      "name": "Rock_Lime_Brick_Smooth"
    },
    {
      "x": -26,
      "y": 0,
      "z": 5,
      "name": "Rock_Lime_Brick_Smooth"
    },
    {
      "x": -26,
      "y": -1,
      "z": 6,
      "name": "Rock_Lime_Brick_Smooth"
    },
    {
      "x": -26,
      "y": 0,
      "z": 6,
      "name": "Rock_Lime_Brick"
    },
    {
      "x": -26,
      "y": -1,
      "z": 7,
      "name": "Rock_Lime_Brick"
    },
    {
      "x": -26,
      "y": 0,
      "z": 7,
      "name": "Rock_Lime_Brick_Smooth"
    },
    {
      "x": -26,
      "y": -1,
      "z": 8,
      "name": "Rock_Lime_Brick_Smooth"
    },
    {
      "x": -26,
      "y": 0,
      "z": 8,
      "name": "Rock_Lime_Brick_Smooth"
    },
    {
      "x": -26,
      "y": -1,
      "z": 9,
      "name": "Rock_Lime_Brick_Smooth"
    },
    {
      "x": -26,
      "y": 0,
      "z": 9,
      "name": "Rock_Lime_Brick"
    },
    {
      "x": -26,
      "y": -1,
      "z": 10,
      "name": "Rock_Lime_Brick_Smooth"
    },
    {
      "x": -26,
      "y": 0,
      "z": 10,
      "name": "Rock_Lime_Brick"
    },
    {
      "x": -26,
      "y": -1,
      "z": 11,
      "name": "Rock_Lime_Brick_Smooth"
    },
    {
      "x": -26,
      "y": 0,
      "z": 11,
      "name": "Rock_Lime_Brick_Smooth"
    },
    {
      "x": -26,
      "y": -1,
      "z": 12,
      "name": "Rock_Lime_Brick_Smooth"
    },
    {
      "x": -26,
      "y": -1,
      "z": 13,
      "name": "Rock_Lime_Brick_Smooth"
    },
    {
      "x": -26,
      "y": -1,
      "z": 14,
      "name": "Rock_Lime_Brick_Smooth"
    },
    {
      "x": -26,
      "y": -1,
      "z": 15,
      "name": "Rock_Lime_Brick_Smooth"
    },
    {
      "x": -26,
      "y": -1,
      "z": 16,
      "name": "Rock_Lime_Brick_Smooth"
    },
    {
      "x": -26,
      "y": -1,
      "z": 17,
      "name": "Rock_Lime_Brick_Smooth"
    },
    {
      "x": -26,
      "y": -1,
      "z": 18,
      "name": "Rock_Lime_Brick_Smooth"
    },
    {
      "x": -26,
      "y": -1,
      "z": 19,
      "name": "Rock_Lime_Brick_Smooth"
    },
    {
      "x": -25,
      "y": -1,
      "z": -20,
      "name": "Rock_Lime_Brick"
    },
    {
      "x": -25,
      "y": -1,
      "z": -19,
      "name": "Rock_Lime_Brick"
    },
    {
      "x": -25,
      "y": -1,
      "z": -18,
      "name": "Rock_Lime_Brick"
    },
    {
      "x": -25,
      "y": -1,
      "z": -17,
      "name": "Rock_Lime_Brick_Smooth"
    },
    {
      "x": -25,
      "y": -1,
      "z": -16,
      "name": "Rock_Lime_Brick_Smooth"
    },
    {
      "x": -25,
      "y": -1,
      "z": -15,
      "name": "Rock_Lime_Brick_Smooth"
    },
    {
      "x": -25,
      "y": -1,
      "z": -14,
      "name": "Rock_Lime_Brick_Smooth"
    },
    {
      "x": -25,
      "y": -1,
      "z": -13,
      "name": "Rock_Lime_Brick_Smooth"
    },
    {
      "x": -25,
      "y": 0,
      "z": -13,
      "name": "Rock_Lime_Brick_Smooth"
    },
    {
      "x": -25,
      "y": -1,
      "z": -12,
      "name": "Rock_Lime_Brick_Smooth"
    },
    {
      "x": -25,
      "y": 0,
      "z": -12,
      "name": "Rock_Lime_Brick_Smooth"
    },
    {
      "x": -25,
      "y": -1,
      "z": -11,
      "name": "Rock_Lime_Brick"
    },
    {
      "x": -25,
      "y": 0,
      "z": -11,
      "name": "Rock_Lime_Brick_Smooth"
    },
    {
      "x": -25,
      "y": -1,
      "z": -10,
      "name": "Rock_Lime_Brick_Smooth"
    },
    {
      "x": -25,
      "y": 0,
      "z": -10,
      "name": "Rock_Lime_Brick_Smooth"
    },
    {
      "x": -25,
      "y": -1,
      "z": -9,
      "name": "Rock_Lime_Brick_Smooth"
    },
    {
      "x": -25,
      "y": 0,
      "z": -9,
      "name": "Rock_Lime_Brick_Smooth"
    },
    {
      "x": -25,
      "y": -1,
      "z": -8,
      "name": "Rock_Lime_Brick_Smooth"
    },
    {
      "x": -25,
      "y": 0,
      "z": -8,
      "name": "Rock_Lime_Brick_Smooth"
    },
    {
      "x": -25,
      "y": -1,
      "z": -7,
      "name": "Rock_Lime_Brick_Smooth"
    },
    {
      "x": -25,
      "y": 0,
      "z": -7,
      "name": "Rock_Lime_Brick_Smooth"
    },
    {
      "x": -25,
      "y": -1,
      "z": -6,
      "name": "Rock_Lime_Brick_Smooth"
    },
    {
      "x": -25,
      "y": 0,
      "z": -6,
      "name": "Rock_Lime_Brick_Smooth"
    },
    {
      "x": -25,
      "y": -1,
      "z": -5,
      "name": "Rock_Lime_Brick_Smooth"
    },
    {
      "x": -25,
      "y": 0,
      "z": -5,
      "name": "Rock_Lime_Brick_Smooth"
    },
    {
      "x": -25,
      "y": -1,
      "z": -4,
      "name": "Rock_Lime_Brick_Smooth"
    },
    {
      "x": -25,
      "y": 0,
      "z": -4,
      "name": "Rock_Lime_Brick"
    },
    {
      "x": -25,
      "y": -1,
      "z": -3,
      "name": "Rock_Lime_Brick_Smooth"
    },
    {
      "x": -25,
      "y": 0,
      "z": -3,
      "name": "Rock_Lime_Brick_Smooth"
    },
    {
      "x": -25,
      "y": -1,
      "z": -2,
      "name": "Rock_Lime_Brick"
    },
    {
      "x": -25,
      "y": 0,
      "z": -2,
      "name": "Rock_Lime_Brick"
    },
    {
      "x": -25,
      "y": -1,
      "z": -1,
      "name": "Rock_Lime_Brick_Smooth"
    },
    {
      "x": -25,
      "y": 0,
      "z": -1,
      "name": "Rock_Lime_Brick_Smooth"
    },
    {
      "x": -25,
      "y": -1,
      "z": 0,
      "name": "Rock_Lime_Brick_Smooth"
    },
    {
      "x": -25,
      "y": 0,
      "z": 0,
      "name": "Rock_Lime_Brick_Smooth"
    },
    {
      "x": -25,
      "y": -1,
      "z": 1,
      "name": "Rock_Lime_Brick"
    },
    {
      "x": -25,
      "y": 0,
      "z": 1,
      "name": "Rock_Lime_Brick_Smooth"
    },
    {
      "x": -25,
      "y": -1,
      "z": 2,
      "name": "Rock_Lime_Brick_Smooth"
    },
    {
      "x": -25,
      "y": 0,
      "z": 2,
      "name": "Rock_Lime_Brick_Smooth"
    },
    {
      "x": -25,
      "y": -1,
      "z": 3,
      "name": "Rock_Lime_Brick"
    },
    {
      "x": -25,
      "y": 0,
      "z": 3,
      "name": "Rock_Lime_Brick_Smooth"
    },
    {
      "x": -25,
      "y": -1,
      "z": 4,
      "name": "Rock_Lime_Brick"
    },
    {
      "x": -25,
      "y": 0,
      "z": 4,
      "name": "Rock_Lime_Brick_Smooth"
    },
    {
      "x": -25,
      "y": -1,
      "z": 5,
      "name": "Rock_Lime_Brick_Smooth"
    },
    {
      "x": -25,
      "y": 0,
      "z": 5,
      "name": "Rock_Lime_Brick_Smooth"
    },
    {
      "x": -25,
      "y": -1,
      "z": 6,
      "name": "Rock_Lime_Brick_Smooth"
    },
    {
      "x": -25,
      "y": 0,
      "z": 6,
      "name": "Rock_Lime_Brick_Smooth"
    },
    {
      "x": -25,
      "y": -1,
      "z": 7,
      "name": "Rock_Lime_Brick_Smooth"
    },
    {
      "x": -25,
      "y": 0,
      "z": 7,
      "name": "Rock_Lime_Brick_Smooth"
    },
    {
      "x": -25,
      "y": -1,
      "z": 8,
      "name": "Rock_Lime_Brick_Smooth"
    },
    {
      "x": -25,
      "y": 0,
      "z": 8,
      "name": "Rock_Lime_Brick_Smooth"
    },
    {
      "x": -25,
      "y": -1,
      "z": 9,
      "name": "Rock_Lime_Brick_Smooth"
    },
    {
      "x": -25,
      "y": 0,
      "z": 9,
      "name": "Rock_Lime_Brick_Smooth"
    },
    {
      "x": -25,
      "y": -1,
      "z": 10,
      "name": "Rock_Lime_Brick_Smooth"
    },
    {
      "x": -25,
      "y": 0,
      "z": 10,
      "name": "Rock_Lime_Brick_Smooth"
    },
    {
      "x": -25,
      "y": -1,
      "z": 11,
      "name": "Rock_Lime_Brick_Smooth"
    },
    {
      "x": -25,
      "y": 0,
      "z": 11,
      "name": "Rock_Lime_Brick_Smooth"
    },
    {
      "x": -25,
      "y": -1,
      "z": 12,
      "name": "Rock_Lime_Brick_Smooth"
    },
    {
      "x": -25,
      "y": 0,
      "z": 12,
      "name": "Rock_Lime_Brick_Smooth"
    },
    {
      "x": -25,
      "y": -1,
      "z": 13,
      "name": "Rock_Lime_Brick_Smooth"
    },
    {
      "x": -25,
      "y": 0,
      "z": 13,
      "name": "Rock_Lime_Brick_Smooth"
    },
    {
      "x": -25,
      "y": -1,
      "z": 14,
      "name": "Rock_Lime_Brick"
    },
    {
      "x": -25,
      "y": -1,
      "z": 15,
      "name": "Rock_Lime_Brick_Smooth"
    },
    {
      "x": -25,
      "y": -1,
      "z": 16,
      "name": "Rock_Lime_Brick_Smooth"
    },
    {
      "x": -25,
      "y": -1,
      "z": 17,
      "name": "Rock_Lime_Brick_Smooth"
    },
    {
      "x": -25,
      "y": -1,
      "z": 18,
      "name": "Rock_Lime_Brick_Smooth"
    },
    {
      "x": -25,
      "y": -1,
      "z": 19,
      "name": "Rock_Lime_Brick_Smooth"
    },
    {
      "x": -25,
      "y": -1,
      "z": 20,
      "name": "Rock_Lime_Brick_Smooth"
    },
    {
      "x": -24,
      "y": -1,
      "z": -21,
      "name": "Rock_Lime_Brick"
    },
    {
      "x": -24,
      "y": -1,
      "z": -20,
      "name": "Rock_Lime_Brick_Smooth"
    },
    {
      "x": -24,
      "y": -1,
      "z": -19,
      "name": "Rock_Lime_Brick_Smooth"
    },
    {
      "x": -24,
      "y": -1,
      "z": -18,
      "name": "Rock_Lime_Brick"
    },
    {
      "x": -24,
      "y": -1,
      "z": -17,
      "name": "Rock_Lime_Brick_Smooth"
    },
    {
      "x": -24,
      "y": -1,
      "z": -16,
      "name": "Rock_Lime_Brick_Smooth"
    },
    {
      "x": -24,
      "y": -1,
      "z": -15,
      "name": "Rock_Lime_Brick"
    },
    {
      "x": -24,
      "y": 0,
      "z": -15,
      "name": "Rock_Lime_Brick_Smooth"
    },
    {
      "x": -24,
      "y": -1,
      "z": -14,
      "name": "Rock_Lime_Brick_Smooth"
    },
    {
      "x": -24,
      "y": 0,
      "z": -14,
      "name": "Rock_Lime_Brick_Smooth"
    },
    {
      "x": -24,
      "y": -1,
      "z": -13,
      "name": "Rock_Lime_Brick_Smooth"
    },
    {
      "x": -24,
      "y": 0,
      "z": -13,
      "name": "Rock_Lime_Brick_Smooth"
    },
    {
      "x": -24,
      "y": -1,
      "z": -12,
      "name": "Rock_Lime_Brick_Smooth"
    },
    {
      "x": -24,
      "y": 0,
      "z": -12,
      "name": "Rock_Lime_Brick_Smooth"
    },
    {
      "x": -24,
      "y": -1,
      "z": -11,
      "name": "Rock_Lime_Brick_Smooth"
    },
    {
      "x": -24,
      "y": 0,
      "z": -11,
      "name": "Rock_Lime_Brick_Smooth"
    },
    {
      "x": -24,
      "y": -1,
      "z": -10,
      "name": "Rock_Lime_Brick_Smooth"
    },
    {
      "x": -24,
      "y": 0,
      "z": -10,
      "name": "Rock_Lime_Brick_Smooth"
    },
    {
      "x": -24,
      "y": -1,
      "z": -9,
      "name": "Rock_Lime_Brick_Smooth"
    },
    {
      "x": -24,
      "y": 0,
      "z": -9,
      "name": "Rock_Lime_Brick_Smooth"
    },
    {
      "x": -24,
      "y": -1,
      "z": -8,
      "name": "Rock_Lime_Brick_Smooth"
    },
    {
      "x": -24,
      "y": 0,
      "z": -8,
      "name": "Rock_Lime_Brick_Smooth"
    },
    {
      "x": -24,
      "y": -1,
      "z": -7,
      "name": "Rock_Lime_Brick_Smooth"
    },
    {
      "x": -24,
      "y": 0,
      "z": -7,
      "name": "Rock_Lime_Brick_Smooth"
    },
    {
      "x": -24,
      "y": -1,
      "z": -6,
      "name": "Rock_Lime_Brick_Smooth"
    },
    {
      "x": -24,
      "y": 0,
      "z": -6,
      "name": "Rock_Lime_Brick_Smooth"
    },
    {
      "x": -24,
      "y": -1,
      "z": -5,
      "name": "Rock_Lime_Brick"
    },
    {
      "x": -24,
      "y": 0,
      "z": -5,
      "name": "Rock_Lime_Brick_Smooth"
    },
    {
      "x": -24,
      "y": -1,
      "z": -4,
      "name": "Rock_Lime_Brick_Smooth"
    },
    {
      "x": -24,
      "y": 0,
      "z": -4,
      "name": "Rock_Lime_Brick_Smooth"
    },
    {
      "x": -24,
      "y": 1,
      "z": -4,
      "name": "Rock_Lime_Brick_Smooth"
    },
    {
      "x": -24,
      "y": -1,
      "z": -3,
      "name": "Rock_Lime_Brick_Smooth"
    },
    {
      "x": -24,
      "y": 0,
      "z": -3,
      "name": "Rock_Lime_Brick_Smooth"
    },
    {
      "x": -24,
      "y": 1,
      "z": -3,
      "name": "Rock_Lime_Brick"
    },
    {
      "x": -24,
      "y": -1,
      "z": -2,
      "name": "Rock_Lime_Brick_Smooth"
    },
    {
      "x": -24,
      "y": 0,
      "z": -2,
      "name": "Rock_Lime_Brick"
    },
    {
      "x": -24,
      "y": 1,
      "z": -2,
      "name": "Rock_Lime_Brick_Smooth"
    },
    {
      "x": -24,
      "y": -1,
      "z": -1,
      "name": "Rock_Lime_Brick_Smooth"
    },
    {
      "x": -24,
      "y": 0,
      "z": -1,
      "name": "Rock_Lime_Brick_Smooth"
    },
    {
      "x": -24,
      "y": 1,
      "z": -1,
      "name": "Rock_Lime_Brick_Smooth"
    },
    {
      "x": -24,
      "y": -1,
      "z": 0,
      "name": "Rock_Lime_Brick_Smooth"
    },
    {
      "x": -24,
      "y": 0,
      "z": 0,
      "name": "Rock_Lime_Brick_Smooth"
    },
    {
      "x": -24,
      "y": 1,
      "z": 0,
      "name": "Rock_Lime_Brick_Smooth"
    },
    {
      "x": -24,
      "y": -1,
      "z": 1,
      "name": "Rock_Lime_Brick_Smooth"
    },
    {
      "x": -24,
      "y": 0,
      "z": 1,
      "name": "Rock_Lime_Brick_Smooth"
    },
    {
      "x": -24,
      "y": 1,
      "z": 1,
      "name": "Rock_Lime_Brick_Smooth"
    },
    {
      "x": -24,
      "y": -1,
      "z": 2,
      "name": "Rock_Lime_Brick"
    },
    {
      "x": -24,
      "y": 0,
      "z": 2,
      "name": "Rock_Lime_Brick_Smooth"
    },
    {
      "x": -24,
      "y": 1,
      "z": 2,
      "name": "Rock_Lime_Brick"
    },
    {
      "x": -24,
      "y": -1,
      "z": 3,
      "name": "Rock_Lime_Brick_Smooth"
    },
    {
      "x": -24,
      "y": 0,
      "z": 3,
      "name": "Rock_Lime_Brick_Smooth"
    },
    {
      "x": -24,
      "y": 1,
      "z": 3,
      "name": "Rock_Lime_Brick_Smooth"
    },
    {
      "x": -24,
      "y": -1,
      "z": 4,
      "name": "Rock_Lime_Brick_Smooth"
    },
    {
      "x": -24,
      "y": 0,
      "z": 4,
      "name": "Rock_Lime_Brick_Smooth"
    },
    {
      "x": -24,
      "y": 1,
      "z": 4,
      "name": "Rock_Lime_Brick_Smooth"
    },
    {
      "x": -24,
      "y": -1,
      "z": 5,
      "name": "Rock_Lime_Brick_Smooth"
    },
    {
      "x": -24,
      "y": 0,
      "z": 5,
      "name": "Rock_Lime_Brick"
    },
    {
      "x": -24,
      "y": -1,
      "z": 6,
      "name": "Rock_Lime_Brick_Smooth"
    },
    {
      "x": -24,
      "y": 0,
      "z": 6,
      "name": "Rock_Lime_Brick_Smooth"
    },
    {
      "x": -24,
      "y": -1,
      "z": 7,
      "name": "Rock_Lime_Brick_Smooth"
    },
    {
      "x": -24,
      "y": 0,
      "z": 7,
      "name": "Rock_Lime_Brick_Smooth"
    },
    {
      "x": -24,
      "y": -1,
      "z": 8,
      "name": "Rock_Lime_Brick_Smooth"
    },
    {
      "x": -24,
      "y": 0,
      "z": 8,
      "name": "Rock_Lime_Brick"
    },
    {
      "x": -24,
      "y": -1,
      "z": 9,
      "name": "Rock_Lime_Brick_Smooth"
    },
    {
      "x": -24,
      "y": 0,
      "z": 9,
      "name": "Rock_Lime_Brick_Smooth"
    },
    {
      "x": -24,
      "y": -1,
      "z": 10,
      "name": "Rock_Lime_Brick_Smooth"
    },
    {
      "x": -24,
      "y": 0,
      "z": 10,
      "name": "Rock_Lime_Brick_Smooth"
    },
    {
      "x": -24,
      "y": -1,
      "z": 11,
      "name": "Rock_Lime_Brick_Smooth"
    },
    {
      "x": -24,
      "y": 0,
      "z": 11,
      "name": "Rock_Lime_Brick"
    },
    {
      "x": -24,
      "y": -1,
      "z": 12,
      "name": "Rock_Lime_Brick_Smooth"
    },
    {
      "x": -24,
      "y": 0,
      "z": 12,
      "name": "Rock_Lime_Brick"
    },
    {
      "x": -24,
      "y": -1,
      "z": 13,
      "name": "Rock_Lime_Brick_Smooth"
    },
    {
      "x": -24,
      "y": 0,
      "z": 13,
      "name": "Rock_Lime_Brick_Smooth"
    },
    {
      "x": -24,
      "y": -1,
      "z": 14,
      "name": "Rock_Lime_Brick"
    },
    {
      "x": -24,
      "y": 0,
      "z": 14,
      "name": "Rock_Lime_Brick"
    },
    {
      "x": -24,
      "y": -1,
      "z": 15,
      "name": "Rock_Lime_Brick_Smooth"
    },
    {
      "x": -24,
      "y": 0,
      "z": 15,
      "name": "Rock_Lime_Brick"
    },
    {
      "x": -24,
      "y": -1,
      "z": 16,
      "name": "Rock_Lime_Brick_Smooth"
    },
    {
      "x": -24,
      "y": -1,
      "z": 17,
      "name": "Rock_Lime_Brick_Smooth"
    },
    {
      "x": -24,
      "y": -1,
      "z": 18,
      "name": "Rock_Lime_Brick_Smooth"
    },
    {
      "x": -24,
      "y": -1,
      "z": 19,
      "name": "Rock_Lime_Brick"
    },
    {
      "x": -24,
      "y": -1,
      "z": 20,
      "name": "Rock_Lime_Brick_Smooth"
    },
    {
      "x": -24,
      "y": -1,
      "z": 21,
      "name": "Rock_Lime_Brick_Smooth"
    },
    {
      "x": -23,
      "y": -1,
      "z": -22,
      "name": "Rock_Lime_Brick"
    },
    {
      "x": -23,
      "y": -1,
      "z": -21,
      "name": "Rock_Lime_Brick_Smooth"
    },
    {
      "x": -23,
      "y": -1,
      "z": -20,
      "name": "Rock_Lime_Brick_Smooth"
    },
    {
      "x": -23,
      "y": -1,
      "z": -19,
      "name": "Rock_Lime_Brick_Smooth"
    },
    {
      "x": -23,
      "y": -1,
      "z": -18,
      "name": "Rock_Lime_Brick_Smooth"
    },
    {
      "x": -23,
      "y": -1,
      "z": -17,
      "name": "Rock_Lime_Brick_Smooth"
    },
    {
      "x": -23,
      "y": -1,
      "z": -16,
      "name": "Rock_Lime_Brick_Smooth"
    },
    {
      "x": -23,
      "y": 0,
      "z": -16,
      "name": "Rock_Lime_Brick_Smooth"
    },
    {
      "x": -23,
      "y": -1,
      "z": -15,
      "name": "Rock_Lime_Brick"
    },
    {
      "x": -23,
      "y": 0,
      "z": -15,
      "name": "Rock_Lime_Brick_Smooth"
    },
    {
      "x": -23,
      "y": -1,
      "z": -14,
      "name": "Rock_Lime_Brick_Smooth"
    },
    {
      "x": -23,
      "y": 0,
      "z": -14,
      "name": "Rock_Lime_Brick_Smooth"
    },
    {
      "x": -23,
      "y": -1,
      "z": -13,
      "name": "Rock_Lime_Brick_Smooth"
    },
    {
      "x": -23,
      "y": 0,
      "z": -13,
      "name": "Rock_Lime_Brick_Smooth"
    },
    {
      "x": -23,
      "y": -1,
      "z": -12,
      "name": "Rock_Lime_Brick"
    },
    {
      "x": -23,
      "y": 0,
      "z": -12,
      "name": "Rock_Lime_Brick_Smooth"
    },
    {
      "x": -23,
      "y": -1,
      "z": -11,
      "name": "Rock_Lime_Brick_Smooth"
    },
    {
      "x": -23,
      "y": 0,
      "z": -11,
      "name": "Rock_Lime_Brick_Smooth"
    },
    {
      "x": -23,
      "y": -1,
      "z": -10,
      "name": "Rock_Lime_Brick"
    },
    {
      "x": -23,
      "y": 0,
      "z": -10,
      "name": "Rock_Lime_Brick_Smooth"
    },
    {
      "x": -23,
      "y": -1,
      "z": -9,
      "name": "Rock_Lime_Brick_Smooth"
    },
    {
      "x": -23,
      "y": 0,
      "z": -9,
      "name": "Rock_Lime_Brick_Smooth"
    },
    {
      "x": -23,
      "y": -1,
      "z": -8,
      "name": "Rock_Lime_Brick_Smooth"
    },
    {
      "x": -23,
      "y": 0,
      "z": -8,
      "name": "Rock_Lime_Brick_Smooth"
    },
    {
      "x": -23,
      "y": 1,
      "z": -8,
      "name": "Rock_Lime_Brick"
    },
    {
      "x": -23,
      "y": -1,
      "z": -7,
      "name": "Rock_Lime_Brick"
    },
    {
      "x": -23,
      "y": 0,
      "z": -7,
      "name": "Rock_Lime_Brick_Smooth"
    },
    {
      "x": -23,
      "y": 1,
      "z": -7,
      "name": "Rock_Lime_Brick_Smooth"
    },
    {
      "x": -23,
      "y": -1,
      "z": -6,
      "name": "Rock_Lime_Brick_Smooth"
    },
    {
      "x": -23,
      "y": 0,
      "z": -6,
      "name": "Rock_Lime_Brick_Smooth"
    },
    {
      "x": -23,
      "y": 1,
      "z": -6,
      "name": "Rock_Lime_Brick_Smooth"
    },
    {
      "x": -23,
      "y": -1,
      "z": -5,
      "name": "Rock_Lime_Brick_Smooth"
    },
    {
      "x": -23,
      "y": 0,
      "z": -5,
      "name": "Rock_Lime_Brick_Smooth"
    },
    {
      "x": -23,
      "y": 1,
      "z": -5,
      "name": "Rock_Lime_Brick_Smooth"
    },
    {
      "x": -23,
      "y": -1,
      "z": -4,
      "name": "Rock_Lime_Brick_Smooth"
    },
    {
      "x": -23,
      "y": 0,
      "z": -4,
      "name": "Rock_Lime_Brick_Smooth"
    },
    {
      "x": -23,
      "y": 1,
      "z": -4,
      "name": "Rock_Lime_Brick_Smooth"
    },
    {
      "x": -23,
      "y": -1,
      "z": -3,
      "name": "Rock_Lime_Brick"
    },
    {
      "x": -23,
      "y": 0,
      "z": -3,
      "name": "Rock_Lime_Brick_Smooth"
    },
    {
      "x": -23,
      "y": 1,
      "z": -3,
      "name": "Rock_Lime_Brick_Smooth"
    },
    {
      "x": -23,
      "y": -1,
      "z": -2,
      "name": "Rock_Lime_Brick_Smooth"
    },
    {
      "x": -23,
      "y": 0,
      "z": -2,
      "name": "Rock_Lime_Brick_Smooth"
    },
    {
      "x": -23,
      "y": 1,
      "z": -2,
      "name": "Rock_Lime_Brick_Smooth"
    },
    {
      "x": -23,
      "y": -1,
      "z": -1,
      "name": "Rock_Lime_Brick"
    },
    {
      "x": -23,
      "y": 0,
      "z": -1,
      "name": "Rock_Lime_Brick"
    },
    {
      "x": -23,
      "y": 1,
      "z": -1,
      "name": "Rock_Lime_Brick_Smooth"
    },
    {
      "x": -23,
      "y": -1,
      "z": 0,
      "name": "Rock_Lime_Brick_Smooth"
    },
    {
      "x": -23,
      "y": 0,
      "z": 0,
      "name": "Rock_Lime_Brick_Smooth"
    },
    {
      "x": -23,
      "y": 1,
      "z": 0,
      "name": "Rock_Lime_Brick_Smooth"
    },
    {
      "x": -23,
      "y": -1,
      "z": 1,
      "name": "Rock_Lime_Brick"
    },
    {
      "x": -23,
      "y": 0,
      "z": 1,
      "name": "Rock_Lime_Brick_Smooth"
    },
    {
      "x": -23,
      "y": 1,
      "z": 1,
      "name": "Rock_Lime_Brick_Smooth"
    },
    {
      "x": -23,
      "y": -1,
      "z": 2,
      "name": "Rock_Lime_Brick_Smooth"
    },
    {
      "x": -23,
      "y": 0,
      "z": 2,
      "name": "Rock_Lime_Brick_Smooth"
    },
    {
      "x": -23,
      "y": 1,
      "z": 2,
      "name": "Rock_Lime_Brick_Smooth"
    },
    {
      "x": -23,
      "y": -1,
      "z": 3,
      "name": "Rock_Lime_Brick_Smooth"
    },
    {
      "x": -23,
      "y": 0,
      "z": 3,
      "name": "Rock_Lime_Brick_Smooth"
    },
    {
      "x": -23,
      "y": 1,
      "z": 3,
      "name": "Rock_Lime_Brick_Smooth"
    },
    {
      "x": -23,
      "y": -1,
      "z": 4,
      "name": "Rock_Lime_Brick_Smooth"
    },
    {
      "x": -23,
      "y": 0,
      "z": 4,
      "name": "Rock_Lime_Brick_Smooth"
    },
    {
      "x": -23,
      "y": 1,
      "z": 4,
      "name": "Rock_Lime_Brick_Smooth"
    },
    {
      "x": -23,
      "y": -1,
      "z": 5,
      "name": "Rock_Lime_Brick_Smooth"
    },
    {
      "x": -23,
      "y": 0,
      "z": 5,
      "name": "Rock_Lime_Brick_Smooth"
    },
    {
      "x": -23,
      "y": 1,
      "z": 5,
      "name": "Rock_Lime_Brick_Smooth"
    },
    {
      "x": -23,
      "y": -1,
      "z": 6,
      "name": "Rock_Lime_Brick_Smooth"
    },
    {
      "x": -23,
      "y": 0,
      "z": 6,
      "name": "Rock_Lime_Brick_Smooth"
    },
    {
      "x": -23,
      "y": 1,
      "z": 6,
      "name": "Rock_Lime_Brick"
    },
    {
      "x": -23,
      "y": -1,
      "z": 7,
      "name": "Rock_Lime_Brick_Smooth"
    },
    {
      "x": -23,
      "y": 0,
      "z": 7,
      "name": "Rock_Lime_Brick"
    },
    {
      "x": -23,
      "y": 1,
      "z": 7,
      "name": "Rock_Lime_Brick_Smooth"
    },
    {
      "x": -23,
      "y": -1,
      "z": 8,
      "name": "Rock_Lime_Brick_Smooth"
    },
    {
      "x": -23,
      "y": 0,
      "z": 8,
      "name": "Rock_Lime_Brick_Smooth"
    },
    {
      "x": -23,
      "y": 1,
      "z": 8,
      "name": "Rock_Lime_Brick"
    },
    {
      "x": -23,
      "y": -1,
      "z": 9,
      "name": "Rock_Lime_Brick_Smooth"
    },
    {
      "x": -23,
      "y": 0,
      "z": 9,
      "name": "Rock_Lime_Brick"
    },
    {
      "x": -23,
      "y": -1,
      "z": 10,
      "name": "Rock_Lime_Brick_Smooth"
    },
    {
      "x": -23,
      "y": 0,
      "z": 10,
      "name": "Rock_Lime_Brick_Smooth"
    },
    {
      "x": -23,
      "y": -1,
      "z": 11,
      "name": "Rock_Lime_Brick_Smooth"
    },
    {
      "x": -23,
      "y": 0,
      "z": 11,
      "name": "Rock_Lime_Brick"
    },
    {
      "x": -23,
      "y": -1,
      "z": 12,
      "name": "Rock_Lime_Brick"
    },
    {
      "x": -23,
      "y": 0,
      "z": 12,
      "name": "Rock_Lime_Brick_Smooth"
    },
    {
      "x": -23,
      "y": -1,
      "z": 13,
      "name": "Rock_Lime_Brick_Smooth"
    },
    {
      "x": -23,
      "y": 0,
      "z": 13,
      "name": "Rock_Lime_Brick"
    },
    {
      "x": -23,
      "y": -1,
      "z": 14,
      "name": "Rock_Lime_Brick_Smooth"
    },
    {
      "x": -23,
      "y": 0,
      "z": 14,
      "name": "Rock_Lime_Brick"
    },
    {
      "x": -23,
      "y": -1,
      "z": 15,
      "name": "Rock_Lime_Brick"
    },
    {
      "x": -23,
      "y": 0,
      "z": 15,
      "name": "Rock_Lime_Brick_Smooth"
    },
    {
      "x": -23,
      "y": -1,
      "z": 16,
      "name": "Rock_Lime_Brick_Smooth"
    },
    {
      "x": -23,
      "y": 0,
      "z": 16,
      "name": "Rock_Lime_Brick_Smooth"
    },
    {
      "x": -23,
      "y": -1,
      "z": 17,
      "name": "Rock_Lime_Brick_Smooth"
    },
    {
      "x": -23,
      "y": -1,
      "z": 18,
      "name": "Rock_Lime_Brick_Smooth"
    },
    {
      "x": -23,
      "y": -1,
      "z": 19,
      "name": "Rock_Lime_Brick_Smooth"
    },
    {
      "x": -23,
      "y": -1,
      "z": 20,
      "name": "Rock_Lime_Brick_Smooth"
    },
    {
      "x": -23,
      "y": -1,
      "z": 21,
      "name": "Rock_Lime_Brick_Smooth"
    },
    {
      "x": -23,
      "y": -1,
      "z": 22,
      "name": "Rock_Lime_Brick_Smooth"
    },
    {
      "x": -22,
      "y": -1,
      "z": -23,
      "name": "Rock_Lime_Brick_Smooth"
    },
    {
      "x": -22,
      "y": -1,
      "z": -22,
      "name": "Rock_Lime_Brick"
    },
    {
      "x": -22,
      "y": -1,
      "z": -21,
      "name": "Rock_Lime_Brick"
    },
    {
      "x": -22,
      "y": -1,
      "z": -20,
      "name": "Rock_Lime_Brick_Smooth"
    },
    {
      "x": -22,
      "y": -1,
      "z": -19,
      "name": "Rock_Lime_Brick_Smooth"
    },
    {
      "x": -22,
      "y": -1,
      "z": -18,
      "name": "Rock_Lime_Brick_Smooth"
    },
    {
      "x": -22,
      "y": -1,
      "z": -17,
      "name": "Rock_Lime_Brick_Smooth"
    },
    {
      "x": -22,
      "y": 0,
      "z": -17,
      "name": "Rock_Lime_Brick_Smooth"
    },
    {
      "x": -22,
      "y": -1,
      "z": -16,
      "name": "Rock_Lime_Brick"
    },
    {
      "x": -22,
      "y": 0,
      "z": -16,
      "name": "Rock_Lime_Brick_Smooth"
    },
    {
      "x": -22,
      "y": -1,
      "z": -15,
      "name": "Rock_Lime_Brick_Smooth"
    },
    {
      "x": -22,
      "y": 0,
      "z": -15,
      "name": "Rock_Lime_Brick_Smooth"
    },
    {
      "x": -22,
      "y": -1,
      "z": -14,
      "name": "Rock_Lime_Brick_Smooth"
    },
    {
      "x": -22,
      "y": 0,
      "z": -14,
      "name": "Rock_Lime_Brick_Smooth"
    },
    {
      "x": -22,
      "y": -1,
      "z": -13,
      "name": "Rock_Lime_Brick_Smooth"
    },
    {
      "x": -22,
      "y": 0,
      "z": -13,
      "name": "Rock_Lime_Brick_Smooth"
    },
    {
      "x": -22,
      "y": -1,
      "z": -12,
      "name": "Rock_Lime_Brick"
    },
    {
      "x": -22,
      "y": 0,
      "z": -12,
      "name": "Rock_Lime_Brick_Smooth"
    },
    {
      "x": -22,
      "y": -1,
      "z": -11,
      "name": "Rock_Lime_Brick_Smooth"
    },
    {
      "x": -22,
      "y": 0,
      "z": -11,
      "name": "Rock_Lime_Brick_Smooth"
    },
    {
      "x": -22,
      "y": -1,
      "z": -10,
      "name": "Rock_Lime_Brick_Smooth"
    },
    {
      "x": -22,
      "y": 0,
      "z": -10,
      "name": "Rock_Lime_Brick"
    },
    {
      "x": -22,
      "y": 1,
      "z": -10,
      "name": "Rock_Lime_Brick_Smooth"
    },
    {
      "x": -22,
      "y": -1,
      "z": -9,
      "name": "Rock_Lime_Brick"
    },
    {
      "x": -22,
      "y": 0,
      "z": -9,
      "name": "Rock_Lime_Brick_Smooth"
    },
    {
      "x": -22,
      "y": 1,
      "z": -9,
      "name": "Rock_Lime_Brick_Smooth"
    },
    {
      "x": -22,
      "y": -1,
      "z": -8,
      "name": "Rock_Lime_Brick"
    },
    {
      "x": -22,
      "y": 0,
      "z": -8,
      "name": "Rock_Lime_Brick_Smooth"
    },
    {
      "x": -22,
      "y": 1,
      "z": -8,
      "name": "Rock_Lime_Brick_Smooth"
    },
    {
      "x": -22,
      "y": -1,
      "z": -7,
      "name": "Rock_Lime_Brick_Smooth"
    },
    {
      "x": -22,
      "y": 0,
      "z": -7,
      "name": "Rock_Lime_Brick_Smooth"
    },
    {
      "x": -22,
      "y": 1,
      "z": -7,
      "name": "Rock_Lime_Brick_Smooth"
    },
    {
      "x": -22,
      "y": -1,
      "z": -6,
      "name": "Rock_Lime_Brick_Smooth"
    },
    {
      "x": -22,
      "y": 0,
      "z": -6,
      "name": "Rock_Lime_Brick_Smooth"
    },
    {
      "x": -22,
      "y": 1,
      "z": -6,
      "name": "Rock_Lime_Brick_Smooth"
    },
    {
      "x": -22,
      "y": -1,
      "z": -5,
      "name": "Rock_Lime_Brick_Smooth"
    },
    {
      "x": -22,
      "y": 0,
      "z": -5,
      "name": "Rock_Lime_Brick_Smooth"
    },
    {
      "x": -22,
      "y": 1,
      "z": -5,
      "name": "Rock_Lime_Brick_Smooth"
    },
    {
      "x": -22,
      "y": -1,
      "z": -4,
      "name": "Rock_Lime_Brick_Smooth"
    },
    {
      "x": -22,
      "y": 0,
      "z": -4,
      "name": "Rock_Lime_Brick_Smooth"
    },
    {
      "x": -22,
      "y": 1,
      "z": -4,
      "name": "Rock_Lime_Brick_Smooth"
    },
    {
      "x": -22,
      "y": -1,
      "z": -3,
      "name": "Rock_Lime_Brick_Smooth"
    },
    {
      "x": -22,
      "y": 0,
      "z": -3,
      "name": "Rock_Lime_Brick"
    },
    {
      "x": -22,
      "y": 1,
      "z": -3,
      "name": "Rock_Lime_Brick_Smooth"
    },
    {
      "x": -22,
      "y": -1,
      "z": -2,
      "name": "Rock_Lime_Brick_Smooth"
    },
    {
      "x": -22,
      "y": 0,
      "z": -2,
      "name": "Rock_Lime_Brick_Smooth"
    },
    {
      "x": -22,
      "y": 1,
      "z": -2,
      "name": "Rock_Lime_Brick_Smooth"
    },
    {
      "x": -22,
      "y": 35,
      "z": -2,
      "name": "Rock_Lime_Cobble"
    },
    {
      "x": -22,
      "y": 36,
      "z": -2,
      "name": "Rock_Lime"
    },
    {
      "x": -22,
      "y": 37,
      "z": -2,
      "name": "Rock_Lime"
    },
    {
      "x": -22,
      "y": 38,
      "z": -2,
      "name": "Rock_Lime"
    },
    {
      "x": -22,
      "y": 39,
      "z": -2,
      "name": "Rock_Lime"
    },
    {
      "x": -22,
      "y": -1,
      "z": -1,
      "name": "Rock_Lime_Brick_Smooth"
    },
    {
      "x": -22,
      "y": 0,
      "z": -1,
      "name": "Rock_Lime_Brick_Smooth"
    },
    {
      "x": -22,
      "y": 1,
      "z": -1,
      "name": "Rock_Lime_Brick_Smooth"
    },
    {
      "x": -22,
      "y": 35,
      "z": -1,
      "name": "Rock_Lime"
    },
    {
      "x": -22,
      "y": 36,
      "z": -1,
      "name": "Rock_Lime"
    },
    {
      "x": -22,
      "y": 37,
      "z": -1,
      "name": "Soil_Gravel_Lime"
    },
    {
      "x": -22,
      "y": 38,
      "z": -1,
      "name": "Rock_Lime_Cobble"
    },
    {
      "x": -22,
      "y": 39,
      "z": -1,
      "name": "Rock_Lime"
    },
    {
      "x": -22,
      "y": -1,
      "z": 0,
      "name": "Rock_Lime_Brick_Smooth"
    },
    {
      "x": -22,
      "y": 0,
      "z": 0,
      "name": "Rock_Lime_Brick_Smooth"
    },
    {
      "x": -22,
      "y": 1,
      "z": 0,
      "name": "Rock_Lime_Brick_Smooth"
    },
    {
      "x": -22,
      "y": 35,
      "z": 0,
      "name": "Rock_Lime_Cobble"
    },
    {
      "x": -22,
      "y": 36,
      "z": 0,
      "name": "Rock_Lime"
    },
    {
      "x": -22,
      "y": 38,
      "z": 0,
      "name": "Rock_Lime"
    },
    {
      "x": -22,
      "y": 39,
      "z": 0,
      "name": "Rock_Lime"
    },
    {
      "x": -22,
      "y": -1,
      "z": 1,
      "name": "Rock_Lime_Brick_Smooth"
    },
    {
      "x": -22,
      "y": 0,
      "z": 1,
      "name": "Rock_Lime_Brick_Smooth"
    },
    {
      "x": -22,
      "y": 1,
      "z": 1,
      "name": "Rock_Lime_Brick"
    },
    {
      "x": -22,
      "y": 35,
      "z": 1,
      "name": "Rock_Lime_Cobble"
    },
    {
      "x": -22,
      "y": 36,
      "z": 1,
      "name": "Rock_Lime_Cobble"
    },
    {
      "x": -22,
      "y": 37,
      "z": 1,
      "name": "Rock_Lime_Cobble"
    },
    {
      "x": -22,
      "y": 38,
      "z": 1,
      "name": "Soil_Gravel_Lime"
    },
    {
      "x": -22,
      "y": 39,
      "z": 1,
      "name": "Rock_Lime_Cobble"
    },
    {
      "x": -22,
      "y": -1,
      "z": 2,
      "name": "Rock_Lime_Brick_Smooth"
    },
    {
      "x": -22,
      "y": 0,
      "z": 2,
      "name": "Rock_Lime_Brick_Smooth"
    },
    {
      "x": -22,
      "y": 1,
      "z": 2,
      "name": "Rock_Lime_Brick_Smooth"
    },
    {
      "x": -22,
      "y": 35,
      "z": 2,
      "name": "Rock_Lime"
    },
    {
      "x": -22,
      "y": 36,
      "z": 2,
      "name": "Rock_Lime_Cobble"
    },
    {
      "x": -22,
      "y": 37,
      "z": 2,
      "name": "Rock_Lime_Cobble"
    },
    {
      "x": -22,
      "y": 38,
      "z": 2,
      "name": "Rock_Lime"
    },
    {
      "x": -22,
      "y": 39,
      "z": 2,
      "name": "Rock_Lime_Cobble"
    },
    {
      "x": -22,
      "y": -1,
      "z": 3,
      "name": "Rock_Lime_Brick_Smooth"
    },
    {
      "x": -22,
      "y": 0,
      "z": 3,
      "name": "Rock_Lime_Brick_Smooth"
    },
    {
      "x": -22,
      "y": 1,
      "z": 3,
      "name": "Rock_Lime_Brick_Smooth"
    },
    {
      "x": -22,
      "y": -1,
      "z": 4,
      "name": "Rock_Lime_Brick_Smooth"
    },
    {
      "x": -22,
      "y": 0,
      "z": 4,
      "name": "Rock_Lime_Brick_Smooth"
    },
    {
      "x": -22,
      "y": 1,
      "z": 4,
      "name": "Rock_Lime_Brick_Smooth"
    },
    {
      "x": -22,
      "y": -1,
      "z": 5,
      "name": "Rock_Lime_Brick_Smooth"
    },
    {
      "x": -22,
      "y": 0,
      "z": 5,
      "name": "Rock_Lime_Brick_Smooth"
    },
    {
      "x": -22,
      "y": 1,
      "z": 5,
      "name": "Rock_Lime_Brick"
    },
    {
      "x": -22,
      "y": -1,
      "z": 6,
      "name": "Rock_Lime_Brick_Smooth"
    },
    {
      "x": -22,
      "y": 0,
      "z": 6,
      "name": "Rock_Lime_Brick_Smooth"
    },
    {
      "x": -22,
      "y": 1,
      "z": 6,
      "name": "Rock_Lime_Brick_Smooth"
    },
    {
      "x": -22,
      "y": -1,
      "z": 7,
      "name": "Rock_Lime_Brick"
    },
    {
      "x": -22,
      "y": 0,
      "z": 7,
      "name": "Rock_Lime_Brick_Smooth"
    },
    {
      "x": -22,
      "y": 1,
      "z": 7,
      "name": "Rock_Lime_Brick_Smooth"
    },
    {
      "x": -22,
      "y": -1,
      "z": 8,
      "name": "Rock_Lime_Brick"
    },
    {
      "x": -22,
      "y": 0,
      "z": 8,
      "name": "Rock_Lime_Brick_Smooth"
    },
    {
      "x": -22,
      "y": 1,
      "z": 8,
      "name": "Rock_Lime_Brick"
    },
    {
      "x": -22,
      "y": -1,
      "z": 9,
      "name": "Rock_Lime_Brick_Smooth"
    },
    {
      "x": -22,
      "y": 0,
      "z": 9,
      "name": "Rock_Lime_Brick_Smooth"
    },
    {
      "x": -22,
      "y": 1,
      "z": 9,
      "name": "Rock_Lime_Brick"
    },
    {
      "x": -22,
      "y": -1,
      "z": 10,
      "name": "Rock_Lime_Brick_Smooth"
    },
    {
      "x": -22,
      "y": 0,
      "z": 10,
      "name": "Rock_Lime_Brick_Smooth"
    },
    {
      "x": -22,
      "y": 1,
      "z": 10,
      "name": "Rock_Lime_Brick_Smooth"
    },
    {
      "x": -22,
      "y": -1,
      "z": 11,
      "name": "Rock_Lime_Brick_Smooth"
    },
    {
      "x": -22,
      "y": 0,
      "z": 11,
      "name": "Rock_Lime_Brick_Smooth"
    },
    {
      "x": -22,
      "y": -1,
      "z": 12,
      "name": "Rock_Lime_Brick_Smooth"
    },
    {
      "x": -22,
      "y": 0,
      "z": 12,
      "name": "Rock_Lime_Brick_Smooth"
    },
    {
      "x": -22,
      "y": -1,
      "z": 13,
      "name": "Rock_Lime_Brick_Smooth"
    },
    {
      "x": -22,
      "y": 0,
      "z": 13,
      "name": "Rock_Lime_Brick_Smooth"
    },
    {
      "x": -22,
      "y": -1,
      "z": 14,
      "name": "Rock_Lime_Brick_Smooth"
    },
    {
      "x": -22,
      "y": 0,
      "z": 14,
      "name": "Rock_Lime_Brick_Smooth"
    },
    {
      "x": -22,
      "y": -1,
      "z": 15,
      "name": "Rock_Lime_Brick"
    },
    {
      "x": -22,
      "y": 0,
      "z": 15,
      "name": "Rock_Lime_Brick_Smooth"
    },
    {
      "x": -22,
      "y": -1,
      "z": 16,
      "name": "Rock_Lime_Brick"
    },
    {
      "x": -22,
      "y": 0,
      "z": 16,
      "name": "Rock_Lime_Brick_Smooth"
    },
    {
      "x": -22,
      "y": -1,
      "z": 17,
      "name": "Rock_Lime_Brick_Smooth"
    },
    {
      "x": -22,
      "y": 0,
      "z": 17,
      "name": "Rock_Lime_Brick_Smooth"
    },
    {
      "x": -22,
      "y": -1,
      "z": 18,
      "name": "Rock_Lime_Brick_Smooth"
    },
    {
      "x": -22,
      "y": -1,
      "z": 19,
      "name": "Rock_Lime_Brick"
    },
    {
      "x": -22,
      "y": -1,
      "z": 20,
      "name": "Rock_Lime_Brick"
    },
    {
      "x": -22,
      "y": -1,
      "z": 21,
      "name": "Rock_Lime_Brick"
    },
    {
      "x": -22,
      "y": -1,
      "z": 22,
      "name": "Rock_Lime_Brick_Smooth"
    },
    {
      "x": -22,
      "y": -1,
      "z": 23,
      "name": "Rock_Lime_Brick_Smooth"
    },
    {
      "x": -21,
      "y": -1,
      "z": -24,
      "name": "Rock_Lime_Brick_Smooth"
    },
    {
      "x": -21,
      "y": -1,
      "z": -23,
      "name": "Rock_Lime_Brick"
    },
    {
      "x": -21,
      "y": -1,
      "z": -22,
      "name": "Rock_Lime_Brick_Smooth"
    },
    {
      "x": -21,
      "y": -1,
      "z": -21,
      "name": "Rock_Lime_Brick"
    },
    {
      "x": -21,
      "y": -1,
      "z": -20,
      "name": "Rock_Lime_Brick_Smooth"
    },
    {
      "x": -21,
      "y": -1,
      "z": -19,
      "name": "Rock_Lime_Brick_Smooth"
    },
    {
      "x": -21,
      "y": 0,
      "z": -19,
      "name": "Rock_Lime_Brick_Smooth"
    },
    {
      "x": -21,
      "y": -1,
      "z": -18,
      "name": "Rock_Lime_Brick_Smooth"
    },
    {
      "x": -21,
      "y": 0,
      "z": -18,
      "name": "Rock_Lime_Brick"
    },
    {
      "x": -21,
      "y": -1,
      "z": -17,
      "name": "Rock_Lime_Brick_Smooth"
    },
    {
      "x": -21,
      "y": 0,
      "z": -17,
      "name": "Rock_Lime_Brick"
    },
    {
      "x": -21,
      "y": -1,
      "z": -16,
      "name": "Rock_Lime_Brick_Smooth"
    },
    {
      "x": -21,
      "y": 0,
      "z": -16,
      "name": "Rock_Lime_Brick_Smooth"
    },
    {
      "x": -21,
      "y": -1,
      "z": -15,
      "name": "Rock_Lime_Brick_Smooth"
    },
    {
      "x": -21,
      "y": 0,
      "z": -15,
      "name": "Rock_Lime_Brick_Smooth"
    },
    {
      "x": -21,
      "y": -1,
      "z": -14,
      "name": "Rock_Lime_Brick"
    },
    {
      "x": -21,
      "y": 0,
      "z": -14,
      "name": "Rock_Lime_Brick_Smooth"
    },
    {
      "x": -21,
      "y": -1,
      "z": -13,
      "name": "Rock_Lime_Brick_Smooth"
    },
    {
      "x": -21,
      "y": 0,
      "z": -13,
      "name": "Rock_Lime_Brick_Smooth"
    },
    {
      "x": -21,
      "y": -1,
      "z": -12,
      "name": "Rock_Lime_Brick"
    },
    {
      "x": -21,
      "y": 0,
      "z": -12,
      "name": "Rock_Lime_Brick_Smooth"
    },
    {
      "x": -21,
      "y": 1,
      "z": -12,
      "name": "Rock_Lime_Brick_Smooth"
    },
    {
      "x": -21,
      "y": -1,
      "z": -11,
      "name": "Rock_Lime_Brick"
    },
    {
      "x": -21,
      "y": 0,
      "z": -11,
      "name": "Rock_Lime_Brick_Smooth"
    },
    {
      "x": -21,
      "y": 1,
      "z": -11,
      "name": "Rock_Lime_Brick_Smooth"
    },
    {
      "x": -21,
      "y": -1,
      "z": -10,
      "name": "Rock_Lime_Brick_Smooth"
    },
    {
      "x": -21,
      "y": 0,
      "z": -10,
      "name": "Rock_Lime_Brick_Smooth"
    },
    {
      "x": -21,
      "y": 1,
      "z": -10,
      "name": "Rock_Lime_Brick_Smooth"
    },
    {
      "x": -21,
      "y": -1,
      "z": -9,
      "name": "Rock_Lime_Brick"
    },
    {
      "x": -21,
      "y": 0,
      "z": -9,
      "name": "Rock_Lime_Brick_Smooth"
    },
    {
      "x": -21,
      "y": 1,
      "z": -9,
      "name": "Rock_Lime_Brick_Smooth"
    },
    {
      "x": -21,
      "y": -1,
      "z": -8,
      "name": "Rock_Lime_Brick"
    },
    {
      "x": -21,
      "y": 0,
      "z": -8,
      "name": "Rock_Lime_Brick_Smooth"
    },
    {
      "x": -21,
      "y": 1,
      "z": -8,
      "name": "Rock_Lime_Brick_Smooth"
    },
    {
      "x": -21,
      "y": -1,
      "z": -7,
      "name": "Rock_Lime_Brick_Smooth"
    },
    {
      "x": -21,
      "y": 0,
      "z": -7,
      "name": "Rock_Lime_Brick_Smooth"
    },
    {
      "x": -21,
      "y": 1,
      "z": -7,
      "name": "Rock_Lime_Brick"
    },
    {
      "x": -21,
      "y": -1,
      "z": -6,
      "name": "Rock_Lime_Brick_Smooth"
    },
    {
      "x": -21,
      "y": 0,
      "z": -6,
      "name": "Rock_Lime_Brick"
    },
    {
      "x": -21,
      "y": 1,
      "z": -6,
      "name": "Rock_Lime_Brick_Smooth"
    },
    {
      "x": -21,
      "y": -1,
      "z": -5,
      "name": "Rock_Lime_Brick"
    },
    {
      "x": -21,
      "y": 0,
      "z": -5,
      "name": "Rock_Lime_Brick_Smooth"
    },
    {
      "x": -21,
      "y": 1,
      "z": -5,
      "name": "Rock_Lime_Brick"
    },
    {
      "x": -21,
      "y": -1,
      "z": -4,
      "name": "Rock_Lime_Brick"
    },
    {
      "x": -21,
      "y": 0,
      "z": -4,
      "name": "Rock_Lime_Brick_Smooth"
    },
    {
      "x": -21,
      "y": 1,
      "z": -4,
      "name": "Rock_Lime_Brick"
    },
    {
      "x": -21,
      "y": -1,
      "z": -3,
      "name": "Rock_Lime_Brick_Smooth"
    },
    {
      "x": -21,
      "y": 0,
      "z": -3,
      "name": "Rock_Lime_Brick_Smooth"
    },
    {
      "x": -21,
      "y": 1,
      "z": -3,
      "name": "Rock_Lime_Brick_Smooth"
    },
    {
      "x": -21,
      "y": -1,
      "z": -2,
      "name": "Rock_Lime_Brick_Smooth"
    },
    {
      "x": -21,
      "y": 0,
      "z": -2,
      "name": "Rock_Lime_Brick_Smooth"
    },
    {
      "x": -21,
      "y": 1,
      "z": -2,
      "name": "Rock_Lime_Brick_Smooth"
    },
    {
      "x": -21,
      "y": 34,
      "z": -2,
      "name": "Rock_Lime_Cobble"
    },
    {
      "x": -21,
      "y": 35,
      "z": -2,
      "name": "Rock_Lime"
    },
    {
      "x": -21,
      "y": 36,
      "z": -2,
      "name": "Rock_Lime_Cobble"
    },
    {
      "x": -21,
      "y": 38,
      "z": -2,
      "name": "Soil_Gravel_Lime"
    },
    {
      "x": -21,
      "y": 39,
      "z": -2,
      "name": "Soil_Gravel_Lime"
    },
    {
      "x": -21,
      "y": 40,
      "z": -2,
      "name": "Rock_Lime_Cobble"
    },
    {
      "x": -21,
      "y": -1,
      "z": -1,
      "name": "Rock_Lime_Brick_Smooth"
    },
    {
      "x": -21,
      "y": 0,
      "z": -1,
      "name": "Rock_Lime_Brick_Smooth"
    },
    {
      "x": -21,
      "y": 1,
      "z": -1,
      "name": "Rock_Lime_Brick_Smooth"
    },
    {
      "x": -21,
      "y": 2,
      "z": -1,
      "name": "Rock_Lime_Cobble"
    },
    {
      "x": -21,
      "y": 3,
      "z": -1,
      "name": "Rock_Lime_Cobble"
    },
    {
      "x": -21,
      "y": 4,
      "z": -1,
      "name": "Rock_Lime_Cobble"
    },
    {
      "x": -21,
      "y": 5,
      "z": -1,
      "name": "Rock_Lime_Cobble"
    },
    {
      "x": -21,
      "y": 6,
      "z": -1,
      "name": "Rock_Lime_Cobble"
    },
    {
      "x": -21,
      "y": 7,
      "z": -1,
      "name": "Rock_Lime_Cobble"
    },
    {
      "x": -21,
      "y": 8,
      "z": -1,
      "name": "Rock_Lime"
    },
    {
      "x": -21,
      "y": 9,
      "z": -1,
      "name": "Rock_Lime"
    },
    {
      "x": -21,
      "y": 10,
      "z": -1,
      "name": "Soil_Gravel_Lime"
    },
    {
      "x": -21,
      "y": 11,
      "z": -1,
      "name": "Rock_Lime"
    },
    {
      "x": -21,
      "y": 12,
      "z": -1,
      "name": "Soil_Gravel_Lime"
    },
    {
      "x": -21,
      "y": 13,
      "z": -1,
      "name": "Soil_Gravel_Lime"
    },
    {
      "x": -21,
      "y": 14,
      "z": -1,
      "name": "Rock_Lime"
    },
    {
      "x": -21,
      "y": 15,
      "z": -1,
      "name": "Rock_Lime"
    },
    {
      "x": -21,
      "y": 16,
      "z": -1,
      "name": "Rock_Lime"
    },
    {
      "x": -21,
      "y": 17,
      "z": -1,
      "name": "Rock_Lime_Cobble"
    },
    {
      "x": -21,
      "y": 18,
      "z": -1,
      "name": "Rock_Lime"
    },
    {
      "x": -21,
      "y": 19,
      "z": -1,
      "name": "Rock_Lime"
    },
    {
      "x": -21,
      "y": 20,
      "z": -1,
      "name": "Rock_Lime"
    },
    {
      "x": -21,
      "y": 21,
      "z": -1,
      "name": "Rock_Lime_Cobble"
    },
    {
      "x": -21,
      "y": 22,
      "z": -1,
      "name": "Rock_Lime"
    },
    {
      "x": -21,
      "y": 23,
      "z": -1,
      "name": "Rock_Lime"
    },
    {
      "x": -21,
      "y": 24,
      "z": -1,
      "name": "Rock_Lime_Cobble"
    },
    {
      "x": -21,
      "y": 25,
      "z": -1,
      "name": "Rock_Lime_Cobble"
    },
    {
      "x": -21,
      "y": 26,
      "z": -1,
      "name": "Rock_Lime_Cobble"
    },
    {
      "x": -21,
      "y": 27,
      "z": -1,
      "name": "Rock_Lime"
    },
    {
      "x": -21,
      "y": 28,
      "z": -1,
      "name": "Rock_Lime"
    },
    {
      "x": -21,
      "y": 29,
      "z": -1,
      "name": "Soil_Gravel_Lime"
    },
    {
      "x": -21,
      "y": 30,
      "z": -1,
      "name": "Rock_Lime_Cobble"
    },
    {
      "x": -21,
      "y": 31,
      "z": -1,
      "name": "Rock_Lime_Cobble"
    },
    {
      "x": -21,
      "y": 32,
      "z": -1,
      "name": "Soil_Gravel_Lime"
    },
    {
      "x": -21,
      "y": 33,
      "z": -1,
      "name": "Rock_Lime"
    },
    {
      "x": -21,
      "y": 34,
      "z": -1,
      "name": "Rock_Lime"
    },
    {
      "x": -21,
      "y": 35,
      "z": -1,
      "name": "Rock_Lime"
    },
    {
      "x": -21,
      "y": 39,
      "z": -1,
      "name": "Soil_Gravel_Lime"
    },
    {
      "x": -21,
      "y": 40,
      "z": -1,
      "name": "Rock_Lime_Cobble"
    },
    {
      "x": -21,
      "y": -1,
      "z": 0,
      "name": "Rock_Lime_Brick_Smooth"
    },
    {
      "x": -21,
      "y": 0,
      "z": 0,
      "name": "Rock_Lime_Brick_Smooth"
    },
    {
      "x": -21,
      "y": 1,
      "z": 0,
      "name": "Rock_Lime_Brick_Smooth"
    },
    {
      "x": -21,
      "y": 2,
      "z": 0,
      "name": "Rock_Lime_Cobble"
    },
    {
      "x": -21,
      "y": 3,
      "z": 0,
      "name": "Rock_Lime"
    },
    {
      "x": -21,
      "y": 4,
      "z": 0,
      "name": "Rock_Lime"
    },
    {
      "x": -21,
      "y": 5,
      "z": 0,
      "name": "Rock_Lime"
    },
    {
      "x": -21,
      "y": 6,
      "z": 0,
      "name": "Rock_Lime_Cobble"
    },
    {
      "x": -21,
      "y": 7,
      "z": 0,
      "name": "Rock_Lime"
    },
    {
      "x": -21,
      "y": 8,
      "z": 0,
      "name": "Rock_Lime"
    },
    {
      "x": -21,
      "y": 9,
      "z": 0,
      "name": "Rock_Lime_Cobble"
    },
    {
      "x": -21,
      "y": 10,
      "z": 0,
      "name": "Rock_Lime"
    },
    {
      "x": -21,
      "y": 11,
      "z": 0,
      "name": "Rock_Lime"
    },
    {
      "x": -21,
      "y": 12,
      "z": 0,
      "name": "Soil_Gravel_Lime"
    },
    {
      "x": -21,
      "y": 13,
      "z": 0,
      "name": "Rock_Lime"
    },
    {
      "x": -21,
      "y": 14,
      "z": 0,
      "name": "Soil_Gravel_Lime"
    },
    {
      "x": -21,
      "y": 15,
      "z": 0,
      "name": "Rock_Lime"
    },
    {
      "x": -21,
      "y": 16,
      "z": 0,
      "name": "Soil_Gravel_Lime"
    },
    {
      "x": -21,
      "y": 17,
      "z": 0,
      "name": "Soil_Gravel_Lime"
    },
    {
      "x": -21,
      "y": 18,
      "z": 0,
      "name": "Soil_Gravel_Lime"
    },
    {
      "x": -21,
      "y": 19,
      "z": 0,
      "name": "Soil_Gravel_Lime"
    },
    {
      "x": -21,
      "y": 20,
      "z": 0,
      "name": "Rock_Lime_Cobble"
    },
    {
      "x": -21,
      "y": 21,
      "z": 0,
      "name": "Rock_Lime"
    },
    {
      "x": -21,
      "y": 22,
      "z": 0,
      "name": "Rock_Lime"
    },
    {
      "x": -21,
      "y": 23,
      "z": 0,
      "name": "Rock_Lime_Cobble"
    },
    {
      "x": -21,
      "y": 24,
      "z": 0,
      "name": "Rock_Lime_Cobble"
    },
    {
      "x": -21,
      "y": 25,
      "z": 0,
      "name": "Rock_Lime_Cobble"
    },
    {
      "x": -21,
      "y": 26,
      "z": 0,
      "name": "Rock_Lime"
    },
    {
      "x": -21,
      "y": 27,
      "z": 0,
      "name": "Rock_Lime_Cobble"
    },
    {
      "x": -21,
      "y": 28,
      "z": 0,
      "name": "Rock_Lime"
    },
    {
      "x": -21,
      "y": 29,
      "z": 0,
      "name": "Rock_Lime_Cobble"
    },
    {
      "x": -21,
      "y": 30,
      "z": 0,
      "name": "Rock_Lime_Cobble"
    },
    {
      "x": -21,
      "y": 31,
      "z": 0,
      "name": "Rock_Lime_Cobble"
    },
    {
      "x": -21,
      "y": 32,
      "z": 0,
      "name": "Rock_Lime_Cobble"
    },
    {
      "x": -21,
      "y": 33,
      "z": 0,
      "name": "Rock_Lime_Cobble"
    },
    {
      "x": -21,
      "y": 34,
      "z": 0,
      "name": "Rock_Lime"
    },
    {
      "x": -21,
      "y": 35,
      "z": 0,
      "name": "Deco_Rope_Diagonal",
      "rotation": 3
    },
    {
      "x": -21,
      "y": 39,
      "z": 0,
      "name": "Deco_Rope_Diagonal",
      "rotation": 1
    },
    {
      "x": -21,
      "y": 40,
      "z": 0,
      "name": "Soil_Gravel_Lime"
    },
    {
      "x": -21,
      "y": -1,
      "z": 1,
      "name": "Rock_Lime_Brick"
    },
    {
      "x": -21,
      "y": 0,
      "z": 1,
      "name": "Rock_Lime_Brick_Smooth"
    },
    {
      "x": -21,
      "y": 1,
      "z": 1,
      "name": "Rock_Lime_Brick_Smooth"
    },
    {
      "x": -21,
      "y": 2,
      "z": 1,
      "name": "Rock_Lime"
    },
    {
      "x": -21,
      "y": 3,
      "z": 1,
      "name": "Rock_Lime"
    },
    {
      "x": -21,
      "y": 4,
      "z": 1,
      "name": "Rock_Lime"
    },
    {
      "x": -21,
      "y": 5,
      "z": 1,
      "name": "Rock_Lime"
    },
    {
      "x": -21,
      "y": 6,
      "z": 1,
      "name": "Rock_Lime"
    },
    {
      "x": -21,
      "y": 7,
      "z": 1,
      "name": "Rock_Lime"
    },
    {
      "x": -21,
      "y": 8,
      "z": 1,
      "name": "Rock_Lime_Cobble"
    },
    {
      "x": -21,
      "y": 9,
      "z": 1,
      "name": "Soil_Gravel_Lime"
    },
    {
      "x": -21,
      "y": 10,
      "z": 1,
      "name": "Soil_Gravel_Lime"
    },
    {
      "x": -21,
      "y": 11,
      "z": 1,
      "name": "Rock_Lime"
    },
    {
      "x": -21,
      "y": 12,
      "z": 1,
      "name": "Rock_Lime"
    },
    {
      "x": -21,
      "y": 13,
      "z": 1,
      "name": "Rock_Lime_Cobble"
    },
    {
      "x": -21,
      "y": 14,
      "z": 1,
      "name": "Rock_Lime"
    },
    {
      "x": -21,
      "y": 15,
      "z": 1,
      "name": "Rock_Lime"
    },
    {
      "x": -21,
      "y": 16,
      "z": 1,
      "name": "Soil_Gravel_Lime"
    },
    {
      "x": -21,
      "y": 17,
      "z": 1,
      "name": "Rock_Lime_Cobble"
    },
    {
      "x": -21,
      "y": 18,
      "z": 1,
      "name": "Soil_Gravel_Lime"
    },
    {
      "x": -21,
      "y": 19,
      "z": 1,
      "name": "Rock_Lime"
    },
    {
      "x": -21,
      "y": 20,
      "z": 1,
      "name": "Rock_Lime_Cobble"
    },
    {
      "x": -21,
      "y": 21,
      "z": 1,
      "name": "Rock_Lime_Cobble"
    },
    {
      "x": -21,
      "y": 22,
      "z": 1,
      "name": "Rock_Lime"
    },
    {
      "x": -21,
      "y": 23,
      "z": 1,
      "name": "Soil_Gravel_Lime"
    },
    {
      "x": -21,
      "y": 24,
      "z": 1,
      "name": "Rock_Lime"
    },
    {
      "x": -21,
      "y": 25,
      "z": 1,
      "name": "Rock_Lime"
    },
    {
      "x": -21,
      "y": 26,
      "z": 1,
      "name": "Rock_Lime_Cobble"
    },
    {
      "x": -21,
      "y": 27,
      "z": 1,
      "name": "Rock_Lime_Cobble"
    },
    {
      "x": -21,
      "y": 28,
      "z": 1,
      "name": "Rock_Lime"
    },
    {
      "x": -21,
      "y": 29,
      "z": 1,
      "name": "Rock_Lime"
    },
    {
      "x": -21,
      "y": 30,
      "z": 1,
      "name": "Rock_Lime_Cobble"
    },
    {
      "x": -21,
      "y": 31,
      "z": 1,
      "name": "Rock_Lime"
    },
    {
      "x": -21,
      "y": 32,
      "z": 1,
      "name": "Rock_Lime_Cobble"
    },
    {
      "x": -21,
      "y": 33,
      "z": 1,
      "name": "Soil_Gravel_Lime"
    },
    {
      "x": -21,
      "y": 34,
      "z": 1,
      "name": "Rock_Lime_Cobble"
    },
    {
      "x": -21,
      "y": 35,
      "z": 1,
      "name": "Soil_Gravel_Lime"
    },
    {
      "x": -21,
      "y": 39,
      "z": 1,
      "name": "Rock_Lime_Cobble"
    },
    {
      "x": -21,
      "y": 40,
      "z": 1,
      "name": "Rock_Lime"
    },
    {
      "x": -21,
      "y": -1,
      "z": 2,
      "name": "Rock_Lime_Brick_Smooth"
    },
    {
      "x": -21,
      "y": 0,
      "z": 2,
      "name": "Rock_Lime_Brick_Smooth"
    },
    {
      "x": -21,
      "y": 1,
      "z": 2,
      "name": "Rock_Lime_Brick"
    },
    {
      "x": -21,
      "y": 34,
      "z": 2,
      "name": "Rock_Lime"
    },
    {
      "x": -21,
      "y": 35,
      "z": 2,
      "name": "Rock_Lime"
    },
    {
      "x": -21,
      "y": 36,
      "z": 2,
      "name": "Rock_Lime"
    },
    {
      "x": -21,
      "y": 38,
      "z": 2,
      "name": "Rock_Lime"
    },
    {
      "x": -21,
      "y": 39,
      "z": 2,
      "name": "Rock_Lime_Cobble"
    },
    {
      "x": -21,
      "y": 40,
      "z": 2,
      "name": "Rock_Lime_Cobble"
    },
    {
      "x": -21,
      "y": -1,
      "z": 3,
      "name": "Rock_Lime_Brick_Smooth"
    },
    {
      "x": -21,
      "y": 0,
      "z": 3,
      "name": "Rock_Lime_Brick"
    },
    {
      "x": -21,
      "y": 1,
      "z": 3,
      "name": "Rock_Lime_Brick_Smooth"
    },
    {
      "x": -21,
      "y": -1,
      "z": 4,
      "name": "Rock_Lime_Brick"
    },
    {
      "x": -21,
      "y": 0,
      "z": 4,
      "name": "Rock_Lime_Brick"
    },
    {
      "x": -21,
      "y": 1,
      "z": 4,
      "name": "Rock_Lime_Brick_Smooth"
    },
    {
      "x": -21,
      "y": -1,
      "z": 5,
      "name": "Rock_Lime_Brick"
    },
    {
      "x": -21,
      "y": 0,
      "z": 5,
      "name": "Rock_Lime_Brick"
    },
    {
      "x": -21,
      "y": 1,
      "z": 5,
      "name": "Rock_Lime_Brick_Smooth"
    },
    {
      "x": -21,
      "y": -1,
      "z": 6,
      "name": "Rock_Lime_Brick_Smooth"
    },
    {
      "x": -21,
      "y": 0,
      "z": 6,
      "name": "Rock_Lime_Brick_Smooth"
    },
    {
      "x": -21,
      "y": 1,
      "z": 6,
      "name": "Rock_Lime_Brick_Smooth"
    },
    {
      "x": -21,
      "y": -1,
      "z": 7,
      "name": "Rock_Lime_Brick"
    },
    {
      "x": -21,
      "y": 0,
      "z": 7,
      "name": "Rock_Lime_Brick_Smooth"
    },
    {
      "x": -21,
      "y": 1,
      "z": 7,
      "name": "Rock_Lime_Brick_Smooth"
    },
    {
      "x": -21,
      "y": -1,
      "z": 8,
      "name": "Rock_Lime_Brick"
    },
    {
      "x": -21,
      "y": 0,
      "z": 8,
      "name": "Rock_Lime_Brick_Smooth"
    },
    {
      "x": -21,
      "y": 1,
      "z": 8,
      "name": "Rock_Lime_Brick_Smooth"
    },
    {
      "x": -21,
      "y": -1,
      "z": 9,
      "name": "Rock_Lime_Brick_Smooth"
    },
    {
      "x": -21,
      "y": 0,
      "z": 9,
      "name": "Rock_Lime_Brick"
    },
    {
      "x": -21,
      "y": 1,
      "z": 9,
      "name": "Rock_Lime_Brick_Smooth"
    },
    {
      "x": -21,
      "y": -1,
      "z": 10,
      "name": "Rock_Lime_Brick_Smooth"
    },
    {
      "x": -21,
      "y": 0,
      "z": 10,
      "name": "Rock_Lime_Brick_Smooth"
    },
    {
      "x": -21,
      "y": 1,
      "z": 10,
      "name": "Rock_Lime_Brick_Smooth"
    },
    {
      "x": -21,
      "y": -1,
      "z": 11,
      "name": "Rock_Lime_Brick"
    },
    {
      "x": -21,
      "y": 0,
      "z": 11,
      "name": "Rock_Lime_Brick_Smooth"
    },
    {
      "x": -21,
      "y": 1,
      "z": 11,
      "name": "Rock_Lime_Brick_Smooth"
    },
    {
      "x": -21,
      "y": -1,
      "z": 12,
      "name": "Rock_Lime_Brick"
    },
    {
      "x": -21,
      "y": 0,
      "z": 12,
      "name": "Rock_Lime_Brick_Smooth"
    },
    {
      "x": -21,
      "y": 1,
      "z": 12,
      "name": "Rock_Lime_Brick_Smooth"
    },
    {
      "x": -21,
      "y": -1,
      "z": 13,
      "name": "Rock_Lime_Brick_Smooth"
    },
    {
      "x": -21,
      "y": 0,
      "z": 13,
      "name": "Rock_Lime_Brick_Smooth"
    },
    {
      "x": -21,
      "y": -1,
      "z": 14,
      "name": "Rock_Lime_Brick_Smooth"
    },
    {
      "x": -21,
      "y": 0,
      "z": 14,
      "name": "Rock_Lime_Brick_Smooth"
    },
    {
      "x": -21,
      "y": -1,
      "z": 15,
      "name": "Rock_Lime_Brick_Smooth"
    },
    {
      "x": -21,
      "y": 0,
      "z": 15,
      "name": "Rock_Lime_Brick_Smooth"
    },
    {
      "x": -21,
      "y": -1,
      "z": 16,
      "name": "Rock_Lime_Brick_Smooth"
    },
    {
      "x": -21,
      "y": 0,
      "z": 16,
      "name": "Rock_Lime_Brick_Smooth"
    },
    {
      "x": -21,
      "y": -1,
      "z": 17,
      "name": "Rock_Lime_Brick_Smooth"
    },
    {
      "x": -21,
      "y": 0,
      "z": 17,
      "name": "Rock_Lime_Brick_Smooth"
    },
    {
      "x": -21,
      "y": -1,
      "z": 18,
      "name": "Rock_Lime_Brick_Smooth"
    },
    {
      "x": -21,
      "y": 0,
      "z": 18,
      "name": "Rock_Lime_Brick_Smooth"
    },
    {
      "x": -21,
      "y": -1,
      "z": 19,
      "name": "Rock_Lime_Brick_Smooth"
    },
    {
      "x": -21,
      "y": 0,
      "z": 19,
      "name": "Rock_Lime_Brick_Smooth"
    },
    {
      "x": -21,
      "y": -1,
      "z": 20,
      "name": "Rock_Lime_Brick_Smooth"
    },
    {
      "x": -21,
      "y": -1,
      "z": 21,
      "name": "Rock_Lime_Brick"
    },
    {
      "x": -21,
      "y": -1,
      "z": 22,
      "name": "Rock_Lime_Brick"
    },
    {
      "x": -21,
      "y": -1,
      "z": 23,
      "name": "Rock_Lime_Brick"
    },
    {
      "x": -21,
      "y": -1,
      "z": 24,
      "name": "Rock_Lime_Brick"
    },
    {
      "x": -20,
      "y": -1,
      "z": -25,
      "name": "Rock_Lime_Brick"
    },
    {
      "x": -20,
      "y": -1,
      "z": -24,
      "name": "Rock_Lime_Brick_Smooth"
    },
    {
      "x": -20,
      "y": -1,
      "z": -23,
      "name": "Rock_Lime_Brick"
    },
    {
      "x": -20,
      "y": -1,
      "z": -22,
      "name": "Rock_Lime_Brick_Smooth"
    },
    {
      "x": -20,
      "y": -1,
      "z": -21,
      "name": "Rock_Lime_Brick_Smooth"
    },
    {
      "x": -20,
      "y": -1,
      "z": -20,
      "name": "Rock_Lime_Brick"
    },
    {
      "x": -20,
      "y": 0,
      "z": -20,
      "name": "Rock_Lime_Brick_Smooth"
    },
    {
      "x": -20,
      "y": -1,
      "z": -19,
      "name": "Rock_Lime_Brick_Smooth"
    },
    {
      "x": -20,
      "y": 0,
      "z": -19,
      "name": "Rock_Lime_Brick_Smooth"
    },
    {
      "x": -20,
      "y": -1,
      "z": -18,
      "name": "Rock_Lime_Brick"
    },
    {
      "x": -20,
      "y": 0,
      "z": -18,
      "name": "Rock_Lime_Brick_Smooth"
    },
    {
      "x": -20,
      "y": -1,
      "z": -17,
      "name": "Rock_Lime_Brick"
    },
    {
      "x": -20,
      "y": 0,
      "z": -17,
      "name": "Rock_Lime_Brick_Smooth"
    },
    {
      "x": -20,
      "y": -1,
      "z": -16,
      "name": "Rock_Lime_Brick_Smooth"
    },
    {
      "x": -20,
      "y": 0,
      "z": -16,
      "name": "Rock_Lime_Brick_Smooth"
    },
    {
      "x": -20,
      "y": -1,
      "z": -15,
      "name": "Rock_Lime_Brick_Smooth"
    },
    {
      "x": -20,
      "y": 0,
      "z": -15,
      "name": "Rock_Lime_Brick_Smooth"
    },
    {
      "x": -20,
      "y": -1,
      "z": -14,
      "name": "Rock_Lime_Brick_Smooth"
    },
    {
      "x": -20,
      "y": 0,
      "z": -14,
      "name": "Rock_Lime_Brick_Smooth"
    },
    {
      "x": -20,
      "y": -1,
      "z": -13,
      "name": "Rock_Lime_Brick"
    },
    {
      "x": -20,
      "y": 0,
      "z": -13,
      "name": "Rock_Lime_Brick_Smooth"
    },
    {
      "x": -20,
      "y": 1,
      "z": -13,
      "name": "Rock_Lime_Brick_Smooth"
    },
    {
      "x": -20,
      "y": -1,
      "z": -12,
      "name": "Rock_Lime_Brick_Smooth"
    },
    {
      "x": -20,
      "y": 0,
      "z": -12,
      "name": "Rock_Lime_Brick"
    },
    {
      "x": -20,
      "y": 1,
      "z": -12,
      "name": "Rock_Lime_Brick_Smooth"
    },
    {
      "x": -20,
      "y": -1,
      "z": -11,
      "name": "Rock_Lime_Brick_Smooth"
    },
    {
      "x": -20,
      "y": 0,
      "z": -11,
      "name": "Rock_Lime_Brick_Smooth"
    },
    {
      "x": -20,
      "y": 1,
      "z": -11,
      "name": "Rock_Lime_Brick_Smooth"
    },
    {
      "x": -20,
      "y": -1,
      "z": -10,
      "name": "Rock_Lime_Brick_Smooth"
    },
    {
      "x": -20,
      "y": 0,
      "z": -10,
      "name": "Rock_Lime_Brick_Smooth"
    },
    {
      "x": -20,
      "y": 1,
      "z": -10,
      "name": "Rock_Lime_Brick_Smooth"
    },
    {
      "x": -20,
      "y": -1,
      "z": -9,
      "name": "Rock_Lime_Brick_Smooth"
    },
    {
      "x": -20,
      "y": 0,
      "z": -9,
      "name": "Rock_Lime_Brick_Smooth"
    },
    {
      "x": -20,
      "y": 1,
      "z": -9,
      "name": "Rock_Lime_Brick_Smooth"
    },
    {
      "x": -20,
      "y": -1,
      "z": -8,
      "name": "Rock_Lime_Brick"
    },
    {
      "x": -20,
      "y": 0,
      "z": -8,
      "name": "Rock_Lime_Brick"
    },
    {
      "x": -20,
      "y": 1,
      "z": -8,
      "name": "Rock_Lime_Brick_Smooth"
    },
    {
      "x": -20,
      "y": -1,
      "z": -7,
      "name": "Rock_Lime_Brick_Smooth"
    },
    {
      "x": -20,
      "y": 0,
      "z": -7,
      "name": "Rock_Lime_Brick_Smooth"
    },
    {
      "x": -20,
      "y": 1,
      "z": -7,
      "name": "Rock_Lime_Brick_Smooth"
    },
    {
      "x": -20,
      "y": -1,
      "z": -6,
      "name": "Rock_Lime_Brick_Smooth"
    },
    {
      "x": -20,
      "y": 0,
      "z": -6,
      "name": "Rock_Lime_Brick_Smooth"
    },
    {
      "x": -20,
      "y": 1,
      "z": -6,
      "name": "Rock_Lime_Brick_Smooth"
    },
    {
      "x": -20,
      "y": -1,
      "z": -5,
      "name": "Rock_Lime_Brick_Smooth"
    },
    {
      "x": -20,
      "y": 0,
      "z": -5,
      "name": "Rock_Lime_Brick_Smooth"
    },
    {
      "x": -20,
      "y": 1,
      "z": -5,
      "name": "Rock_Lime_Brick"
    },
    {
      "x": -20,
      "y": -1,
      "z": -4,
      "name": "Rock_Lime_Brick_Smooth"
    },
    {
      "x": -20,
      "y": 0,
      "z": -4,
      "name": "Rock_Lime_Brick_Smooth"
    },
    {
      "x": -20,
      "y": 1,
      "z": -4,
      "name": "Rock_Lime_Brick"
    },
    {
      "x": -20,
      "y": -1,
      "z": -3,
      "name": "Rock_Lime_Brick_Smooth"
    },
    {
      "x": -20,
      "y": 0,
      "z": -3,
      "name": "Rock_Lime_Brick_Smooth"
    },
    {
      "x": -20,
      "y": 1,
      "z": -3,
      "name": "Rock_Lime_Brick_Smooth"
    },
    {
      "x": -20,
      "y": -1,
      "z": -2,
      "name": "Rock_Lime_Brick_Smooth"
    },
    {
      "x": -20,
      "y": 0,
      "z": -2,
      "name": "Rock_Lime_Brick_Smooth"
    },
    {
      "x": -20,
      "y": 1,
      "z": -2,
      "name": "Rock_Lime_Brick_Smooth"
    },
    {
      "x": -20,
      "y": 2,
      "z": -2,
      "name": "Soil_Gravel_Lime"
    },
    {
      "x": -20,
      "y": 3,
      "z": -2,
      "name": "Soil_Gravel_Lime"
    },
    {
      "x": -20,
      "y": 4,
      "z": -2,
      "name": "Soil_Gravel_Lime"
    },
    {
      "x": -20,
      "y": 5,
      "z": -2,
      "name": "Rock_Lime_Cobble"
    },
    {
      "x": -20,
      "y": 6,
      "z": -2,
      "name": "Rock_Lime_Cobble"
    },
    {
      "x": -20,
      "y": 7,
      "z": -2,
      "name": "Rock_Lime_Cobble"
    },
    {
      "x": -20,
      "y": 8,
      "z": -2,
      "name": "Rock_Lime"
    },
    {
      "x": -20,
      "y": 9,
      "z": -2,
      "name": "Soil_Gravel_Lime"
    },
    {
      "x": -20,
      "y": 10,
      "z": -2,
      "name": "Soil_Gravel_Lime"
    },
    {
      "x": -20,
      "y": 11,
      "z": -2,
      "name": "Rock_Lime"
    },
    {
      "x": -20,
      "y": 12,
      "z": -2,
      "name": "Rock_Lime"
    },
    {
      "x": -20,
      "y": 13,
      "z": -2,
      "name": "Rock_Lime_Cobble"
    },
    {
      "x": -20,
      "y": 14,
      "z": -2,
      "name": "Rock_Lime_Cobble"
    },
    {
      "x": -20,
      "y": 15,
      "z": -2,
      "name": "Rock_Lime"
    },
    {
      "x": -20,
      "y": 16,
      "z": -2,
      "name": "Rock_Lime_Cobble"
    },
    {
      "x": -20,
      "y": 17,
      "z": -2,
      "name": "Rock_Lime"
    },
    {
      "x": -20,
      "y": 18,
      "z": -2,
      "name": "Rock_Lime_Cobble"
    },
    {
      "x": -20,
      "y": 19,
      "z": -2,
      "name": "Rock_Lime_Cobble"
    },
    {
      "x": -20,
      "y": 20,
      "z": -2,
      "name": "Rock_Lime_Cobble"
    },
    {
      "x": -20,
      "y": 21,
      "z": -2,
      "name": "Rock_Lime"
    },
    {
      "x": -20,
      "y": 22,
      "z": -2,
      "name": "Rock_Lime_Cobble"
    },
    {
      "x": -20,
      "y": 23,
      "z": -2,
      "name": "Rock_Lime"
    },
    {
      "x": -20,
      "y": 24,
      "z": -2,
      "name": "Rock_Lime_Cobble"
    },
    {
      "x": -20,
      "y": 25,
      "z": -2,
      "name": "Rock_Lime"
    },
    {
      "x": -20,
      "y": 26,
      "z": -2,
      "name": "Rock_Lime"
    },
    {
      "x": -20,
      "y": 27,
      "z": -2,
      "name": "Rock_Lime_Cobble"
    },
    {
      "x": -20,
      "y": 28,
      "z": -2,
      "name": "Rock_Lime"
    },
    {
      "x": -20,
      "y": 29,
      "z": -2,
      "name": "Rock_Lime"
    },
    {
      "x": -20,
      "y": 30,
      "z": -2,
      "name": "Rock_Lime"
    },
    {
      "x": -20,
      "y": 31,
      "z": -2,
      "name": "Rock_Lime"
    },
    {
      "x": -20,
      "y": 32,
      "z": -2,
      "name": "Rock_Lime"
    },
    {
      "x": -20,
      "y": 33,
      "z": -2,
      "name": "Rock_Lime"
    },
    {
      "x": -20,
      "y": 34,
      "z": -2,
      "name": "Rock_Lime_Cobble"
    },
    {
      "x": -20,
      "y": 35,
      "z": -2,
      "name": "Rock_Lime"
    },
    {
      "x": -20,
      "y": 39,
      "z": -2,
      "name": "Rock_Lime"
    },
    {
      "x": -20,
      "y": 40,
      "z": -2,
      "name": "Rock_Lime"
    },
    {
      "x": -20,
      "y": -1,
      "z": -1,
      "name": "Rock_Lime_Brick"
    },
    {
      "x": -20,
      "y": 0,
      "z": -1,
      "name": "Rock_Lime_Brick_Smooth"
    },
    {
      "x": -20,
      "y": 1,
      "z": -1,
      "name": "Rock_Lime_Brick"
    },
    {
      "x": -20,
      "y": 33,
      "z": -1,
      "name": "Rock_Lime_Cobble"
    },
    {
      "x": -20,
      "y": 34,
      "z": -1,
      "name": "Rock_Lime"
    },
    {
      "x": -20,
      "y": 40,
      "z": -1,
      "name": "Rock_Lime"
    },
    {
      "x": -20,
      "y": -1,
      "z": 0,
      "name": "Rock_Lime_Brick_Smooth"
    },
    {
      "x": -20,
      "y": 0,
      "z": 0,
      "name": "Rock_Lime_Brick_Smooth"
    },
    {
      "x": -20,
      "y": 1,
      "z": 0,
      "name": "Rock_Lime_Brick"
    },
    {
      "x": -20,
      "y": 33,
      "z": 0,
      "name": "Rock_Lime"
    },
    {
      "x": -20,
      "y": 34,
      "z": 0,
      "name": "Rock_Lime"
    },
    {
      "x": -20,
      "y": 36,
      "z": 0,
      "name": "Deco_Rope_Diagonal",
      "rotation": 3
    },
    {
      "x": -20,
      "y": 37,
      "z": 0,
      "name": "Rock_Crystal_White_Block",
      "rotation": 5
    },
    {
      "x": -20,
      "y": 38,
      "z": 0,
      "name": "Deco_Rope_Diagonal",
      "rotation": 1
    },
    {
      "x": -20,
      "y": 40,
      "z": 0,
      "name": "Rock_Lime_Cobble"
    },
    {
      "x": -20,
      "y": -1,
      "z": 1,
      "name": "Rock_Lime_Brick_Smooth"
    },
    {
      "x": -20,
      "y": 0,
      "z": 1,
      "name": "Rock_Lime_Brick"
    },
    {
      "x": -20,
      "y": 1,
      "z": 1,
      "name": "Rock_Lime_Brick_Smooth"
    },
    {
      "x": -20,
      "y": 33,
      "z": 1,
      "name": "Soil_Gravel_Lime"
    },
    {
      "x": -20,
      "y": 34,
      "z": 1,
      "name": "Rock_Lime_Cobble"
    },
    {
      "x": -20,
      "y": 40,
      "z": 1,
      "name": "Rock_Lime_Cobble"
    },
    {
      "x": -20,
      "y": -1,
      "z": 2,
      "name": "Rock_Lime_Brick"
    },
    {
      "x": -20,
      "y": 0,
      "z": 2,
      "name": "Rock_Lime_Brick_Smooth"
    },
    {
      "x": -20,
      "y": 1,
      "z": 2,
      "name": "Rock_Lime_Brick_Smooth"
    },
    {
      "x": -20,
      "y": 2,
      "z": 2,
      "name": "Rock_Lime"
    },
    {
      "x": -20,
      "y": 3,
      "z": 2,
      "name": "Rock_Lime"
    },
    {
      "x": -20,
      "y": 4,
      "z": 2,
      "name": "Rock_Lime_Cobble"
    },
    {
      "x": -20,
      "y": 5,
      "z": 2,
      "name": "Soil_Gravel_Lime"
    },
    {
      "x": -20,
      "y": 6,
      "z": 2,
      "name": "Rock_Lime"
    },
    {
      "x": -20,
      "y": 7,
      "z": 2,
      "name": "Rock_Lime_Cobble"
    },
    {
      "x": -20,
      "y": 8,
      "z": 2,
      "name": "Rock_Lime"
    },
    {
      "x": -20,
      "y": 9,
      "z": 2,
      "name": "Rock_Lime"
    },
    {
      "x": -20,
      "y": 10,
      "z": 2,
      "name": "Rock_Lime"
    },
    {
      "x": -20,
      "y": 11,
      "z": 2,
      "name": "Rock_Lime"
    },
    {
      "x": -20,
      "y": 12,
      "z": 2,
      "name": "Rock_Lime_Cobble"
    },
    {
      "x": -20,
      "y": 13,
      "z": 2,
      "name": "Rock_Lime_Cobble"
    },
    {
      "x": -20,
      "y": 14,
      "z": 2,
      "name": "Rock_Lime_Cobble"
    },
    {
      "x": -20,
      "y": 15,
      "z": 2,
      "name": "Soil_Gravel_Lime"
    },
    {
      "x": -20,
      "y": 16,
      "z": 2,
      "name": "Rock_Lime"
    },
    {
      "x": -20,
      "y": 17,
      "z": 2,
      "name": "Rock_Lime"
    },
    {
      "x": -20,
      "y": 18,
      "z": 2,
      "name": "Rock_Lime_Cobble"
    },
    {
      "x": -20,
      "y": 19,
      "z": 2,
      "name": "Rock_Lime"
    },
    {
      "x": -20,
      "y": 20,
      "z": 2,
      "name": "Soil_Gravel_Lime"
    },
    {
      "x": -20,
      "y": 21,
      "z": 2,
      "name": "Rock_Lime"
    },
    {
      "x": -20,
      "y": 22,
      "z": 2,
      "name": "Rock_Lime"
    },
    {
      "x": -20,
      "y": 23,
      "z": 2,
      "name": "Rock_Lime"
    },
    {
      "x": -20,
      "y": 24,
      "z": 2,
      "name": "Rock_Lime_Cobble"
    },
    {
      "x": -20,
      "y": 25,
      "z": 2,
      "name": "Rock_Lime_Cobble"
    },
    {
      "x": -20,
      "y": 26,
      "z": 2,
      "name": "Soil_Gravel_Lime"
    },
    {
      "x": -20,
      "y": 27,
      "z": 2,
      "name": "Rock_Lime_Cobble"
    },
    {
      "x": -20,
      "y": 28,
      "z": 2,
      "name": "Rock_Lime"
    },
    {
      "x": -20,
      "y": 29,
      "z": 2,
      "name": "Rock_Lime"
    },
    {
      "x": -20,
      "y": 30,
      "z": 2,
      "name": "Soil_Gravel_Lime"
    },
    {
      "x": -20,
      "y": 31,
      "z": 2,
      "name": "Rock_Lime_Cobble"
    },
    {
      "x": -20,
      "y": 32,
      "z": 2,
      "name": "Rock_Lime"
    },
    {
      "x": -20,
      "y": 33,
      "z": 2,
      "name": "Rock_Lime"
    },
    {
      "x": -20,
      "y": 34,
      "z": 2,
      "name": "Rock_Lime_Cobble"
    },
    {
      "x": -20,
      "y": 35,
      "z": 2,
      "name": "Rock_Lime_Cobble"
    },
    {
      "x": -20,
      "y": 39,
      "z": 2,
      "name": "Rock_Lime_Cobble"
    },
    {
      "x": -20,
      "y": 40,
      "z": 2,
      "name": "Rock_Lime"
    },
    {
      "x": -20,
      "y": -1,
      "z": 3,
      "name": "Rock_Lime_Brick_Smooth"
    },
    {
      "x": -20,
      "y": 0,
      "z": 3,
      "name": "Rock_Lime_Brick"
    },
    {
      "x": -20,
      "y": 1,
      "z": 3,
      "name": "Rock_Lime_Brick_Smooth"
    },
    {
      "x": -20,
      "y": -1,
      "z": 4,
      "name": "Rock_Lime_Brick_Smooth"
    },
    {
      "x": -20,
      "y": 0,
      "z": 4,
      "name": "Rock_Lime_Brick_Smooth"
    },
    {
      "x": -20,
      "y": 1,
      "z": 4,
      "name": "Rock_Lime_Brick_Smooth"
    },
    {
      "x": -20,
      "y": -1,
      "z": 5,
      "name": "Rock_Lime_Brick_Smooth"
    },
    {
      "x": -20,
      "y": 0,
      "z": 5,
      "name": "Rock_Lime_Brick"
    },
    {
      "x": -20,
      "y": 1,
      "z": 5,
      "name": "Rock_Lime_Brick_Smooth"
    },
    {
      "x": -20,
      "y": -1,
      "z": 6,
      "name": "Rock_Lime_Brick"
    },
    {
      "x": -20,
      "y": 0,
      "z": 6,
      "name": "Rock_Lime_Brick_Smooth"
    },
    {
      "x": -20,
      "y": 1,
      "z": 6,
      "name": "Rock_Lime_Brick_Smooth"
    },
    {
      "x": -20,
      "y": -1,
      "z": 7,
      "name": "Rock_Lime_Brick"
    },
    {
      "x": -20,
      "y": 0,
      "z": 7,
      "name": "Rock_Lime_Brick"
    },
    {
      "x": -20,
      "y": 1,
      "z": 7,
      "name": "Rock_Lime_Brick_Smooth"
    },
    {
      "x": -20,
      "y": -1,
      "z": 8,
      "name": "Rock_Lime_Brick"
    },
    {
      "x": -20,
      "y": 0,
      "z": 8,
      "name": "Rock_Lime_Brick_Smooth"
    },
    {
      "x": -20,
      "y": 1,
      "z": 8,
      "name": "Rock_Lime_Brick_Smooth"
    },
    {
      "x": -20,
      "y": -1,
      "z": 9,
      "name": "Rock_Lime_Brick_Smooth"
    },
    {
      "x": -20,
      "y": 0,
      "z": 9,
      "name": "Rock_Lime_Brick_Smooth"
    },
    {
      "x": -20,
      "y": 1,
      "z": 9,
      "name": "Rock_Lime_Brick_Smooth"
    },
    {
      "x": -20,
      "y": -1,
      "z": 10,
      "name": "Rock_Lime_Brick"
    },
    {
      "x": -20,
      "y": 0,
      "z": 10,
      "name": "Rock_Lime_Brick_Smooth"
    },
    {
      "x": -20,
      "y": 1,
      "z": 10,
      "name": "Rock_Lime_Brick_Smooth"
    },
    {
      "x": -20,
      "y": -1,
      "z": 11,
      "name": "Rock_Lime_Brick_Smooth"
    },
    {
      "x": -20,
      "y": 0,
      "z": 11,
      "name": "Rock_Lime_Brick"
    },
    {
      "x": -20,
      "y": 1,
      "z": 11,
      "name": "Rock_Lime_Brick_Smooth"
    },
    {
      "x": -20,
      "y": -1,
      "z": 12,
      "name": "Rock_Lime_Brick_Smooth"
    },
    {
      "x": -20,
      "y": 0,
      "z": 12,
      "name": "Rock_Lime_Brick_Smooth"
    },
    {
      "x": -20,
      "y": 1,
      "z": 12,
      "name": "Rock_Lime_Brick_Smooth"
    },
    {
      "x": -20,
      "y": -1,
      "z": 13,
      "name": "Rock_Lime_Brick_Smooth"
    },
    {
      "x": -20,
      "y": 0,
      "z": 13,
      "name": "Rock_Lime_Brick_Smooth"
    },
    {
      "x": -20,
      "y": 1,
      "z": 13,
      "name": "Rock_Lime_Brick_Smooth"
    },
    {
      "x": -20,
      "y": -1,
      "z": 14,
      "name": "Rock_Lime_Brick"
    },
    {
      "x": -20,
      "y": 0,
      "z": 14,
      "name": "Rock_Lime_Brick_Smooth"
    },
    {
      "x": -20,
      "y": -1,
      "z": 15,
      "name": "Rock_Lime_Brick_Smooth"
    },
    {
      "x": -20,
      "y": 0,
      "z": 15,
      "name": "Rock_Lime_Brick_Smooth"
    },
    {
      "x": -20,
      "y": -1,
      "z": 16,
      "name": "Rock_Lime_Brick_Smooth"
    },
    {
      "x": -20,
      "y": 0,
      "z": 16,
      "name": "Rock_Lime_Brick_Smooth"
    },
    {
      "x": -20,
      "y": -1,
      "z": 17,
      "name": "Rock_Lime_Brick"
    },
    {
      "x": -20,
      "y": 0,
      "z": 17,
      "name": "Rock_Lime_Brick_Smooth"
    },
    {
      "x": -20,
      "y": -1,
      "z": 18,
      "name": "Rock_Lime_Brick_Smooth"
    },
    {
      "x": -20,
      "y": 0,
      "z": 18,
      "name": "Rock_Lime_Brick_Smooth"
    },
    {
      "x": -20,
      "y": -1,
      "z": 19,
      "name": "Rock_Lime_Brick_Smooth"
    },
    {
      "x": -20,
      "y": 0,
      "z": 19,
      "name": "Rock_Lime_Brick_Smooth"
    },
    {
      "x": -20,
      "y": -1,
      "z": 20,
      "name": "Rock_Lime_Brick_Smooth"
    },
    {
      "x": -20,
      "y": 0,
      "z": 20,
      "name": "Rock_Lime_Brick_Smooth"
    },
    {
      "x": -20,
      "y": -1,
      "z": 21,
      "name": "Rock_Lime_Brick_Smooth"
    },
    {
      "x": -20,
      "y": -1,
      "z": 22,
      "name": "Rock_Lime_Brick_Smooth"
    },
    {
      "x": -20,
      "y": -1,
      "z": 23,
      "name": "Rock_Lime_Brick_Smooth"
    },
    {
      "x": -20,
      "y": -1,
      "z": 24,
      "name": "Rock_Lime_Brick_Smooth"
    },
    {
      "x": -20,
      "y": -1,
      "z": 25,
      "name": "Rock_Lime_Brick_Smooth"
    },
    {
      "x": -19,
      "y": -1,
      "z": -26,
      "name": "Rock_Lime_Brick_Smooth"
    },
    {
      "x": -19,
      "y": -1,
      "z": -25,
      "name": "Rock_Lime_Brick_Smooth"
    },
    {
      "x": -19,
      "y": -1,
      "z": -24,
      "name": "Rock_Lime_Brick"
    },
    {
      "x": -19,
      "y": -1,
      "z": -23,
      "name": "Rock_Lime_Brick_Smooth"
    },
    {
      "x": -19,
      "y": -1,
      "z": -22,
      "name": "Rock_Lime_Brick_Smooth"
    },
    {
      "x": -19,
      "y": -1,
      "z": -21,
      "name": "Rock_Lime_Brick_Smooth"
    },
    {
      "x": -19,
      "y": 0,
      "z": -21,
      "name": "Rock_Lime_Brick"
    },
    {
      "x": -19,
      "y": -1,
      "z": -20,
      "name": "Rock_Lime_Brick_Smooth"
    },
    {
      "x": -19,
      "y": 0,
      "z": -20,
