{
  "version": 8,
  "blockIdVersion": 11,
  "anchorX": 0,
  "anchorY": 0,
  "anchorZ": 0,
  "blocks": [
    {
      "x": -24,
      "y": 77,
      "z": -8,
      "name": "Rock_Calcite"
    },
    {
      "x": -24,
      "y": 75,
      "z": -7,
      "name": "Rock_Calcite"
    },
    {
      "x": -24,
      "y": 76,
      "z": -7,
      "name": "Rock_Calcite"
    },
    {
      "x": -24,
      "y": 77,
      "z": -7,
      "name": "Rock_Calcite"
    },
    {
      "x": -24,
      "y": 78,
      "z": -7,
      "name": "Rock_Calcite"
    },
    {
      "x": -24,
      "y": 74,
      "z": -6,
      "name": "Rock_Calcite"
    },
    {
      "x": -24,
      "y": 75,
      "z": -6,
      "name": "Rock_Calcite"
    },
    {
      "x": -24,
      "y": 76,
      "z": -6,
      "name": "Rock_Calcite"
    },
    {
      "x": -24,
      "y": 77,
      "z": -6,
      "name": "Rock_Calcite"
    },
    {
      "x": -24,
      "y": 78,
      "z": -6,
      "name": "Rock_Calcite"
    },
    {
      "x": -24,
      "y": 73,
      "z": -5,
      "name": "Rock_Calcite"
    },
    {
      "x": -24,
      "y": 74,
      "z": -5,
      "name": "Rock_Calcite"
    },
    {
      "x": -24,
      "y": 75,
      "z": -5,
      "name": "Rock_Calcite"
    },
    {
      "x": -24,
      "y": 76,
      "z": -5,
      "name": "Rock_Calcite"
    },
    {
      "x": -24,
      "y": 77,
      "z": -5,
      "name": "Rock_Calcite"
    },
    {
      "x": -24,
      "y": 78,
      "z": -5,
      "name": "Rock_Calcite"
    },
    {
      "x": -24,
      "y": 79,
      "z": -5,
      "name": "Rock_Calcite"
    },
    {
      "x": -24,
      "y": 74,
      "z": -4,
      "name": "Rock_Calcite"
    },
    {
      "x": -24,
      "y": 75,
      "z": -4,
      "name": "Rock_Calcite"
    },
    {
      "x": -24,
      "y": 77,
      "z": -4,
      "name": "Rock_Calcite"
    },
    {
      "x": -24,
      "y": 78,
      "z": -4,
      "name": "Rock_Calcite"
    },
    {
      "x": -23,
      "y": 76,
      "z": -10,
      "name": "Rock_Calcite"
    },
    {
      "x": -23,
      "y": 77,
      "z": -10,
      "name": "Rock_Calcite"
    },
    {
      "x": -23,
      "y": 78,
      "z": -10,
      "name": "Rock_Calcite"
    },
    {
      "x": -23,
      "y": 74,
      "z": -9,
      "name": "Rock_Calcite"
    },
    {
      "x": -23,
      "y": 75,
      "z": -9,
      "name": "Rock_Calcite"
    },
    {
      "x": -23,
      "y": 76,
      "z": -9,
      "name": "Rock_Calcite"
    },
    {
      "x": -23,
      "y": 77,
      "z": -9,
      "name": "Rock_Calcite"
    },
    {
      "x": -23,
      "y": 78,
      "z": -9,
      "name": "Rock_Calcite"
    },
    {
      "x": -23,
      "y": 73,
      "z": -8,
      "name": "Rock_Calcite"
    },
    {
      "x": -23,
      "y": 74,
      "z": -8,
      "name": "Rock_Calcite"
    },
    {
      "x": -23,
      "y": 75,
      "z": -8,
      "name": "Rock_Calcite"
    },
    {
      "x": -23,
      "y": 76,
      "z": -8,
      "name": "Rock_Calcite"
    },
    {
      "x": -23,
      "y": 77,
      "z": -8,
      "name": "Rock_Calcite"
    },
    {
      "x": -23,
      "y": 78,
      "z": -8,
      "name": "Rock_Calcite"
    },
    {
      "x": -23,
      "y": 79,
      "z": -8,
      "name": "Rock_Calcite"
    },
    {
      "x": -23,
      "y": 72,
      "z": -7,
      "name": "Rock_Calcite"
    },
    {
      "x": -23,
      "y": 73,
      "z": -7,
      "name": "Rock_Calcite"
    },
    {
      "x": -23,
      "y": 74,
      "z": -7,
      "name": "Rock_Calcite"
    },
    {
      "x": -23,
      "y": 75,
      "z": -7,
      "name": "Rock_Calcite"
    },
    {
      "x": -23,
      "y": 76,
      "z": -7,
      "name": "Rock_Calcite"
    },
    {
      "x": -23,
      "y": 77,
      "z": -7,
      "name": "Rock_Calcite"
    },
    {
      "x": -23,
      "y": 78,
      "z": -7,
      "name": "Rock_Calcite"
    },
    {
      "x": -23,
      "y": 79,
      "z": -7,
      "name": "Rock_Calcite"
    },
    {
      "x": -23,
      "y": 71,
      "z": -6,
      "name": "Rock_Calcite"
    },
    {
      "x": -23,
      "y": 72,
      "z": -6,
      "name": "Rock_Calcite"
    },
    {
      "x": -23,
      "y": 73,
      "z": -6,
      "name": "Rock_Calcite"
    },
    {
      "x": -23,
      "y": 74,
      "z": -6,
      "name": "Rock_Calcite"
    },
    {
      "x": -23,
      "y": 75,
      "z": -6,
      "name": "Rock_Calcite"
    },
    {
      "x": -23,
      "y": 76,
      "z": -6,
      "name": "Rock_Calcite"
    },
    {
      "x": -23,
      "y": 77,
      "z": -6,
      "name": "Rock_Calcite"
    },
    {
      "x": -23,
      "y": 78,
      "z": -6,
      "name": "Rock_Calcite"
    },
    {
      "x": -23,
      "y": 79,
      "z": -6,
      "name": "Rock_Calcite"
    },
    {
      "x": -23,
      "y": 70,
      "z": -5,
      "name": "Rock_Calcite"
    },
    {
      "x": -23,
      "y": 71,
      "z": -5,
      "name": "Rock_Calcite"
    },
    {
      "x": -23,
      "y": 72,
      "z": -5,
      "name": "Rock_Calcite"
    },
    {
      "x": -23,
      "y": 73,
      "z": -5,
      "name": "Rock_Calcite"
    },
    {
      "x": -23,
      "y": 74,
      "z": -5,
      "name": "Rock_Calcite"
    },
    {
      "x": -23,
      "y": 75,
      "z": -5,
      "name": "Rock_Calcite"
    },
    {
      "x": -23,
      "y": 76,
      "z": -5,
      "name": "Rock_Calcite"
    },
    {
      "x": -23,
      "y": 77,
      "z": -5,
      "name": "Rock_Calcite"
    },
    {
      "x": -23,
      "y": 78,
      "z": -5,
      "name": "Rock_Calcite"
    },
    {
      "x": -23,
      "y": 79,
      "z": -5,
      "name": "Rock_Calcite"
    },
    {
      "x": -23,
      "y": 71,
      "z": -4,
      "name": "Rock_Calcite"
    },
    {
      "x": -23,
      "y": 72,
      "z": -4,
      "name": "Rock_Calcite"
    },
    {
      "x": -23,
      "y": 74,
      "z": -4,
      "name": "Rock_Calcite"
    },
    {
      "x": -23,
      "y": 78,
      "z": -4,
      "name": "Rock_Calcite"
    },
    {
      "x": -23,
      "y": 79,
      "z": -4,
      "name": "Rock_Calcite"
    },
    {
      "x": -22,
      "y": 73,
      "z": -11,
      "name": "Rock_Calcite"
    },
    {
      "x": -22,
      "y": 74,
      "z": -11,
      "name": "Rock_Calcite"
    },
    {
      "x": -22,
      "y": 75,
      "z": -11,
      "name": "Rock_Calcite"
    },
    {
      "x": -22,
      "y": 76,
      "z": -11,
      "name": "Rock_Calcite"
    },
    {
      "x": -22,
      "y": 72,
      "z": -10,
      "name": "Rock_Calcite"
    },
    {
      "x": -22,
      "y": 73,
      "z": -10,
      "name": "Rock_Calcite"
    },
    {
      "x": -22,
      "y": 74,
      "z": -10,
      "name": "Rock_Calcite"
    },
    {
      "x": -22,
      "y": 75,
      "z": -10,
      "name": "Rock_Calcite"
    },
    {
      "x": -22,
      "y": 76,
      "z": -10,
      "name": "Rock_Calcite"
    },
    {
      "x": -22,
      "y": 77,
      "z": -10,
      "name": "Rock_Calcite"
    },
    {
      "x": -22,
      "y": 71,
      "z": -9,
      "name": "Rock_Calcite"
    },
    {
      "x": -22,
      "y": 72,
      "z": -9,
      "name": "Rock_Calcite"
    },
    {
      "x": -22,
      "y": 73,
      "z": -9,
      "name": "Rock_Calcite"
    },
    {
      "x": -22,
      "y": 74,
      "z": -9,
      "name": "Rock_Calcite"
    },
    {
      "x": -22,
      "y": 75,
      "z": -9,
      "name": "Rock_Calcite"
    },
    {
      "x": -22,
      "y": 76,
      "z": -9,
      "name": "Rock_Calcite"
    },
    {
      "x": -22,
      "y": 77,
      "z": -9,
      "name": "Rock_Calcite"
    },
    {
      "x": -22,
      "y": 78,
      "z": -9,
      "name": "Rock_Calcite"
    },
    {
      "x": -22,
      "y": 62,
      "z": -8,
      "name": "Rock_Calcite"
    },
    {
      "x": -22,
      "y": 63,
      "z": -8,
      "name": "Rock_Calcite"
    },
    {
      "x": -22,
      "y": 64,
      "z": -8,
      "name": "Rock_Calcite"
    },
    {
      "x": -22,
      "y": 69,
      "z": -8,
      "name": "Rock_Calcite"
    },
    {
      "x": -22,
      "y": 70,
      "z": -8,
      "name": "Rock_Calcite"
    },
    {
      "x": -22,
      "y": 71,
      "z": -8,
      "name": "Rock_Calcite"
    },
    {
      "x": -22,
      "y": 72,
      "z": -8,
      "name": "Rock_Calcite"
    },
    {
      "x": -22,
      "y": 73,
      "z": -8,
      "name": "Rock_Calcite"
    },
    {
      "x": -22,
      "y": 74,
      "z": -8,
      "name": "Rock_Calcite"
    },
    {
      "x": -22,
      "y": 75,
      "z": -8,
      "name": "Rock_Calcite"
    },
    {
      "x": -22,
      "y": 76,
      "z": -8,
      "name": "Rock_Calcite"
    },
    {
      "x": -22,
      "y": 77,
      "z": -8,
      "name": "Rock_Calcite"
    },
    {
      "x": -22,
      "y": 78,
      "z": -8,
      "name": "Rock_Calcite"
    },
    {
      "x": -22,
      "y": 79,
      "z": -8,
      "name": "Rock_Calcite"
    },
    {
      "x": -22,
      "y": 80,
      "z": -8,
      "name": "Rock_Calcite"
    },
    {
      "x": -22,
      "y": 60,
      "z": -7,
      "name": "Rock_Calcite"
    },
    {
      "x": -22,
      "y": 61,
      "z": -7,
      "name": "Rock_Calcite"
    },
    {
      "x": -22,
      "y": 62,
      "z": -7,
      "name": "Rock_Calcite"
    },
    {
      "x": -22,
      "y": 63,
      "z": -7,
      "name": "Rock_Calcite"
    },
    {
      "x": -22,
      "y": 64,
      "z": -7,
      "name": "Rock_Calcite"
    },
    {
      "x": -22,
      "y": 65,
      "z": -7,
      "name": "Rock_Calcite"
    },
    {
      "x": -22,
      "y": 66,
      "z": -7,
      "name": "Rock_Calcite"
    },
    {
      "x": -22,
      "y": 67,
      "z": -7,
      "name": "Rock_Calcite"
    },
    {
      "x": -22,
      "y": 68,
      "z": -7,
      "name": "Rock_Calcite"
    },
    {
      "x": -22,
      "y": 69,
      "z": -7,
      "name": "Rock_Calcite"
    },
    {
      "x": -22,
      "y": 70,
      "z": -7,
      "name": "Rock_Calcite"
    },
    {
      "x": -22,
      "y": 71,
      "z": -7,
      "name": "Rock_Calcite"
    },
    {
      "x": -22,
      "y": 72,
      "z": -7,
      "name": "Rock_Calcite"
    },
    {
      "x": -22,
      "y": 73,
      "z": -7,
      "name": "Rock_Calcite"
    },
    {
      "x": -22,
      "y": 74,
      "z": -7,
      "name": "Rock_Calcite"
    },
    {
      "x": -22,
      "y": 75,
      "z": -7,
      "name": "Rock_Calcite"
    },
    {
      "x": -22,
      "y": 76,
      "z": -7,
      "name": "Rock_Calcite"
    },
    {
      "x": -22,
      "y": 77,
      "z": -7,
      "name": "Rock_Calcite"
    },
    {
      "x": -22,
      "y": 78,
      "z": -7,
      "name": "Rock_Calcite"
    },
    {
      "x": -22,
      "y": 79,
      "z": -7,
      "name": "Rock_Calcite"
    },
    {
      "x": -22,
      "y": 80,
      "z": -7,
      "name": "Rock_Calcite"
    },
    {
      "x": -22,
      "y": 60,
      "z": -6,
      "name": "Rock_Calcite"
    },
    {
      "x": -22,
      "y": 61,
      "z": -6,
      "name": "Rock_Calcite"
    },
    {
      "x": -22,
      "y": 62,
      "z": -6,
      "name": "Rock_Calcite"
    },
    {
      "x": -22,
      "y": 63,
      "z": -6,
      "name": "Rock_Calcite"
    },
    {
      "x": -22,
      "y": 64,
      "z": -6,
      "name": "Rock_Calcite"
    },
    {
      "x": -22,
      "y": 65,
      "z": -6,
      "name": "Rock_Calcite"
    },
    {
      "x": -22,
      "y": 66,
      "z": -6,
      "name": "Rock_Calcite"
    },
    {
      "x": -22,
      "y": 67,
      "z": -6,
      "name": "Rock_Calcite"
    },
    {
      "x": -22,
      "y": 68,
      "z": -6,
      "name": "Rock_Calcite"
    },
    {
      "x": -22,
      "y": 69,
      "z": -6,
      "name": "Rock_Calcite"
    },
    {
      "x": -22,
      "y": 70,
      "z": -6,
      "name": "Rock_Calcite"
    },
    {
      "x": -22,
      "y": 71,
      "z": -6,
      "name": "Rock_Calcite"
    },
    {
      "x": -22,
      "y": 72,
      "z": -6,
      "name": "Rock_Calcite"
    },
    {
      "x": -22,
      "y": 73,
      "z": -6,
      "name": "Rock_Calcite"
    },
    {
      "x": -22,
      "y": 74,
      "z": -6,
      "name": "Rock_Calcite"
    },
    {
      "x": -22,
      "y": 75,
      "z": -6,
      "name": "Rock_Calcite"
    },
    {
      "x": -22,
      "y": 76,
      "z": -6,
      "name": "Rock_Calcite"
    },
    {
      "x": -22,
      "y": 77,
      "z": -6,
      "name": "Rock_Calcite"
    },
    {
      "x": -22,
      "y": 78,
      "z": -6,
      "name": "Rock_Calcite"
    },
    {
      "x": -22,
      "y": 79,
      "z": -6,
      "name": "Rock_Calcite"
    },
    {
      "x": -22,
      "y": 80,
      "z": -6,
      "name": "Rock_Calcite"
    },
    {
      "x": -22,
      "y": 81,
      "z": -6,
      "name": "Rock_Calcite"
    },
    {
      "x": -22,
      "y": 60,
      "z": -5,
      "name": "Rock_Calcite"
    },
    {
      "x": -22,
      "y": 61,
      "z": -5,
      "name": "Rock_Calcite"
    },
    {
      "x": -22,
      "y": 62,
      "z": -5,
      "name": "Rock_Calcite"
    },
    {
      "x": -22,
      "y": 63,
      "z": -5,
      "name": "Rock_Calcite"
    },
    {
      "x": -22,
      "y": 64,
      "z": -5,
      "name": "Rock_Calcite"
    },
    {
      "x": -22,
      "y": 65,
      "z": -5,
      "name": "Rock_Calcite"
    },
    {
      "x": -22,
      "y": 66,
      "z": -5,
      "name": "Rock_Calcite"
    },
    {
      "x": -22,
      "y": 67,
      "z": -5,
      "name": "Rock_Calcite"
    },
    {
      "x": -22,
      "y": 68,
      "z": -5,
      "name": "Rock_Calcite"
    },
    {
      "x": -22,
      "y": 69,
      "z": -5,
      "name": "Rock_Calcite"
    },
    {
      "x": -22,
      "y": 70,
      "z": -5,
      "name": "Rock_Calcite"
    },
    {
      "x": -22,
      "y": 71,
      "z": -5,
      "name": "Rock_Calcite"
    },
    {
      "x": -22,
      "y": 72,
      "z": -5,
      "name": "Rock_Calcite"
    },
    {
      "x": -22,
      "y": 73,
      "z": -5,
      "name": "Rock_Calcite"
    },
    {
      "x": -22,
      "y": 74,
      "z": -5,
      "name": "Rock_Calcite"
    },
    {
      "x": -22,
      "y": 75,
      "z": -5,
      "name": "Rock_Calcite"
    },
    {
      "x": -22,
      "y": 76,
      "z": -5,
      "name": "Rock_Calcite"
    },
    {
      "x": -22,
      "y": 77,
      "z": -5,
      "name": "Rock_Calcite"
    },
    {
      "x": -22,
      "y": 78,
      "z": -5,
      "name": "Rock_Calcite"
    },
    {
      "x": -22,
      "y": 79,
      "z": -5,
      "name": "Rock_Calcite"
    },
    {
      "x": -22,
      "y": 80,
      "z": -5,
      "name": "Rock_Calcite"
    },
    {
      "x": -22,
      "y": 62,
      "z": -4,
      "name": "Rock_Calcite"
    },
    {
      "x": -22,
      "y": 63,
      "z": -4,
      "name": "Rock_Calcite"
    },
    {
      "x": -22,
      "y": 64,
      "z": -4,
      "name": "Rock_Calcite"
    },
    {
      "x": -22,
      "y": 69,
      "z": -4,
      "name": "Rock_Calcite"
    },
    {
      "x": -22,
      "y": 70,
      "z": -4,
      "name": "Rock_Calcite"
    },
    {
      "x": -22,
      "y": 71,
      "z": -4,
      "name": "Rock_Calcite"
    },
    {
      "x": -22,
      "y": 77,
      "z": -4,
      "name": "Rock_Calcite"
    },
    {
      "x": -22,
      "y": 78,
      "z": -4,
      "name": "Rock_Calcite"
    },
    {
      "x": -22,
      "y": 79,
      "z": -4,
      "name": "Rock_Calcite"
    },
    {
      "x": -22,
      "y": 78,
      "z": -3,
      "name": "Rock_Calcite"
    },
    {
      "x": -22,
      "y": 79,
      "z": -3,
      "name": "Rock_Calcite"
    },
    {
      "x": -22,
      "y": 77,
      "z": 5,
      "name": "Rock_Calcite"
    },
    {
      "x": -22,
      "y": 78,
      "z": 5,
      "name": "Rock_Calcite"
    },
    {
      "x": -22,
      "y": 79,
      "z": 5,
      "name": "Rock_Calcite"
    },
    {
      "x": -22,
      "y": 80,
      "z": 5,
      "name": "Rock_Calcite"
    },
    {
      "x": -22,
      "y": 75,
      "z": 6,
      "name": "Rock_Calcite"
    },
    {
      "x": -22,
      "y": 76,
      "z": 6,
      "name": "Rock_Calcite"
    },
    {
      "x": -22,
      "y": 77,
      "z": 6,
      "name": "Rock_Calcite"
    },
    {
      "x": -22,
      "y": 78,
      "z": 6,
      "name": "Rock_Calcite"
    },
    {
      "x": -22,
      "y": 79,
      "z": 6,
      "name": "Rock_Calcite"
    },
    {
      "x": -22,
      "y": 80,
      "z": 6,
      "name": "Rock_Calcite"
    },
    {
      "x": -22,
      "y": 74,
      "z": 7,
      "name": "Rock_Calcite"
    },
    {
      "x": -22,
      "y": 75,
      "z": 7,
      "name": "Rock_Calcite"
    },
    {
      "x": -22,
      "y": 76,
      "z": 7,
      "name": "Rock_Calcite"
    },
    {
      "x": -22,
      "y": 77,
      "z": 7,
      "name": "Rock_Calcite"
    },
    {
      "x": -22,
      "y": 78,
      "z": 7,
      "name": "Rock_Calcite"
    },
    {
      "x": -22,
      "y": 79,
      "z": 7,
      "name": "Rock_Calcite"
    },
    {
      "x": -22,
      "y": 80,
      "z": 7,
      "name": "Rock_Calcite"
    },
    {
      "x": -22,
      "y": 75,
      "z": 8,
      "name": "Rock_Calcite"
    },
    {
      "x": -22,
      "y": 76,
      "z": 8,
      "name": "Rock_Calcite"
    },
    {
      "x": -22,
      "y": 77,
      "z": 8,
      "name": "Rock_Calcite"
    },
    {
      "x": -22,
      "y": 78,
      "z": 8,
      "name": "Rock_Calcite"
    },
    {
      "x": -22,
      "y": 79,
      "z": 8,
      "name": "Rock_Calcite"
    },
    {
      "x": -22,
      "y": 77,
      "z": 9,
      "name": "Rock_Calcite"
    },
    {
      "x": -22,
      "y": 78,
      "z": 9,
      "name": "Rock_Calcite"
    },
    {
      "x": -21,
      "y": 71,
      "z": -11,
      "name": "Rock_Calcite"
    },
    {
      "x": -21,
      "y": 72,
      "z": -11,
      "name": "Rock_Calcite"
    },
    {
      "x": -21,
      "y": 73,
      "z": -11,
      "name": "Rock_Calcite"
    },
    {
      "x": -21,
      "y": 74,
      "z": -11,
      "name": "Rock_Calcite"
    },
    {
      "x": -21,
      "y": 70,
      "z": -10,
      "name": "Rock_Calcite"
    },
    {
      "x": -21,
      "y": 71,
      "z": -10,
      "name": "Rock_Calcite"
    },
    {
      "x": -21,
      "y": 72,
      "z": -10,
      "name": "Rock_Calcite"
    },
    {
      "x": -21,
      "y": 73,
      "z": -10,
      "name": "Rock_Calcite"
    },
    {
      "x": -21,
      "y": 74,
      "z": -10,
      "name": "Rock_Calcite"
    },
    {
      "x": -21,
      "y": 75,
      "z": -10,
      "name": "Rock_Calcite"
    },
    {
      "x": -21,
      "y": 76,
      "z": -10,
      "name": "Rock_Calcite"
    },
    {
      "x": -21,
      "y": 62,
      "z": -9,
      "name": "Rock_Calcite"
    },
    {
      "x": -21,
      "y": 63,
      "z": -9,
      "name": "Rock_Calcite"
    },
    {
      "x": -21,
      "y": 64,
      "z": -9,
      "name": "Rock_Calcite"
    },
    {
      "x": -21,
      "y": 65,
      "z": -9,
      "name": "Rock_Calcite"
    },
    {
      "x": -21,
      "y": 66,
      "z": -9,
      "name": "Rock_Calcite"
    },
    {
      "x": -21,
      "y": 67,
      "z": -9,
      "name": "Rock_Calcite"
    },
    {
      "x": -21,
      "y": 68,
      "z": -9,
      "name": "Rock_Calcite"
    },
    {
      "x": -21,
      "y": 69,
      "z": -9,
      "name": "Rock_Calcite"
    },
    {
      "x": -21,
      "y": 70,
      "z": -9,
      "name": "Rock_Calcite"
    },
    {
      "x": -21,
      "y": 71,
      "z": -9,
      "name": "Rock_Calcite"
    },
    {
      "x": -21,
      "y": 72,
      "z": -9,
      "name": "Rock_Calcite"
    },
    {
      "x": -21,
      "y": 73,
      "z": -9,
      "name": "Rock_Calcite"
    },
    {
      "x": -21,
      "y": 74,
      "z": -9,
      "name": "Rock_Calcite"
    },
    {
      "x": -21,
      "y": 75,
      "z": -9,
      "name": "Rock_Calcite"
    },
    {
      "x": -21,
      "y": 76,
      "z": -9,
      "name": "Rock_Calcite"
    },
    {
      "x": -21,
      "y": 77,
      "z": -9,
      "name": "Rock_Calcite"
    },
    {
      "x": -21,
      "y": 60,
      "z": -8,
      "name": "Rock_Calcite"
    },
    {
      "x": -21,
      "y": 61,
      "z": -8,
      "name": "Rock_Calcite"
    },
    {
      "x": -21,
      "y": 62,
      "z": -8,
      "name": "Rock_Calcite"
    },
    {
      "x": -21,
      "y": 63,
      "z": -8,
      "name": "Rock_Calcite"
    },
    {
      "x": -21,
      "y": 64,
      "z": -8,
      "name": "Rock_Calcite"
    },
    {
      "x": -21,
      "y": 65,
      "z": -8,
      "name": "Rock_Calcite"
    },
    {
      "x": -21,
      "y": 66,
      "z": -8,
      "name": "Rock_Calcite"
    },
    {
      "x": -21,
      "y": 67,
      "z": -8,
      "name": "Rock_Calcite"
    },
    {
      "x": -21,
      "y": 68,
      "z": -8,
      "name": "Rock_Calcite"
    },
    {
      "x": -21,
      "y": 69,
      "z": -8,
      "name": "Rock_Calcite"
    },
    {
      "x": -21,
      "y": 70,
      "z": -8,
      "name": "Rock_Calcite"
    },
    {
      "x": -21,
      "y": 71,
      "z": -8,
      "name": "Rock_Calcite"
    },
    {
      "x": -21,
      "y": 72,
      "z": -8,
      "name": "Rock_Calcite"
    },
    {
      "x": -21,
      "y": 73,
      "z": -8,
      "name": "Rock_Calcite"
    },
    {
      "x": -21,
      "y": 74,
      "z": -8,
      "name": "Rock_Calcite"
    },
    {
      "x": -21,
      "y": 75,
      "z": -8,
      "name": "Rock_Calcite"
    },
    {
      "x": -21,
      "y": 76,
      "z": -8,
      "name": "Rock_Calcite"
    },
    {
      "x": -21,
      "y": 77,
      "z": -8,
      "name": "Rock_Calcite"
    },
    {
      "x": -21,
      "y": 78,
      "z": -8,
      "name": "Rock_Calcite"
    },
    {
      "x": -21,
      "y": 79,
      "z": -8,
      "name": "Rock_Calcite"
    },
    {
      "x": -21,
      "y": 80,
      "z": -8,
      "name": "Rock_Calcite"
    },
    {
      "x": -21,
      "y": 55,
      "z": -7,
      "name": "Rock_Calcite"
    },
    {
      "x": -21,
      "y": 56,
      "z": -7,
      "name": "Rock_Calcite"
    },
    {
      "x": -21,
      "y": 57,
      "z": -7,
      "name": "Rock_Calcite"
    },
    {
      "x": -21,
      "y": 58,
      "z": -7,
      "name": "Rock_Calcite"
    },
    {
      "x": -21,
      "y": 59,
      "z": -7,
      "name": "Rock_Calcite"
    },
    {
      "x": -21,
      "y": 60,
      "z": -7,
      "name": "Rock_Calcite"
    },
    {
      "x": -21,
      "y": 61,
      "z": -7,
      "name": "Rock_Calcite"
    },
    {
      "x": -21,
      "y": 62,
      "z": -7,
      "name": "Rock_Calcite"
    },
    {
      "x": -21,
      "y": 63,
      "z": -7,
      "name": "Rock_Calcite"
    },
    {
      "x": -21,
      "y": 64,
      "z": -7,
      "name": "Rock_Calcite"
    },
    {
      "x": -21,
      "y": 65,
      "z": -7,
      "name": "Rock_Calcite"
    },
    {
      "x": -21,
      "y": 66,
      "z": -7,
      "name": "Rock_Calcite"
    },
    {
      "x": -21,
      "y": 67,
      "z": -7,
      "name": "Rock_Calcite"
    },
    {
      "x": -21,
      "y": 68,
      "z": -7,
      "name": "Rock_Calcite"
    },
    {
      "x": -21,
      "y": 69,
      "z": -7,
      "name": "Rock_Calcite"
    },
    {
      "x": -21,
      "y": 70,
      "z": -7,
      "name": "Rock_Calcite"
    },
    {
      "x": -21,
      "y": 71,
      "z": -7,
      "name": "Rock_Calcite"
    },
    {
      "x": -21,
      "y": 72,
      "z": -7,
      "name": "Rock_Calcite"
    },
    {
      "x": -21,
      "y": 73,
      "z": -7,
      "name": "Rock_Calcite"
    },
    {
      "x": -21,
      "y": 74,
      "z": -7,
      "name": "Rock_Calcite"
    },
    {
      "x": -21,
      "y": 75,
      "z": -7,
      "name": "Rock_Calcite"
    },
    {
      "x": -21,
      "y": 76,
      "z": -7,
      "name": "Rock_Calcite"
    },
    {
      "x": -21,
      "y": 77,
      "z": -7,
      "name": "Rock_Calcite"
    },
    {
      "x": -21,
      "y": 78,
      "z": -7,
      "name": "Rock_Calcite"
    },
    {
      "x": -21,
      "y": 79,
      "z": -7,
      "name": "Rock_Calcite"
    },
    {
      "x": -21,
      "y": 80,
      "z": -7,
      "name": "Rock_Calcite"
    },
    {
      "x": -21,
      "y": 81,
      "z": -7,
      "name": "Rock_Calcite"
    },
    {
      "x": -21,
      "y": 82,
      "z": -7,
      "name": "Rock_Calcite"
    },
    {
      "x": -21,
      "y": 83,
      "z": -7,
      "name": "Rock_Calcite"
    },
    {
      "x": -21,
      "y": 54,
      "z": -6,
      "name": "Rock_Calcite"
    },
    {
      "x": -21,
      "y": 55,
      "z": -6,
      "name": "Rock_Calcite"
    },
    {
      "x": -21,
      "y": 56,
      "z": -6,
      "name": "Rock_Calcite"
    },
    {
      "x": -21,
      "y": 57,
      "z": -6,
      "name": "Rock_Calcite"
    },
    {
      "x": -21,
      "y": 58,
      "z": -6,
      "name": "Rock_Calcite"
    },
    {
      "x": -21,
      "y": 59,
      "z": -6,
      "name": "Rock_Calcite"
    },
    {
      "x": -21,
      "y": 60,
      "z": -6,
      "name": "Rock_Calcite"
    },
    {
      "x": -21,
      "y": 61,
      "z": -6,
      "name": "Rock_Calcite"
    },
    {
      "x": -21,
      "y": 62,
      "z": -6,
      "name": "Rock_Calcite"
    },
    {
      "x": -21,
      "y": 63,
      "z": -6,
      "name": "Rock_Calcite"
    },
    {
      "x": -21,
      "y": 64,
      "z": -6,
      "name": "Rock_Calcite"
    },
    {
      "x": -21,
      "y": 65,
      "z": -6,
      "name": "Rock_Calcite"
    },
    {
      "x": -21,
      "y": 66,
      "z": -6,
      "name": "Rock_Calcite"
    },
    {
      "x": -21,
      "y": 67,
      "z": -6,
      "name": "Rock_Calcite"
    },
    {
      "x": -21,
      "y": 68,
      "z": -6,
      "name": "Rock_Calcite"
    },
    {
      "x": -21,
      "y": 69,
      "z": -6,
      "name": "Rock_Calcite"
    },
    {
      "x": -21,
      "y": 70,
      "z": -6,
      "name": "Rock_Calcite"
    },
    {
      "x": -21,
      "y": 71,
      "z": -6,
      "name": "Rock_Calcite"
    },
    {
      "x": -21,
      "y": 72,
      "z": -6,
      "name": "Rock_Calcite"
    },
    {
      "x": -21,
      "y": 73,
      "z": -6,
      "name": "Rock_Calcite"
    },
    {
      "x": -21,
      "y": 74,
      "z": -6,
      "name": "Rock_Calcite"
    },
    {
      "x": -21,
      "y": 75,
      "z": -6,
      "name": "Rock_Calcite"
    },
    {
      "x": -21,
      "y": 76,
      "z": -6,
      "name": "Rock_Calcite"
    },
    {
      "x": -21,
      "y": 77,
      "z": -6,
      "name": "Rock_Calcite"
    },
    {
      "x": -21,
      "y": 78,
      "z": -6,
      "name": "Rock_Calcite"
    },
    {
      "x": -21,
      "y": 80,
      "z": -6,
      "name": "Rock_Calcite"
    },
    {
      "x": -21,
      "y": 81,
      "z": -6,
      "name": "Rock_Calcite"
    },
    {
      "x": -21,
      "y": 82,
      "z": -6,
      "name": "Rock_Calcite"
    },
    {
      "x": -21,
      "y": 83,
      "z": -6,
      "name": "Rock_Calcite"
    },
    {
      "x": -21,
      "y": 84,
      "z": -6,
      "name": "Rock_Calcite"
    },
    {
      "x": -21,
      "y": 55,
      "z": -5,
      "name": "Rock_Calcite"
    },
    {
      "x": -21,
      "y": 56,
      "z": -5,
      "name": "Rock_Calcite"
    },
    {
      "x": -21,
      "y": 57,
      "z": -5,
      "name": "Rock_Calcite"
    },
    {
      "x": -21,
      "y": 58,
      "z": -5,
      "name": "Rock_Calcite"
    },
    {
      "x": -21,
      "y": 59,
      "z": -5,
      "name": "Rock_Calcite"
    },
    {
      "x": -21,
      "y": 60,
      "z": -5,
      "name": "Rock_Calcite"
    },
    {
      "x": -21,
      "y": 61,
      "z": -5,
      "name": "Rock_Calcite"
    },
    {
      "x": -21,
      "y": 62,
      "z": -5,
      "name": "Rock_Calcite"
    },
    {
      "x": -21,
      "y": 63,
      "z": -5,
      "name": "Rock_Calcite"
    },
    {
      "x": -21,
      "y": 64,
      "z": -5,
      "name": "Rock_Calcite"
    },
    {
      "x": -21,
      "y": 65,
      "z": -5,
      "name": "Rock_Calcite"
    },
    {
      "x": -21,
      "y": 66,
      "z": -5,
      "name": "Rock_Calcite"
    },
    {
      "x": -21,
      "y": 67,
      "z": -5,
      "name": "Rock_Calcite"
    },
    {
      "x": -21,
      "y": 68,
      "z": -5,
      "name": "Rock_Calcite"
    },
    {
      "x": -21,
      "y": 69,
      "z": -5,
      "name": "Rock_Calcite"
    },
    {
      "x": -21,
      "y": 70,
      "z": -5,
      "name": "Rock_Calcite"
    },
    {
      "x": -21,
      "y": 71,
      "z": -5,
      "name": "Rock_Calcite"
    },
    {
      "x": -21,
      "y": 72,
      "z": -5,
      "name": "Rock_Calcite"
    },
    {
      "x": -21,
      "y": 73,
      "z": -5,
      "name": "Rock_Calcite"
    },
    {
      "x": -21,
      "y": 74,
      "z": -5,
      "name": "Rock_Calcite"
    },
    {
      "x": -21,
      "y": 75,
      "z": -5,
      "name": "Rock_Calcite"
    },
    {
      "x": -21,
      "y": 76,
      "z": -5,
      "name": "Rock_Calcite"
    },
    {
      "x": -21,
      "y": 77,
      "z": -5,
      "name": "Rock_Calcite"
    },
    {
      "x": -21,
      "y": 78,
      "z": -5,
      "name": "Rock_Calcite"
    },
    {
      "x": -21,
      "y": 79,
      "z": -5,
      "name": "Rock_Calcite"
    },
    {
      "x": -21,
      "y": 80,
      "z": -5,
      "name": "Rock_Calcite"
    },
    {
      "x": -21,
      "y": 81,
      "z": -5,
      "name": "Rock_Calcite"
    },
    {
      "x": -21,
      "y": 82,
      "z": -5,
      "name": "Rock_Calcite"
    },
    {
      "x": -21,
      "y": 83,
      "z": -5,
      "name": "Rock_Calcite"
    },
    {
      "x": -21,
      "y": 60,
      "z": -4,
      "name": "Rock_Calcite"
    },
    {
      "x": -21,
      "y": 61,
      "z": -4,
      "name": "Rock_Calcite"
    },
    {
      "x": -21,
      "y": 62,
      "z": -4,
      "name": "Rock_Calcite"
    },
    {
      "x": -21,
      "y": 63,
      "z": -4,
      "name": "Rock_Calcite"
    },
    {
      "x": -21,
      "y": 64,
      "z": -4,
      "name": "Rock_Calcite"
    },
    {
      "x": -21,
      "y": 65,
      "z": -4,
      "name": "Rock_Calcite"
    },
    {
      "x": -21,
      "y": 66,
      "z": -4,
      "name": "Rock_Calcite"
    },
    {
      "x": -21,
      "y": 67,
      "z": -4,
      "name": "Rock_Calcite"
    },
    {
      "x": -21,
      "y": 68,
      "z": -4,
      "name": "Rock_Calcite"
    },
    {
      "x": -21,
      "y": 69,
      "z": -4,
      "name": "Rock_Calcite"
    },
    {
      "x": -21,
      "y": 70,
      "z": -4,
      "name": "Rock_Calcite"
    },
    {
      "x": -21,
      "y": 74,
      "z": -4,
      "name": "Rock_Calcite"
    },
    {
      "x": -21,
      "y": 76,
      "z": -4,
      "name": "Rock_Calcite"
    },
    {
      "x": -21,
      "y": 77,
      "z": -4,
      "name": "Rock_Calcite"
    },
    {
      "x": -21,
      "y": 78,
      "z": -4,
      "name": "Rock_Calcite"
    },
    {
      "x": -21,
      "y": 79,
      "z": -4,
      "name": "Rock_Calcite"
    },
    {
      "x": -21,
      "y": 80,
      "z": -4,
      "name": "Rock_Calcite"
    },
    {
      "x": -21,
      "y": 62,
      "z": -3,
      "name": "Rock_Calcite"
    },
    {
      "x": -21,
      "y": 63,
      "z": -3,
      "name": "Rock_Calcite"
    },
    {
      "x": -21,
      "y": 64,
      "z": -3,
      "name": "Rock_Calcite"
    },
    {
      "x": -21,
      "y": 77,
      "z": -3,
      "name": "Rock_Calcite"
    },
    {
      "x": -21,
      "y": 78,
      "z": -3,
      "name": "Rock_Calcite"
    },
    {
      "x": -21,
      "y": 79,
      "z": -3,
      "name": "Rock_Calcite"
    },
    {
      "x": -21,
      "y": 76,
      "z": 5,
      "name": "Rock_Calcite"
    },
    {
      "x": -21,
      "y": 77,
      "z": 5,
      "name": "Rock_Calcite"
    },
    {
      "x": -21,
      "y": 78,
      "z": 5,
      "name": "Rock_Calcite"
    },
    {
      "x": -21,
      "y": 79,
      "z": 5,
      "name": "Rock_Calcite"
    },
    {
      "x": -21,
      "y": 80,
      "z": 5,
      "name": "Rock_Calcite"
    },
    {
      "x": -21,
      "y": 66,
      "z": 6,
      "name": "Rock_Calcite"
    },
    {
      "x": -21,
      "y": 67,
      "z": 6,
      "name": "Rock_Calcite"
    },
    {
      "x": -21,
      "y": 68,
      "z": 6,
      "name": "Rock_Calcite"
    },
    {
      "x": -21,
      "y": 69,
      "z": 6,
      "name": "Rock_Calcite"
    },
    {
      "x": -21,
      "y": 70,
      "z": 6,
      "name": "Rock_Calcite"
    },
    {
      "x": -21,
      "y": 71,
      "z": 6,
      "name": "Rock_Calcite"
    },
    {
      "x": -21,
      "y": 72,
      "z": 6,
      "name": "Rock_Calcite"
    },
    {
      "x": -21,
      "y": 73,
      "z": 6,
      "name": "Rock_Calcite"
    },
    {
      "x": -21,
      "y": 74,
      "z": 6,
      "name": "Rock_Calcite"
    },
    {
      "x": -21,
      "y": 75,
      "z": 6,
      "name": "Rock_Calcite"
    },
    {
      "x": -21,
      "y": 76,
      "z": 6,
      "name": "Rock_Calcite"
    },
    {
      "x": -21,
      "y": 77,
      "z": 6,
      "name": "Rock_Calcite"
    },
    {
      "x": -21,
      "y": 78,
      "z": 6,
      "name": "Rock_Calcite"
    },
    {
      "x": -21,
      "y": 79,
      "z": 6,
      "name": "Rock_Calcite"
    },
    {
      "x": -21,
      "y": 80,
      "z": 6,
      "name": "Rock_Calcite"
    },
    {
      "x": -21,
      "y": 81,
      "z": 6,
      "name": "Rock_Calcite"
    },
    {
      "x": -21,
      "y": 82,
      "z": 6,
      "name": "Rock_Calcite"
    },
    {
      "x": -21,
      "y": 71,
      "z": 7,
      "name": "Rock_Calcite"
    },
    {
      "x": -21,
      "y": 72,
      "z": 7,
      "name": "Rock_Calcite"
    },
    {
      "x": -21,
      "y": 73,
      "z": 7,
      "name": "Rock_Calcite"
    },
    {
      "x": -21,
      "y": 74,
      "z": 7,
      "name": "Rock_Calcite"
    },
    {
      "x": -21,
      "y": 75,
      "z": 7,
      "name": "Rock_Calcite"
    },
    {
      "x": -21,
      "y": 76,
      "z": 7,
      "name": "Rock_Calcite"
    },
    {
      "x": -21,
      "y": 77,
      "z": 7,
      "name": "Rock_Calcite"
    },
    {
      "x": -21,
      "y": 78,
      "z": 7,
      "name": "Rock_Calcite"
    },
    {
      "x": -21,
      "y": 79,
      "z": 7,
      "name": "Rock_Calcite"
    },
    {
      "x": -21,
      "y": 80,
      "z": 7,
      "name": "Rock_Calcite"
    },
    {
      "x": -21,
      "y": 81,
      "z": 7,
      "name": "Rock_Calcite"
    },
    {
      "x": -21,
      "y": 82,
      "z": 7,
      "name": "Rock_Calcite"
    },
    {
      "x": -21,
      "y": 83,
      "z": 7,
      "name": "Rock_Calcite"
    },
    {
      "x": -21,
      "y": 72,
      "z": 8,
      "name": "Rock_Calcite"
    },
    {
      "x": -21,
      "y": 73,
      "z": 8,
      "name": "Rock_Calcite"
    },
    {
      "x": -21,
      "y": 74,
      "z": 8,
      "name": "Rock_Calcite"
    },
    {
      "x": -21,
      "y": 75,
      "z": 8,
      "name": "Rock_Calcite"
    },
    {
      "x": -21,
      "y": 76,
      "z": 8,
      "name": "Rock_Calcite"
    },
    {
      "x": -21,
      "y": 77,
      "z": 8,
      "name": "Rock_Calcite"
    },
    {
      "x": -21,
      "y": 78,
      "z": 8,
      "name": "Rock_Calcite"
    },
    {
      "x": -21,
      "y": 79,
      "z": 8,
      "name": "Rock_Calcite"
    },
    {
      "x": -21,
      "y": 80,
      "z": 8,
      "name": "Rock_Calcite"
    },
    {
      "x": -21,
      "y": 81,
      "z": 8,
      "name": "Rock_Calcite"
    },
    {
      "x": -21,
      "y": 82,
      "z": 8,
      "name": "Rock_Calcite"
    },
    {
      "x": -21,
      "y": 75,
      "z": 9,
      "name": "Rock_Calcite"
    },
    {
      "x": -21,
      "y": 76,
      "z": 9,
      "name": "Rock_Calcite"
    },
    {
      "x": -21,
      "y": 77,
      "z": 9,
      "name": "Rock_Calcite"
    },
    {
      "x": -21,
      "y": 78,
      "z": 9,
      "name": "Rock_Calcite"
    },
    {
      "x": -21,
      "y": 79,
      "z": 9,
      "name": "Rock_Calcite"
    },
    {
      "x": -20,
      "y": 69,
      "z": -10,
      "name": "Rock_Calcite"
    },
    {
      "x": -20,
      "y": 70,
      "z": -10,
      "name": "Rock_Calcite"
    },
    {
      "x": -20,
      "y": 71,
      "z": -10,
      "name": "Rock_Calcite"
    },
    {
      "x": -20,
      "y": 72,
      "z": -10,
      "name": "Rock_Calcite"
    },
    {
      "x": -20,
      "y": 73,
      "z": -10,
      "name": "Rock_Calcite"
    },
    {
      "x": -20,
      "y": 76,
      "z": -10,
      "name": "Rock_Calcite"
    },
    {
      "x": -20,
      "y": 60,
      "z": -9,
      "name": "Rock_Calcite"
    },
    {
      "x": -20,
      "y": 61,
      "z": -9,
      "name": "Rock_Calcite"
    },
    {
      "x": -20,
      "y": 62,
      "z": -9,
      "name": "Rock_Calcite"
    },
    {
      "x": -20,
      "y": 63,
      "z": -9,
      "name": "Rock_Calcite"
    },
    {
      "x": -20,
      "y": 64,
      "z": -9,
      "name": "Rock_Calcite"
    },
    {
      "x": -20,
      "y": 65,
      "z": -9,
      "name": "Rock_Calcite"
    },
    {
      "x": -20,
      "y": 66,
      "z": -9,
      "name": "Rock_Calcite"
    },
    {
      "x": -20,
      "y": 67,
      "z": -9,
      "name": "Rock_Calcite"
    },
    {
      "x": -20,
      "y": 68,
      "z": -9,
      "name": "Rock_Calcite"
    },
    {
      "x": -20,
      "y": 69,
      "z": -9,
      "name": "Rock_Calcite"
    },
    {
      "x": -20,
      "y": 70,
      "z": -9,
      "name": "Rock_Calcite"
    },
    {
      "x": -20,
      "y": 71,
      "z": -9,
      "name": "Rock_Calcite"
    },
    {
      "x": -20,
      "y": 72,
      "z": -9,
      "name": "Rock_Calcite"
    },
    {
      "x": -20,
      "y": 73,
      "z": -9,
      "name": "Rock_Calcite"
    },
    {
      "x": -20,
      "y": 74,
      "z": -9,
      "name": "Rock_Calcite"
    },
    {
      "x": -20,
      "y": 75,
      "z": -9,
      "name": "Rock_Calcite"
    },
    {
      "x": -20,
      "y": 76,
      "z": -9,
      "name": "Rock_Calcite"
    },
    {
      "x": -20,
      "y": 77,
      "z": -9,
      "name": "Rock_Calcite"
    },
    {
      "x": -20,
      "y": 54,
      "z": -8,
      "name": "Rock_Calcite"
    },
    {
      "x": -20,
      "y": 55,
      "z": -8,
      "name": "Rock_Calcite"
    },
    {
      "x": -20,
      "y": 56,
      "z": -8,
      "name": "Rock_Calcite"
    },
    {
      "x": -20,
      "y": 57,
      "z": -8,
      "name": "Rock_Calcite"
    },
    {
      "x": -20,
      "y": 58,
      "z": -8,
      "name": "Rock_Calcite"
    },
    {
      "x": -20,
      "y": 59,
      "z": -8,
      "name": "Rock_Calcite"
    },
    {
      "x": -20,
      "y": 60,
      "z": -8,
      "name": "Rock_Calcite"
    },
    {
      "x": -20,
      "y": 61,
      "z": -8,
      "name": "Rock_Calcite"
    },
    {
      "x": -20,
      "y": 62,
      "z": -8,
      "name": "Rock_Calcite"
    },
    {
      "x": -20,
      "y": 63,
      "z": -8,
      "name": "Rock_Calcite"
    },
    {
      "x": -20,
      "y": 64,
      "z": -8,
      "name": "Rock_Calcite"
    },
    {
      "x": -20,
      "y": 65,
      "z": -8,
      "name": "Rock_Calcite"
    },
    {
      "x": -20,
      "y": 66,
      "z": -8,
      "name": "Rock_Calcite"
    },
    {
      "x": -20,
      "y": 67,
      "z": -8,
      "name": "Rock_Calcite"
    },
    {
      "x": -20,
      "y": 68,
      "z": -8,
      "name": "Rock_Calcite"
    },
    {
      "x": -20,
      "y": 69,
      "z": -8,
      "name": "Rock_Calcite"
    },
    {
      "x": -20,
      "y": 70,
      "z": -8,
      "name": "Rock_Calcite"
    },
    {
      "x": -20,
      "y": 71,
      "z": -8,
      "name": "Rock_Calcite"
    },
    {
      "x": -20,
      "y": 72,
      "z": -8,
      "name": "Rock_Calcite"
    },
    {
      "x": -20,
      "y": 73,
      "z": -8,
      "name": "Rock_Calcite"
    },
    {
      "x": -20,
      "y": 74,
      "z": -8,
      "name": "Rock_Calcite"
    },
    {
      "x": -20,
      "y": 75,
      "z": -8,
      "name": "Rock_Calcite"
    },
    {
      "x": -20,
      "y": 76,
      "z": -8,
      "name": "Rock_Calcite"
    },
    {
      "x": -20,
      "y": 77,
      "z": -8,
      "name": "Rock_Calcite"
    },
    {
      "x": -20,
      "y": 78,
      "z": -8,
      "name": "Rock_Calcite"
    },
    {
      "x": -20,
      "y": 79,
      "z": -8,
      "name": "Rock_Calcite"
    },
    {
      "x": -20,
      "y": 80,
      "z": -8,
      "name": "Rock_Calcite"
    },
    {
      "x": -20,
      "y": 81,
      "z": -8,
      "name": "Rock_Calcite"
    },
    {
      "x": -20,
      "y": 53,
      "z": -7,
      "name": "Rock_Calcite"
    },
    {
      "x": -20,
      "y": 54,
      "z": -7,
      "name": "Rock_Calcite"
    },
    {
      "x": -20,
      "y": 55,
      "z": -7,
      "name": "Rock_Calcite"
    },
    {
      "x": -20,
      "y": 56,
      "z": -7,
      "name": "Rock_Calcite"
    },
    {
      "x": -20,
      "y": 57,
      "z": -7,
      "name": "Rock_Calcite"
    },
    {
      "x": -20,
      "y": 58,
      "z": -7,
      "name": "Rock_Calcite"
    },
    {
      "x": -20,
      "y": 59,
      "z": -7,
      "name": "Rock_Calcite"
    },
    {
      "x": -20,
      "y": 60,
      "z": -7,
      "name": "Rock_Calcite"
    },
    {
      "x": -20,
      "y": 61,
      "z": -7,
      "name": "Rock_Calcite"
    },
    {
      "x": -20,
      "y": 62,
      "z": -7,
      "name": "Rock_Calcite"
    },
    {
      "x": -20,
      "y": 63,
      "z": -7,
      "name": "Rock_Calcite"
    },
    {
      "x": -20,
      "y": 64,
      "z": -7,
      "name": "Rock_Calcite"
    },
    {
      "x": -20,
      "y": 65,
      "z": -7,
      "name": "Rock_Calcite"
    },
    {
      "x": -20,
      "y": 66,
      "z": -7,
      "name": "Rock_Calcite"
    },
    {
      "x": -20,
      "y": 67,
      "z": -7,
      "name": "Rock_Calcite"
    },
    {
      "x": -20,
      "y": 68,
      "z": -7,
      "name": "Rock_Calcite"
    },
    {
      "x": -20,
      "y": 69,
      "z": -7,
      "name": "Rock_Calcite"
    },
    {
      "x": -20,
      "y": 70,
      "z": -7,
      "name": "Rock_Calcite"
    },
    {
      "x": -20,
      "y": 71,
      "z": -7,
      "name": "Rock_Calcite"
    },
    {
      "x": -20,
      "y": 72,
      "z": -7,
      "name": "Rock_Calcite"
    },
    {
      "x": -20,
      "y": 73,
      "z": -7,
      "name": "Rock_Calcite"
    },
    {
      "x": -20,
      "y": 74,
      "z": -7,
      "name": "Rock_Calcite"
    },
    {
      "x": -20,
      "y": 75,
      "z": -7,
      "name": "Rock_Calcite"
    },
    {
      "x": -20,
      "y": 76,
      "z": -7,
      "name": "Rock_Calcite"
    },
    {
      "x": -20,
      "y": 77,
      "z": -7,
      "name": "Rock_Calcite"
    },
    {
      "x": -20,
      "y": 78,
      "z": -7,
      "name": "Rock_Calcite"
    },
    {
      "x": -20,
      "y": 79,
      "z": -7,
      "name": "Rock_Calcite"
    },
    {
      "x": -20,
      "y": 80,
      "z": -7,
      "name": "Rock_Calcite"
    },
    {
      "x": -20,
      "y": 81,
      "z": -7,
      "name": "Rock_Calcite"
    },
    {
      "x": -20,
      "y": 82,
      "z": -7,
      "name": "Rock_Calcite"
    },
    {
      "x": -20,
      "y": 83,
      "z": -7,
      "name": "Rock_Calcite"
    },
    {
      "x": -20,
      "y": 84,
      "z": -7,
      "name": "Rock_Calcite"
    },
    {
      "x": -20,
      "y": 53,
      "z": -6,
      "name": "Rock_Calcite"
    },
    {
      "x": -20,
      "y": 54,
      "z": -6,
      "name": "Rock_Calcite"
    },
    {
      "x": -20,
      "y": 55,
      "z": -6,
      "name": "Rock_Calcite"
    },
    {
      "x": -20,
      "y": 56,
      "z": -6,
      "name": "Rock_Calcite"
    },
    {
      "x": -20,
      "y": 57,
      "z": -6,
      "name": "Rock_Calcite"
    },
    {
      "x": -20,
      "y": 58,
      "z": -6,
      "name": "Rock_Calcite"
    },
    {
      "x": -20,
      "y": 59,
      "z": -6,
      "name": "Rock_Calcite"
    },
    {
      "x": -20,
      "y": 60,
      "z": -6,
      "name": "Rock_Calcite"
    },
    {
      "x": -20,
      "y": 61,
      "z": -6,
      "name": "Rock_Calcite"
    },
    {
      "x": -20,
      "y": 62,
      "z": -6,
      "name": "Rock_Calcite"
    },
    {
      "x": -20,
      "y": 63,
      "z": -6,
      "name": "Rock_Calcite"
    },
    {
      "x": -20,
      "y": 64,
      "z": -6,
      "name": "Rock_Calcite"
    },
    {
      "x": -20,
      "y": 65,
      "z": -6,
      "name": "Rock_Calcite"
    },
    {
      "x": -20,
      "y": 66,
      "z": -6,
      "name": "Rock_Calcite"
    },
    {
      "x": -20,
      "y": 67,
      "z": -6,
      "name": "Rock_Calcite"
    },
    {
      "x": -20,
      "y": 68,
      "z": -6,
      "name": "Rock_Calcite"
    },
    {
      "x": -20,
      "y": 69,
      "z": -6,
      "name": "Rock_Calcite"
    },
    {
      "x": -20,
      "y": 70,
      "z": -6,
      "name": "Rock_Calcite"
    },
    {
      "x": -20,
      "y": 71,
      "z": -6,
      "name": "Rock_Calcite"
    },
    {
      "x": -20,
      "y": 72,
      "z": -6,
      "name": "Rock_Calcite"
    },
    {
      "x": -20,
      "y": 73,
      "z": -6,
      "name": "Rock_Calcite"
    },
    {
      "x": -20,
      "y": 74,
      "z": -6,
      "name": "Rock_Calcite"
    },
    {
      "x": -20,
      "y": 75,
      "z": -6,
      "name": "Rock_Calcite"
    },
    {
      "x": -20,
      "y": 76,
      "z": -6,
      "name": "Rock_Calcite"
    },
    {
      "x": -20,
      "y": 77,
      "z": -6,
      "name": "Rock_Calcite"
    },
    {
      "x": -20,
      "y": 78,
      "z": -6,
      "name": "Rock_Calcite"
    },
    {
      "x": -20,
      "y": 79,
      "z": -6,
      "name": "Rock_Calcite"
    },
    {
      "x": -20,
      "y": 80,
      "z": -6,
      "name": "Rock_Calcite"
    },
    {
      "x": -20,
      "y": 81,
      "z": -6,
      "name": "Rock_Calcite"
    },
    {
      "x": -20,
      "y": 82,
      "z": -6,
      "name": "Rock_Calcite"
    },
    {
      "x": -20,
      "y": 83,
      "z": -6,
      "name": "Rock_Calcite"
    },
    {
      "x": -20,
      "y": 84,
      "z": -6,
      "name": "Rock_Calcite"
    },
    {
      "x": -20,
      "y": 85,
      "z": -6,
      "name": "Rock_Calcite"
    },
    {
      "x": -20,
      "y": 86,
      "z": -6,
      "name": "Rock_Calcite"
    },
    {
      "x": -20,
      "y": 87,
      "z": -6,
      "name": "Rock_Calcite"
    },
    {
      "x": -20,
      "y": 53,
      "z": -5,
      "name": "Rock_Calcite"
    },
    {
      "x": -20,
      "y": 54,
      "z": -5,
      "name": "Rock_Calcite"
    },
    {
      "x": -20,
      "y": 55,
      "z": -5,
      "name": "Rock_Calcite"
    },
    {
      "x": -20,
      "y": 56,
      "z": -5,
      "name": "Rock_Calcite"
    },
    {
      "x": -20,
      "y": 57,
      "z": -5,
      "name": "Rock_Calcite"
    },
    {
      "x": -20,
      "y": 58,
      "z": -5,
      "name": "Rock_Calcite"
    },
    {
      "x": -20,
      "y": 59,
      "z": -5,
      "name": "Rock_Calcite"
    },
    {
      "x": -20,
      "y": 60,
      "z": -5,
      "name": "Rock_Calcite"
    },
    {
      "x": -20,
      "y": 61,
      "z": -5,
      "name": "Rock_Calcite"
    },
    {
      "x": -20,
      "y": 62,
      "z": -5,
      "name": "Rock_Calcite"
    },
    {
      "x": -20,
      "y": 63,
      "z": -5,
      "name": "Rock_Calcite"
    },
    {
      "x": -20,
      "y": 64,
      "z": -5,
      "name": "Rock_Calcite"
    },
    {
      "x": -20,
      "y": 65,
      "z": -5,
      "name": "Rock_Calcite"
    },
    {
      "x": -20,
      "y": 66,
      "z": -5,
      "name": "Rock_Calcite"
    },
    {
      "x": -20,
      "y": 67,
      "z": -5,
      "name": "Rock_Calcite"
    },
    {
      "x": -20,
      "y": 68,
      "z": -5,
      "name": "Rock_Calcite"
    },
    {
      "x": -20,
      "y": 69,
      "z": -5,
      "name": "Rock_Calcite"
    },
    {
      "x": -20,
      "y": 70,
      "z": -5,
      "name": "Rock_Calcite"
    },
    {
      "x": -20,
      "y": 71,
      "z": -5,
      "name": "Rock_Calcite"
    },
    {
      "x": -20,
      "y": 72,
      "z": -5,
      "name": "Rock_Calcite"
    },
    {
      "x": -20,
      "y": 73,
      "z": -5,
      "name": "Rock_Calcite"
    },
    {
      "x": -20,
      "y": 74,
      "z": -5,
      "name": "Rock_Calcite"
    },
    {
      "x": -20,
      "y": 75,
      "z": -5,
      "name": "Rock_Calcite"
    },
    {
      "x": -20,
      "y": 76,
      "z": -5,
      "name": "Rock_Calcite"
    },
    {
      "x": -20,
      "y": 77,
      "z": -5,
      "name": "Rock_Calcite"
    },
    {
      "x": -20,
      "y": 78,
      "z": -5,
      "name": "Rock_Calcite"
    },
    {
      "x": -20,
      "y": 79,
      "z": -5,
      "name": "Rock_Calcite"
    },
    {
      "x": -20,
      "y": 80,
      "z": -5,
      "name": "Rock_Calcite"
    },
    {
      "x": -20,
      "y": 81,
      "z": -5,
      "name": "Rock_Calcite"
    },
    {
      "x": -20,
      "y": 82,
      "z": -5,
      "name": "Rock_Calcite"
    },
    {
      "x": -20,
      "y": 83,
      "z": -5,
      "name": "Rock_Calcite"
    },
    {
      "x": -20,
      "y": 84,
      "z": -5,
      "name": "Rock_Calcite"
    },
    {
      "x": -20,
      "y": 54,
      "z": -4,
      "name": "Rock_Calcite"
    },
    {
      "x": -20,
      "y": 55,
      "z": -4,
      "name": "Rock_Calcite"
    },
    {
      "x": -20,
      "y": 56,
      "z": -4,
      "name": "Rock_Calcite"
    },
    {
      "x": -20,
      "y": 57,
      "z": -4,
      "name": "Rock_Calcite"
    },
    {
      "x": -20,
      "y": 58,
      "z": -4,
      "name": "Rock_Calcite"
    },
    {
      "x": -20,
      "y": 59,
      "z": -4,
      "name": "Rock_Calcite"
    },
    {
      "x": -20,
      "y": 60,
      "z": -4,
      "name": "Rock_Calcite"
    },
    {
      "x": -20,
      "y": 61,
      "z": -4,
      "name": "Rock_Calcite"
    },
    {
      "x": -20,
      "y": 62,
      "z": -4,
      "name": "Rock_Calcite"
    },
    {
      "x": -20,
      "y": 63,
      "z": -4,
      "name": "Rock_Calcite"
    },
    {
      "x": -20,
      "y": 64,
      "z": -4,
      "name": "Rock_Calcite"
    },
    {
      "x": -20,
      "y": 65,
      "z": -4,
      "name": "Rock_Calcite"
    },
    {
      "x": -20,
      "y": 66,
      "z": -4,
      "name": "Rock_Calcite"
    },
    {
      "x": -20,
      "y": 67,
      "z": -4,
      "name": "Rock_Calcite"
    },
    {
      "x": -20,
      "y": 68,
      "z": -4,
      "name": "Rock_Calcite"
    },
    {
      "x": -20,
      "y": 69,
      "z": -4,
      "name": "Rock_Calcite"
    },
    {
      "x": -20,
      "y": 73,
      "z": -4,
      "name": "Rock_Calcite"
    },
    {
      "x": -20,
      "y": 74,
      "z": -4,
      "name": "Rock_Calcite"
    },
    {
      "x": -20,
      "y": 75,
      "z": -4,
      "name": "Rock_Calcite"
    },
    {
      "x": -20,
      "y": 76,
      "z": -4,
      "name": "Rock_Calcite"
    },
    {
      "x": -20,
      "y": 77,
      "z": -4,
      "name": "Rock_Calcite"
    },
    {
      "x": -20,
      "y": 78,
      "z": -4,
      "name": "Rock_Calcite"
    },
    {
      "x": -20,
      "y": 79,
      "z": -4,
      "name": "Rock_Calcite"
    },
    {
      "x": -20,
      "y": 80,
      "z": -4,
      "name": "Rock_Calcite"
    },
    {
      "x": -20,
      "y": 81,
      "z": -4,
      "name": "Rock_Calcite"
    },
    {
      "x": -20,
      "y": 60,
      "z": -3,
      "name": "Rock_Calcite"
    },
    {
      "x": -20,
      "y": 61,
      "z": -3,
      "name": "Rock_Calcite"
    },
    {
      "x": -20,
      "y": 62,
      "z": -3,
      "name": "Rock_Calcite"
    },
    {
      "x": -20,
      "y": 63,
      "z": -3,
      "name": "Rock_Calcite"
    },
    {
      "x": -20,
      "y": 64,
      "z": -3,
      "name": "Rock_Calcite"
    },
    {
      "x": -20,
      "y": 65,
      "z": -3,
      "name": "Rock_Calcite"
    },
    {
      "x": -20,
      "y": 66,
      "z": -3,
      "name": "Rock_Calcite"
    },
    {
      "x": -20,
      "y": 67,
      "z": -3,
      "name": "Rock_Calcite"
    },
    {
      "x": -20,
      "y": 68,
      "z": -3,
      "name": "Rock_Calcite"
    },
    {
      "x": -20,
      "y": 74,
      "z": -3,
      "name": "Rock_Calcite"
    },
    {
      "x": -20,
      "y": 76,
      "z": -3,
      "name": "Rock_Calcite"
    },
    {
      "x": -20,
      "y": 77,
      "z": -3,
      "name": "Rock_Calcite"
    },
    {
      "x": -20,
      "y": 78,
      "z": -3,
      "name": "Rock_Calcite"
    },
    {
      "x": -20,
      "y": 64,
      "z": 4,
      "name": "Rock_Calcite"
    },
    {
      "x": -20,
      "y": 65,
      "z": 4,
      "name": "Rock_Calcite"
    },
    {
      "x": -20,
      "y": 66,
      "z": 4,
      "name": "Rock_Calcite"
    },
    {
      "x": -20,
      "y": 67,
      "z": 4,
      "name": "Rock_Calcite"
    },
    {
      "x": -20,
      "y": 68,
      "z": 4,
      "name": "Rock_Calcite"
    },
    {
      "x": -20,
      "y": 69,
      "z": 4,
      "name": "Rock_Calcite"
    },
    {
      "x": -20,
      "y": 77,
      "z": 4,
      "name": "Rock_Calcite"
    },
    {
      "x": -20,
      "y": 78,
      "z": 4,
      "name": "Rock_Calcite"
    },
    {
      "x": -20,
      "y": 63,
      "z": 5,
      "name": "Rock_Calcite"
    },
    {
      "x": -20,
      "y": 64,
      "z": 5,
      "name": "Rock_Calcite"
    },
    {
      "x": -20,
      "y": 65,
      "z": 5,
      "name": "Rock_Calcite"
    },
    {
      "x": -20,
      "y": 66,
      "z": 5,
      "name": "Rock_Calcite"
    },
    {
      "x": -20,
      "y": 67,
      "z": 5,
      "name": "Rock_Calcite"
    },
    {
      "x": -20,
      "y": 68,
      "z": 5,
      "name": "Rock_Calcite"
    },
    {
      "x": -20,
      "y": 69,
      "z": 5,
      "name": "Rock_Calcite"
    },
    {
      "x": -20,
      "y": 70,
      "z": 5,
      "name": "Rock_Calcite"
    },
    {
      "x": -20,
      "y": 71,
      "z": 5,
      "name": "Rock_Calcite"
    },
    {
      "x": -20,
      "y": 72,
      "z": 5,
      "name": "Rock_Calcite"
    },
    {
      "x": -20,
      "y": 74,
      "z": 5,
      "name": "Rock_Calcite"
    },
    {
      "x": -20,
      "y": 75,
      "z": 5,
      "name": "Rock_Calcite"
    },
    {
      "x": -20,
      "y": 76,
      "z": 5,
      "name": "Rock_Calcite"
    },
    {
      "x": -20,
      "y": 77,
      "z": 5,
      "name": "Rock_Calcite"
    },
    {
      "x": -20,
      "y": 78,
      "z": 5,
      "name": "Rock_Calcite"
    },
    {
      "x": -20,
      "y": 79,
      "z": 5,
      "name": "Rock_Calcite"
    },
    {
      "x": -20,
      "y": 80,
      "z": 5,
      "name": "Rock_Calcite"
    },
    {
      "x": -20,
      "y": 62,
      "z": 6,
      "name": "Rock_Calcite"
    },
    {
      "x": -20,
      "y": 63,
      "z": 6,
      "name": "Rock_Calcite"
    },
    {
      "x": -20,
      "y": 64,
      "z": 6,
      "name": "Rock_Calcite"
    },
    {
      "x": -20,
      "y": 65,
      "z": 6,
      "name": "Rock_Calcite"
    },
    {
      "x": -20,
      "y": 66,
      "z": 6,
      "name": "Rock_Calcite"
    },
    {
      "x": -20,
      "y": 67,
      "z": 6,
      "name": "Rock_Calcite"
    },
    {
      "x": -20,
      "y": 68,
      "z": 6,
      "name": "Rock_Calcite"
    },
    {
      "x": -20,
      "y": 69,
      "z": 6,
      "name": "Rock_Calcite"
    },
    {
      "x": -20,
      "y": 70,
      "z": 6,
      "name": "Rock_Calcite"
    },
    {
      "x": -20,
      "y": 71,
      "z": 6,
      "name": "Rock_Calcite"
    },
    {
      "x": -20,
      "y": 72,
      "z": 6,
      "name": "Rock_Calcite"
    },
    {
      "x": -20,
      "y": 73,
      "z": 6,
      "name": "Rock_Calcite"
    },
    {
      "x": -20,
      "y": 74,
      "z": 6,
      "name": "Rock_Calcite"
    },
    {
      "x": -20,
      "y": 75,
      "z": 6,
      "name": "Rock_Calcite"
    },
    {
      "x": -20,
      "y": 76,
      "z": 6,
      "name": "Rock_Calcite"
    },
    {
      "x": -20,
      "y": 77,
      "z": 6,
      "name": "Rock_Calcite"
    },
    {
      "x": -20,
      "y": 78,
      "z": 6,
      "name": "Rock_Calcite"
    },
    {
      "x": -20,
      "y": 79,
      "z": 6,
      "name": "Rock_Calcite"
    },
    {
      "x": -20,
      "y": 80,
      "z": 6,
      "name": "Rock_Calcite"
    },
    {
      "x": -20,
      "y": 81,
      "z": 6,
      "name": "Rock_Calcite"
    },
    {
      "x": -20,
      "y": 82,
      "z": 6,
      "name": "Rock_Calcite"
    },
    {
      "x": -20,
      "y": 83,
      "z": 6,
      "name": "Rock_Calcite"
    },
    {
      "x": -20,
      "y": 63,
      "z": 7,
      "name": "Rock_Calcite"
    },
    {
      "x": -20,
      "y": 64,
      "z": 7,
      "name": "Rock_Calcite"
    },
    {
      "x": -20,
      "y": 65,
      "z": 7,
      "name": "Rock_Calcite"
    },
    {
      "x": -20,
      "y": 66,
      "z": 7,
      "name": "Rock_Calcite"
    },
    {
      "x": -20,
      "y": 67,
      "z": 7,
      "name": "Rock_Calcite"
    },
    {
      "x": -20,
      "y": 68,
      "z": 7,
      "name": "Rock_Calcite"
    },
    {
      "x": -20,
      "y": 69,
      "z": 7,
      "name": "Rock_Calcite"
    },
    {
      "x": -20,
      "y": 70,
      "z": 7,
      "name": "Rock_Calcite"
    },
    {
      "x": -20,
      "y": 71,
      "z": 7,
      "name": "Rock_Calcite"
    },
    {
      "x": -20,
      "y": 72,
      "z": 7,
      "name": "Rock_Calcite"
    },
    {
      "x": -20,
      "y": 73,
      "z": 7,
      "name": "Rock_Calcite"
    },
    {
      "x": -20,
      "y": 74,
      "z": 7,
      "name": "Rock_Calcite"
    },
    {
      "x": -20,
      "y": 75,
      "z": 7,
      "name": "Rock_Calcite"
    },
    {
      "x": -20,
      "y": 76,
      "z": 7,
      "name": "Rock_Calcite"
    },
    {
      "x": -20,
      "y": 77,
      "z": 7,
      "name": "Rock_Calcite"
    },
    {
      "x": -20,
      "y": 78,
      "z": 7,
      "name": "Rock_Calcite"
    },
    {
      "x": -20,
      "y": 79,
      "z": 7,
      "name": "Rock_Calcite"
    },
    {
      "x": -20,
      "y": 80,
      "z": 7,
      "name": "Rock_Calcite"
    },
    {
      "x": -20,
      "y": 81,
      "z": 7,
      "name": "Rock_Calcite"
    },
    {
      "x": -20,
      "y": 82,
      "z": 7,
      "name": "Rock_Calcite"
    },
    {
      "x": -20,
      "y": 83,
      "z": 7,
      "name": "Rock_Calcite"
    },
    {
      "x": -20,
      "y": 84,
      "z": 7,
      "name": "Rock_Calcite"
    },
    {
      "x": -20,
      "y": 85,
      "z": 7,
      "name": "Rock_Calcite"
    },
    {
      "x": -20,
      "y": 86,
      "z": 7,
      "name": "Rock_Calcite"
    },
    {
      "x": -20,
      "y": 64,
      "z": 8,
      "name": "Rock_Calcite"
    },
    {
      "x": -20,
      "y": 70,
      "z": 8,
      "name": "Rock_Calcite"
    },
    {
      "x": -20,
      "y": 71,
      "z": 8,
      "name": "Rock_Calcite"
    },
    {
      "x": -20,
      "y": 72,
      "z": 8,
      "name": "Rock_Calcite"
    },
    {
      "x": -20,
      "y": 73,
      "z": 8,
      "name": "Rock_Calcite"
    },
    {
      "x": -20,
      "y": 74,
      "z": 8,
      "name": "Rock_Calcite"
    },
    {
      "x": -20,
      "y": 75,
      "z": 8,
      "name": "Rock_Calcite"
    },
    {
      "x": -20,
      "y": 76,
      "z": 8,
      "name": "Rock_Calcite"
    },
    {
      "x": -20,
      "y": 77,
      "z": 8,
      "name": "Rock_Calcite"
    },
    {
      "x": -20,
      "y": 78,
      "z": 8,
      "name": "Rock_Calcite"
    },
    {
      "x": -20,
      "y": 79,
      "z": 8,
      "name": "Rock_Calcite"
    },
    {
      "x": -20,
      "y": 80,
      "z": 8,
      "name": "Rock_Calcite"
    },
    {
      "x": -20,
      "y": 81,
      "z": 8,
      "name": "Rock_Calcite"
    },
    {
      "x": -20,
      "y": 82,
      "z": 8,
      "name": "Rock_Calcite"
    },
    {
      "x": -20,
      "y": 83,
      "z": 8,
      "name": "Rock_Calcite"
    },
    {
      "x": -20,
      "y": 74,
      "z": 9,
      "name": "Rock_Calcite"
    },
    {
      "x": -20,
      "y": 75,
      "z": 9,
      "name": "Rock_Calcite"
    },
    {
      "x": -20,
      "y": 76,
      "z": 9,
      "name": "Rock_Calcite"
    },
    {
      "x": -20,
      "y": 77,
      "z": 9,
      "name": "Rock_Calcite"
    },
    {
      "x": -20,
      "y": 78,
      "z": 9,
      "name": "Rock_Calcite"
    },
    {
      "x": -20,
      "y": 79,
      "z": 9,
      "name": "Rock_Calcite"
    },
    {
      "x": -20,
      "y": 80,
      "z": 9,
      "name": "Rock_Calcite"
    },
    {
      "x": -20,
      "y": 77,
      "z": 10,
      "name": "Rock_Calcite"
    },
    {
      "x": -20,
      "y": 78,
      "z": 10,
      "name": "Rock_Calcite"
    },
    {
      "x": -19,
      "y": 64,
      "z": -10,
      "name": "Rock_Calcite"
    },
    {
      "x": -19,
      "y": 65,
      "z": -10,
      "name": "Rock_Calcite"
    },
    {
      "x": -19,
      "y": 66,
      "z": -10,
      "name": "Rock_Calcite"
    },
    {
      "x": -19,
      "y": 55,
      "z": -9,
      "name": "Rock_Calcite"
    },
    {
      "x": -19,
      "y": 56,
      "z": -9,
      "name": "Rock_Calcite"
    },
    {
      "x": -19,
      "y": 57,
      "z": -9,
      "name": "Rock_Calcite"
    },
    {
      "x": -19,
      "y": 58,
      "z": -9,
      "name": "Rock_Calcite"
    },
    {
      "x": -19,
      "y": 59,
      "z": -9,
      "name": "Rock_Calcite"
    },
    {
      "x": -19,
      "y": 60,
      "z": -9,
      "name": "Rock_Calcite"
    },
    {
      "x": -19,
      "y": 61,
      "z": -9,
      "name": "Rock_Calcite"
    },
    {
      "x": -19,
      "y": 62,
      "z": -9,
      "name": "Rock_Calcite"
    },
    {
      "x": -19,
      "y": 63,
      "z": -9,
      "name": "Rock_Calcite"
    },
    {
      "x": -19,
      "y": 64,
      "z": -9,
      "name": "Rock_Calcite"
    },
    {
      "x": -19,
      "y": 65,
      "z": -9,
      "name": "Rock_Calcite"
    },
    {
      "x": -19,
      "y": 66,
      "z": -9,
      "name": "Rock_Calcite"
    },
    {
      "x": -19,
      "y": 67,
      "z": -9,
      "name": "Rock_Calcite"
    },
    {
      "x": -19,
      "y": 69,
      "z": -9,
      "name": "Rock_Calcite"
    },
    {
      "x": -19,
      "y": 74,
      "z": -9,
      "name": "Rock_Calcite"
    },
    {
      "x": -19,
      "y": 75,
      "z": -9,
      "name": "Rock_Calcite"
    },
    {
      "x": -19,
      "y": 76,
      "z": -9,
      "name": "Rock_Calcite"
    },
    {
      "x": -19,
      "y": 51,
      "z": -8,
      "name": "Rock_Calcite"
    },
    {
      "x": -19,
      "y": 53,
      "z": -8,
      "name": "Rock_Calcite"
    },
    {
      "x": -19,
      "y": 54,
      "z": -8,
      "name": "Rock_Calcite"
    },
    {
      "x": -19,
      "y": 55,
      "z": -8,
      "name": "Rock_Calcite"
    },
    {
      "x": -19,
      "y": 56,
      "z": -8,
      "name": "Rock_Calcite"
    },
    {
      "x": -19,
      "y": 57,
      "z": -8,
      "name": "Rock_Calcite"
    },
    {
      "x": -19,
      "y": 58,
      "z": -8,
      "name": "Rock_Calcite"
    },
    {
      "x": -19,
      "y": 59,
      "z": -8,
      "name": "Rock_Calcite"
    },
    {
      "x": -19,
      "y": 60,
      "z": -8,
      "name": "Rock_Calcite"
    },
    {
      "x": -19,
      "y": 61,
      "z": -8,
      "name": "Rock_Calcite"
    },
    {
      "x": -19,
      "y": 62,
      "z": -8,
      "name": "Rock_Calcite"
    },
    {
      "x": -19,
      "y": 63,
      "z": -8,
      "name": "Rock_Calcite"
    },
    {
      "x": -19,
      "y": 64,
      "z": -8,
      "name": "Rock_Calcite"
    },
    {
      "x": -19,
      "y": 65,
      "z": -8,
      "name": "Rock_Calcite"
    },
    {
      "x": -19,
      "y": 66,
      "z": -8,
      "name": "Rock_Calcite"
    },
    {
      "x": -19,
      "y": 67,
      "z": -8,
      "name": "Rock_Calcite"
    },
    {
      "x": -19,
      "y": 68,
      "z": -8,
      "name": "Rock_Calcite"
    },
    {
      "x": -19,
      "y": 69,
      "z": -8,
      "name": "Rock_Calcite"
    },
    {
      "x": -19,
      "y": 70,
      "z": -8,
      "name": "Rock_Calcite"
    },
    {
      "x": -19,
      "y": 71,
      "z": -8,
      "name": "Rock_Calcite"
    },
    {
      "x": -19,
      "y": 72,
      "z": -8,
      "name": "Rock_Calcite"
    },
    {
      "x": -19,
      "y": 73,
      "z": -8,
      "name": "Rock_Calcite"
    },
    {
      "x": -19,
      "y": 74,
      "z": -8,
      "name": "Rock_Calcite"
    },
    {
      "x": -19,
      "y": 75,
      "z": -8,
      "name": "Rock_Calcite"
    },
    {
      "x": -19,
      "y": 76,
      "z": -8,
      "name": "Rock_Calcite"
    },
    {
      "x": -19,
      "y": 77,
      "z": -8,
      "name": "Rock_Calcite"
    },
    {
      "x": -19,
      "y": 78,
      "z": -8,
      "name": "Rock_Calcite"
    },
    {
      "x": -19,
      "y": 79,
      "z": -8,
      "name": "Rock_Calcite"
    },
    {
      "x": -19,
      "y": 80,
      "z": -8,
      "name": "Rock_Calcite"
    },
    {
      "x": -19,
      "y": 50,
      "z": -7,
      "name": "Rock_Calcite"
    },
    {
      "x": -19,
      "y": 51,
      "z": -7,
      "name": "Rock_Calcite"
    },
    {
      "x": -19,
      "y": 52,
      "z": -7,
      "name": "Rock_Calcite"
    },
    {
      "x": -19,
      "y": 53,
      "z": -7,
      "name": "Rock_Calcite"
    },
    {
      "x": -19,
      "y": 54,
      "z": -7,
      "name": "Rock_Calcite"
    },
    {
      "x": -19,
      "y": 55,
      "z": -7,
      "name": "Rock_Calcite"
    },
    {
      "x": -19,
      "y": 56,
      "z": -7,
      "name": "Rock_Calcite"
    },
    {
      "x": -19,
      "y": 57,
      "z": -7,
      "name": "Rock_Calcite"
    },
    {
      "x": -19,
      "y": 58,
      "z": -7,
      "name": "Rock_Calcite"
    },
    {
      "x": -19,
      "y": 59,
      "z": -7,
      "name": "Rock_Calcite"
    },
    {
      "x": -19,
      "y": 60,
      "z": -7,
      "name": "Rock_Calcite"
    },
    {
      "x": -19,
      "y": 61,
      "z": -7,
      "name": "Rock_Calcite"
    },
    {
      "x": -19,
      "y": 62,
      "z": -7,
      "name": "Rock_Calcite"
    },
    {
      "x": -19,
      "y": 63,
      "z": -7,
      "name": "Rock_Calcite"
    },
    {
      "x": -19,
      "y": 64,
      "z": -7,
      "name": "Rock_Calcite"
    },
    {
      "x": -19,
      "y": 65,
      "z": -7,
      "name": "Rock_Calcite"
    },
    {
      "x": -19,
      "y": 66,
      "z": -7,
      "name": "Rock_Calcite"
    },
    {
      "x": -19,
      "y": 67,
      "z": -7,
      "name": "Rock_Calcite"
    },
    {
      "x": -19,
      "y": 68,
      "z": -7,
      "name": "Rock_Calcite"
    },
    {
      "x": -19,
      "y": 69,
      "z": -7,
      "name": "Rock_Calcite"
    },
    {
      "x": -19,
      "y": 70,
      "z": -7,
      "name": "Rock_Calcite"
    },
    {
      "x": -19,
      "y": 71,
      "z": -7,
      "name": "Rock_Calcite"
    },
    {
      "x": -19,
      "y": 72,
      "z": -7,
      "name": "Rock_Calcite"
    },
    {
      "x": -19,
      "y": 73,
      "z": -7,
      "name": "Rock_Calcite"
    },
    {
      "x": -19,
      "y": 74,
      "z": -7,
      "name": "Rock_Calcite"
    },
    {
      "x": -19,
      "y": 75,
      "z": -7,
      "name": "Rock_Calcite"
    },
    {
      "x": -19,
      "y": 76,
      "z": -7,
      "name": "Rock_Calcite"
    },
    {
      "x": -19,
      "y": 77,
      "z": -7,
      "name": "Rock_Calcite"
    },
    {
      "x": -19,
      "y": 78,
      "z": -7,
      "name": "Rock_Calcite"
    },
    {
      "x": -19,
      "y": 79,
      "z": -7,
      "name": "Rock_Calcite"
    },
    {
      "x": -19,
      "y": 80,
      "z": -7,
      "name": "Rock_Calcite"
    },
    {
      "x": -19,
      "y": 81,
      "z": -7,
      "name": "Rock_Calcite"
    },
    {
      "x": -19,
      "y": 82,
      "z": -7,
      "name": "Rock_Calcite"
    },
    {
      "x": -19,
      "y": 83,
      "z": -7,
      "name": "Rock_Calcite"
    },
    {
      "x": -19,
      "y": 51,
      "z": -6,
      "name": "Rock_Calcite"
    },
    {
      "x": -19,
      "y": 52,
      "z": -6,
      "name": "Rock_Calcite"
    },
    {
      "x": -19,
      "y": 53,
      "z": -6,
      "name": "Rock_Calcite"
    },
    {
      "x": -19,
      "y": 54,
      "z": -6,
      "name": "Rock_Calcite"
    },
    {
      "x": -19,
      "y": 55,
      "z": -6,
      "name": "Rock_Calcite"
    },
    {
      "x": -19,
      "y": 56,
      "z": -6,
      "name": "Rock_Calcite"
    },
    {
      "x": -19,
      "y": 57,
      "z": -6,
      "name": "Rock_Calcite"
    },
    {
      "x": -19,
      "y": 58,
      "z": -6,
      "name": "Rock_Calcite"
    },
    {
      "x": -19,
      "y": 59,
      "z": -6,
      "name": "Rock_Calcite"
    },
    {
      "x": -19,
      "y": 60,
      "z": -6,
      "name": "Rock_Calcite"
    },
    {
      "x": -19,
      "y": 61,
      "z": -6,
      "name": "Rock_Calcite"
    },
    {
      "x": -19,
      "y": 62,
      "z": -6,
      "name": "Rock_Calcite"
    },
    {
      "x": -19,
      "y": 63,
      "z": -6,
      "name": "Rock_Calcite"
    },
    {
      "x": -19,
      "y": 64,
      "z": -6,
      "name": "Rock_Calcite"
    },
    {
      "x": -19,
      "y": 65,
      "z": -6,
      "name": "Rock_Calcite"
    },
    {
      "x": -19,
      "y": 66,
      "z": -6,
      "name": "Rock_Calcite"
    },
    {
      "x": -19,
      "y": 67,
      "z": -6,
      "name": "Rock_Calcite"
    },
    {
      "x": -19,
      "y": 68,
      "z": -6,
      "name": "Rock_Calcite"
    },
    {
      "x": -19,
      "y": 69,
      "z": -6,
      "name": "Rock_Calcite"
    },
    {
      "x": -19,
      "y": 70,
      "z": -6,
      "name": "Rock_Calcite"
    },
    {
      "x": -19,
      "y": 71,
      "z": -6,
      "name": "Rock_Calcite"
    },
    {
      "x": -19,
      "y": 72,
      "z": -6,
      "name": "Rock_Calcite"
    },
    {
      "x": -19,
      "y": 73,
      "z": -6,
      "name": "Rock_Calcite"
    },
    {
      "x": -19,
      "y": 74,
      "z": -6,
      "name": "Rock_Calcite"
    },
    {
      "x": -19,
      "y": 75,
      "z": -6,
      "name": "Rock_Calcite"
    },
    {
      "x": -19,
      "y": 76,
      "z": -6,
      "name": "Rock_Calcite"
    },
    {
      "x": -19,
      "y": 77,
      "z": -6,
      "name": "Rock_Calcite"
    },
    {
      "x": -19,
      "y": 78,
      "z": -6,
      "name": "Rock_Calcite"
    },
    {
      "x": -19,
      "y": 79,
      "z": -6,
      "name": "Rock_Calcite"
    },
    {
      "x": -19,
      "y": 80,
      "z": -6,
      "name": "Rock_Calcite"
    },
    {
      "x": -19,
      "y": 81,
      "z": -6,
      "name": "Rock_Calcite"
    },
    {
      "x": -19,
      "y": 82,
      "z": -6,
      "name": "Rock_Calcite"
    },
    {
      "x": -19,
      "y": 83,
      "z": -6,
      "name": "Rock_Calcite"
    },
    {
      "x": -19,
      "y": 84,
      "z": -6,
      "name": "Rock_Calcite"
    },
    {
      "x": -19,
      "y": 52,
      "z": -5,
      "name": "Rock_Calcite"
    },
    {
      "x": -19,
      "y": 53,
      "z": -5,
      "name": "Rock_Calcite"
    },
    {
      "x": -19,
      "y": 54,
      "z": -5,
      "name": "Rock_Calcite"
    },
    {
      "x": -19,
      "y": 55,
      "z": -5,
      "name": "Rock_Calcite"
    },
    {
      "x": -19,
      "y": 56,
      "z": -5,
      "name": "Rock_Calcite"
    },
    {
      "x": -19,
      "y": 57,
      "z": -5,
      "name": "Rock_Calcite"
    },
    {
      "x": -19,
      "y": 58,
      "z": -5,
      "name": "Rock_Calcite"
    },
    {
      "x": -19,
      "y": 59,
      "z": -5,
      "name": "Rock_Calcite"
    },
    {
      "x": -19,
      "y": 60,
      "z": -5,
      "name": "Rock_Calcite"
    },
    {
      "x": -19,
      "y": 61,
      "z": -5,
      "name": "Rock_Calcite"
    },
    {
      "x": -19,
      "y": 62,
      "z": -5,
      "name": "Rock_Calcite"
    },
    {
      "x": -19,
      "y": 63,
      "z": -5,
      "name": "Rock_Calcite"
    },
    {
      "x": -19,
      "y": 64,
      "z": -5,
      "name": "Rock_Calcite"
    },
    {
      "x": -19,
      "y": 65,
      "z": -5,
      "name": "Rock_Calcite"
    },
    {
      "x": -19,
      "y": 66,
      "z": -5,
      "name": "Rock_Calcite"
    },
    {
      "x": -19,
      "y": 67,
      "z": -5,
      "name": "Rock_Calcite"
    },
    {
      "x": -19,
      "y": 68,
      "z": -5,
      "name": "Rock_Calcite"
    },
    {
      "x": -19,
      "y": 69,
      "z": -5,
      "name": "Rock_Calcite"
    },
    {
      "x": -19,
      "y": 70,
      "z": -5,
      "name": "Rock_Calcite"
    },
    {
      "x": -19,
      "y": 71,
      "z": -5,
      "name": "Rock_Calcite"
    },
    {
      "x": -19,
      "y": 72,
      "z": -5,
      "name": "Rock_Calcite"
    },
    {
      "x": -19,
      "y": 73,
      "z": -5,
      "name": "Rock_Calcite"
    },
    {
      "x": -19,
      "y": 74,
      "z": -5,
      "name": "Rock_Calcite"
    },
    {
      "x": -19,
      "y": 75,
      "z": -5,
      "name": "Rock_Calcite"
    },
    {
      "x": -19,
      "y": 76,
      "z": -5,
      "name": "Rock_Calcite"
    },
    {
      "x": -19,
      "y": 77,
      "z": -5,
      "name": "Rock_Calcite"
    },
    {
      "x": -19,
      "y": 78,
      "z": -5,
      "name": "Rock_Calcite"
    },
    {
      "x": -19,
      "y": 79,
      "z": -5,
      "name": "Rock_Calcite"
    },
    {
      "x": -19,
      "y": 80,
      "z": -5,
      "name": "Rock_Calcite"
    },
    {
      "x": -19,
      "y": 81,
      "z": -5,
      "name": "Rock_Calcite"
    },
    {
      "x": -19,
      "y": 82,
      "z": -5,
      "name": "Rock_Calcite"
    },
    {
      "x": -19,
      "y": 83,
      "z": -5,
      "name": "Rock_Calcite"
    },
    {
      "x": -19,
      "y": 53,
      "z": -4,
      "name": "Rock_Calcite"
    },
    {
      "x": -19,
      "y": 54,
      "z": -4,
      "name": "Rock_Calcite"
    },
    {
      "x": -19,
      "y": 55,
      "z": -4,
      "name": "Rock_Calcite"
    },
    {
      "x": -19,
      "y": 56,
      "z": -4,
      "name": "Rock_Calcite"
    },
    {
      "x": -19,
      "y": 57,
      "z": -4,
      "name": "Rock_Calcite"
    },
    {
      "x": -19,
      "y": 58,
      "z": -4,
      "name": "Rock_Calcite"
    },
    {
      "x": -19,
      "y": 59,
      "z": -4,
      "name": "Rock_Calcite"
    },
    {
      "x": -19,
      "y": 60,
      "z": -4,
      "name": "Rock_Calcite"
    },
    {
      "x": -19,
      "y": 61,
      "z": -4,
      "name": "Rock_Calcite"
    },
    {
      "x": -19,
      "y": 62,
      "z": -4,
      "name": "Rock_Calcite"
    },
    {
      "x": -19,
      "y": 63,
      "z": -4,
      "name": "Rock_Calcite"
    },
    {
      "x": -19,
      "y": 64,
      "z": -4,
      "name": "Rock_Calcite"
    },
    {
      "x": -19,
      "y": 65,
      "z": -4,
      "name": "Rock_Calcite"
    },
    {
      "x": -19,
      "y": 66,
      "z": -4,
      "name": "Rock_Calcite"
    },
    {
      "x": -19,
      "y": 67,
      "z": -4,
      "name": "Rock_Calcite"
    },
    {
      "x": -19,
      "y": 68,
      "z": -4,
      "name": "Rock_Calcite"
    },
    {
      "x": -19,
      "y": 69,
      "z": -4,
      "name": "Rock_Calcite"
    },
    {
      "x": -19,
      "y": 70,
      "z": -4,
      "name": "Rock_Calcite"
    },
    {
      "x": -19,
      "y": 72,
      "z": -4,
      "name": "Rock_Calcite"
    },
    {
      "x": -19,
      "y": 73,
      "z": -4,
      "name": "Rock_Calcite"
    },
    {
      "x": -19,
      "y": 74,
      "z": -4,
      "name": "Rock_Calcite"
    },
    {
      "x": -19,
      "y": 75,
      "z": -4,
      "name": "Rock_Calcite"
    },
    {
      "x": -19,
      "y": 76,
      "z": -4,
      "name": "Rock_Calcite"
    },
    {
      "x": -19,
      "y": 77,
      "z": -4,
      "name": "Rock_Calcite"
    },
    {
      "x": -19,
      "y": 78,
      "z": -4,
      "name": "Rock_Calcite"
    },
    {
      "x": -19,
      "y": 79,
      "z": -4,
      "name": "Rock_Calcite"
    },
    {
      "x": -19,
      "y": 80,
      "z": -4,
      "name": "Rock_Calcite"
    },
    {
      "x": -19,
      "y": 55,
      "z": -3,
      "name": "Rock_Calcite"
    },
    {
      "x": -19,
      "y": 56,
      "z": -3,
      "name": "Rock_Calcite"
    },
    {
      "x": -19,
      "y": 57,
      "z": -3,
      "name": "Rock_Calcite"
    },
    {
      "x": -19,
      "y": 58,
      "z": -3,
      "name": "Rock_Calcite"
    },
    {
      "x": -19,
      "y": 59,
      "z": -3,
      "name": "Rock_Calcite"
    },
    {
      "x": -19,
      "y": 60,
      "z": -3,
      "name": "Rock_Calcite"
    },
    {
      "x": -19,
      "y": 61,
      "z": -3,
      "name": "Rock_Calcite"
    },
    {
      "x": -19,
      "y": 62,
      "z": -3,
      "name": "Rock_Calcite"
    },
    {
      "x": -19,
      "y": 63,
      "z": -3,
      "name": "Rock_Calcite"
    },
    {
      "x": -19,
      "y": 64,
      "z": -3,
      "name": "Rock_Calcite"
    },
    {
      "x": -19,
      "y": 65,
      "z": -3,
      "name": "Rock_Calcite"
    },
    {
      "x": -19,
      "y": 66,
      "z": -3,
      "name": "Rock_Calcite"
    },
    {
      "x": -19,
      "y": 67,
      "z": -3,
      "name": "Rock_Calcite"
    },
    {
      "x": -19,
      "y": 68,
      "z": -3,
      "name": "Rock_Calcite"
    },
    {
      "x": -19,
      "y": 69,
      "z": -3,
      "name": "Rock_Calcite"
    },
    {
      "x": -19,
      "y": 73,
      "z": -3,
      "name": "Rock_Calcite"
    },
    {
      "x": -19,
      "y": 74,
      "z": -3,
      "name": "Rock_Calcite"
    },
    {
      "x": -19,
      "y": 75,
      "z": -3,
      "name": "Rock_Calcite"
    },
    {
      "x": -19,
      "y": 76,
      "z": -3,
      "name": "Rock_Calcite"
    },
    {
      "x": -19,
      "y": 65,
      "z": 3,
      "name": "Rock_Calcite"
    },
    {
      "x": -19,
      "y": 66,
      "z": 3,
      "name": "Rock_Calcite"
    },
    {
      "x": -19,
      "y": 62,
      "z": 4,
      "name": "Rock_Calcite"
    },
    {
      "x": -19,
      "y": 63,
      "z": 4,
      "name": "Rock_Calcite"
    },
    {
      "x": -19,
      "y": 64,
      "z": 4,
      "name": "Rock_Calcite"
    },
    {
      "x": -19,
      "y": 65,
      "z": 4,
      "name": "Rock_Calcite"
    },
    {
      "x": -19,
      "y": 66,
      "z": 4,
      "name": "Rock_Calcite"
    },
    {
      "x": -19,
      "y": 67,
      "z": 4,
      "name": "Rock_Calcite"
    },
    {
      "x": -19,
      "y": 68,
      "z": 4,
      "name": "Rock_Calcite"
    },
    {
      "x": -19,
      "y": 69,
      "z": 4,
      "name": "Rock_Calcite"
    },
    {
      "x": -19,
      "y": 70,
      "z": 4,
      "name": "Rock_Calcite"
    },
    {
      "x": -19,
      "y": 71,
      "z": 4,
      "name": "Rock_Calcite"
    },
    {
      "x": -19,
      "y": 73,
      "z": 4,
      "name": "Rock_Calcite"
    },
    {
      "x": -19,
      "y": 76,
      "z": 4,
      "name": "Rock_Calcite"
    },
    {
      "x": -19,
      "y": 77,
      "z": 4,
      "name": "Rock_Calcite"
    },
    {
      "x": -19,
      "y": 78,
      "z": 4,
      "name": "Rock_Calcite"
    },
    {
      "x": -19,
      "y": 61,
      "z": 5,
      "name": "Rock_Calcite"
    },
    {
      "x": -19,
      "y": 62,
      "z": 5,
      "name": "Rock_Calcite"
    },
    {
      "x": -19,
      "y": 63,
      "z": 5,
      "name": "Rock_Calcite"
    },
    {
      "x": -19,
      "y": 64,
      "z": 5,
      "name": "Rock_Calcite"
    },
    {
      "x": -19,
      "y": 65,
      "z": 5,
      "name": "Rock_Calcite"
    },
    {
      "x": -19,
      "y": 66,
      "z": 5,
      "name": "Rock_Calcite"
    },
    {
      "x": -19,
      "y": 67,
      "z": 5,
      "name": "Rock_Calcite"
    },
    {
      "x": -19,
      "y": 68,
      "z": 5,
      "name": "Rock_Calcite"
    },
    {
      "x": -19,
      "y": 69,
      "z": 5,
      "name": "Rock_Calcite"
    },
    {
      "x": -19,
      "y": 70,
      "z": 5,
      "name": "Rock_Calcite"
    },
    {
      "x": -19,
      "y": 71,
      "z": 5,
      "name": "Rock_Calcite"
    },
    {
      "x": -19,
      "y": 72,
      "z": 5,
      "name": "Rock_Calcite"
    },
    {
      "x": -19,
      "y": 73,
      "z": 5,
      "name": "Rock_Calcite"
    },
    {
      "x": -19,
      "y": 74,
      "z": 5,
      "name": "Rock_Calcite"
    },
    {
      "x": -19,
      "y": 75,
      "z": 5,
      "name": "Rock_Calcite"
    },
    {
      "x": -19,
      "y": 76,
      "z": 5,
      "name": "Rock_Calcite"
    },
    {
      "x": -19,
      "y": 77,
      "z": 5,
      "name": "Rock_Calcite"
    },
    {
      "x": -19,
      "y": 78,
      "z": 5,
      "name": "Rock_Calcite"
    },
    {
      "x": -19,
      "y": 79,
      "z": 5,
      "name": "Rock_Calcite"
    },
    {
      "x": -19,
      "y": 60,
      "z": 6,
      "name": "Rock_Calcite"
    },
    {
      "x": -19,
      "y": 61,
      "z": 6,
      "name": "Rock_Calcite"
    },
    {
      "x": -19,
      "y": 62,
      "z": 6,
      "name": "Rock_Calcite"
    },
    {
      "x": -19,
      "y": 63,
      "z": 6,
      "name": "Rock_Calcite"
    },
    {
      "x": -19,
      "y": 64,
      "z": 6,
      "name": "Rock_Calcite"
    },
    {
      "x": -19,
      "y": 65,
      "z": 6,
      "name": "Rock_Calcite"
    },
    {
      "x": -19,
      "y": 66,
      "z": 6,
      "name": "Rock_Calcite"
    },
    {
      "x": -19,
      "y": 67,
      "z": 6,
      "name": "Rock_Calcite"
    },
    {
      "x": -19,
      "y": 68,
      "z": 6,
      "name": "Rock_Calcite"
    },
    {
      "x": -19,
      "y": 69,
      "z": 6,
      "name": "Rock_Calcite"
    },
    {
      "x": -19,
      "y": 70,
      "z": 6,
      "name": "Rock_Calcite"
    },
    {
      "x": -19,
      "y": 71,
      "z": 6,
      "name": "Rock_Calcite"
    },
    {
      "x": -19,
      "y": 72,
      "z": 6,
      "name": "Rock_Calcite"
    },
    {
      "x": -19,
      "y": 73,
      "z": 6,
      "name": "Rock_Calcite"
    },
    {
      "x": -19,
      "y": 74,
      "z": 6,
      "name": "Rock_Calcite"
    },
    {
      "x": -19,
      "y": 75,
      "z": 6,
      "name": "Rock_Calcite"
    },
    {
      "x": -19,
      "y": 76,
      "z": 6,
      "name": "Rock_Calcite"
    },
    {
      "x": -19,
      "y": 77,
      "z": 6,
      "name": "Rock_Calcite"
    },
    {
      "x": -19,
      "y": 78,
      "z": 6,
      "name": "Rock_Calcite"
    },
    {
      "x": -19,
      "y": 79,
      "z": 6,
      "name": "Rock_Calcite"
    },
    {
      "x": -19,
      "y": 80,
      "z": 6,
      "name": "Rock_Calcite"
    },
    {
      "x": -19,
      "y": 81,
      "z": 6,
      "name": "Rock_Calcite"
    },
    {
      "x": -19,
      "y": 82,
      "z": 6,
      "name": "Rock_Calcite"
    },
    {
      "x": -19,
      "y": 60,
      "z": 7,
      "name": "Rock_Calcite"
    },
    {
      "x": -19,
      "y": 61,
      "z": 7,
      "name": "Rock_Calcite"
    },
    {
      "x": -19,
      "y": 62,
      "z": 7,
      "name": "Rock_Calcite"
    },
    {
      "x": -19,
      "y": 63,
      "z": 7,
      "name": "Rock_Calcite"
    },
    {
      "x": -19,
      "y": 64,
      "z": 7,
      "name": "Rock_Calcite"
    },
    {
      "x": -19,
      "y": 65,
      "z": 7,
      "name": "Rock_Calcite"
    },
    {
      "x": -19,
      "y": 66,
      "z": 7,
      "name": "Rock_Calcite"
    },
    {
      "x": -19,
      "y": 67,
      "z": 7,
      "name": "Rock_Calcite"
    },
    {
      "x": -19,
      "y": 68,
      "z": 7,
      "name": "Rock_Calcite"
    },
    {
      "x": -19,
      "y": 69,
      "z": 7,
      "name": "Rock_Calcite"
    },
    {
      "x": -19,
      "y": 70,
      "z": 7,
      "name": "Rock_Calcite"
    },
    {
      "x": -19,
      "y": 71,
      "z": 7,
      "name": "Rock_Calcite"
    },
    {
      "x": -19,
      "y": 72,
      "z": 7,
      "name": "Rock_Calcite"
    },
    {
      "x": -19,
      "y": 73,
      "z": 7,
      "name": "Rock_Calcite"
    },
    {
      "x": -19,
      "y": 74,
      "z": 7,
      "name": "Rock_Calcite"
    },
    {
      "x": -19,
      "y": 75,
      "z": 7,
      "name": "Rock_Calcite"
    },
    {
      "x": -19,
      "y": 76,
      "z": 7,
      "name": "Rock_Calcite"
    },
    {
      "x": -19,
      "y": 77,
      "z": 7,
      "name": "Rock_Calcite"
    },
    {
      "x": -19,
      "y": 78,
      "z": 7,
      "name": "Rock_Calcite"
    },
    {
      "x": -19,
      "y": 79,
      "z": 7,
      "name": "Rock_Calcite"
    },
    {
      "x": -19,
      "y": 80,
      "z": 7,
      "name": "Rock_Calcite"
    },
    {
      "x": -19,
      "y": 81,
      "z": 7,
      "name": "Rock_Calcite"
    },
    {
      "x": -19,
      "y": 82,
      "z": 7,
      "name": "Rock_Calcite"
    },
    {
      "x": -19,
      "y": 83,
      "z": 7,
      "name": "Rock_Calcite"
    },
    {
      "x": -19,
      "y": 62,
      "z": 8,
      "name": "Rock_Calcite"
    },
    {
      "x": -19,
      "y": 63,
      "z": 8,
      "name": "Rock_Calcite"
    },
    {
      "x": -19,
      "y": 64,
      "z": 8,
      "name": "Rock_Calcite"
    },
    {
      "x": -19,
      "y": 65,
      "z": 8,
      "name": "Rock_Calcite"
    },
    {
      "x": -19,
      "y": 66,
      "z": 8,
      "name": "Rock_Calcite"
    },
    {
      "x": -19,
      "y": 67,
      "z": 8,
      "name": "Rock_Calcite"
    },
    {
      "x": -19,
      "y": 68,
      "z": 8,
      "name": "Rock_Calcite"
    },
    {
      "x": -19,
      "y": 69,
      "z": 8,
      "name": "Rock_Calcite"
    },
    {
      "x": -19,
      "y": 70,
      "z": 8,
      "name": "Rock_Calcite"
    },
    {
      "x": -19,
      "y": 71,
      "z": 8,
      "name": "Rock_Calcite"
    },
    {
      "x": -19,
      "y": 72,
      "z": 8,
      "name": "Rock_Calcite"
    },
    {
      "x": -19,
      "y": 73,
      "z": 8,
      "name": "Rock_Calcite"
    },
    {
      "x": -19,
      "y": 74,
      "z": 8,
      "name": "Rock_Calcite"
    },
    {
      "x": -19,
      "y": 75,
      "z": 8,
      "name": "Rock_Calcite"
    },
    {
      "x": -19,
      "y": 76,
      "z": 8,
      "name": "Rock_Calcite"
    },
    {
      "x": -19,
      "y": 77,
      "z": 8,
      "name": "Rock_Calcite"
    },
    {
      "x": -19,
      "y": 78,
      "z": 8,
      "name": "Rock_Calcite"
    },
    {
      "x": -19,
      "y": 79,
      "z": 8,
      "name": "Rock_Calcite"
    },
    {
      "x": -19,
      "y": 80,
      "z": 8,
      "name": "Rock_Calcite"
    },
    {
      "x": -19,
      "y": 81,
      "z": 8,
      "name": "Rock_Calcite"
    },
    {
      "x": -19,
      "y": 82,
      "z": 8,
      "name": "Rock_Calcite"
    },
    {
      "x": -19,
      "y": 74,
      "z": 9,
      "name": "Rock_Calcite"
    },
    {
      "x": -19,
      "y": 75,
      "z": 9,
      "name": "Rock_Calcite"
    },
    {
      "x": -19,
      "y": 76,
      "z": 9,
      "name": "Rock_Calcite"
    },
    {
      "x": -19,
      "y": 77,
      "z": 9,
      "name": "Rock_Calcite"
    },
    {
      "x": -19,
      "y": 78,
      "z": 9,
      "name": "Rock_Calcite"
    },
    {
      "x": -19,
      "y": 79,
      "z": 9,
      "name": "Rock_Calcite"
    },
    {
      "x": -19,
      "y": 77,
      "z": 10,
      "name": "Rock_Calcite"
    },
    {
      "x": -19,
      "y": 78,
      "z": 10,
      "name": "Rock_Calcite"
    },
    {
      "x": -18,
      "y": 64,
      "z": -10,
      "name": "Rock_Calcite"
    },
    {
      "x": -18,
      "y": 65,
      "z": -10,
      "name": "Rock_Calcite"
    },
    {
      "x": -18,
      "y": 51,
      "z": -9,
      "name": "Rock_Calcite"
    },
    {
      "x": -18,
      "y": 54,
      "z": -9,
      "name": "Rock_Calcite"
    },
    {
      "x": -18,
      "y": 55,
      "z": -9,
      "name": "Rock_Calcite"
    },
    {
      "x": -18,
      "y": 56,
      "z": -9,
      "name": "Rock_Calcite"
    },
    {
      "x": -18,
      "y": 57,
      "z": -9,
      "name": "Rock_Calcite"
    },
    {
      "x": -18,
      "y": 58,
      "z": -9,
      "name": "Rock_Calcite"
    },
    {
      "x": -18,
      "y": 59,
      "z": -9,
      "name": "Rock_Calcite"
    },
    {
      "x": -18,
      "y": 60,
      "z": -9,
      "name": "Rock_Calcite"
    },
    {
      "x": -18,
      "y": 61,
      "z": -9,
      "name": "Rock_Calcite"
    },
    {
      "x": -18,
      "y": 62,
      "z": -9,
      "name": "Rock_Calcite"
    },
    {
      "x": -18,
      "y": 63,
      "z": -9,
      "name": "Rock_Calcite"
    },
    {
      "x": -18,
      "y": 64,
      "z": -9,
      "name": "Rock_Calcite"
    },
    {
      "x": -18,
      "y": 65,
      "z": -9,
      "name": "Rock_Calcite"
    },
    {
      "x": -18,
      "y": 66,
      "z": -9,
      "name": "Rock_Calcite"
    },
    {
      "x": -18,
      "y": 50,
      "z": -8,
      "name": "Rock_Calcite"
    },
    {
      "x": -18,
      "y": 51,
      "z": -8,
      "name": "Rock_Calcite"
    },
    {
      "x": -18,
      "y": 52,
      "z": -8,
      "name": "Rock_Calcite"
    },
    {
      "x": -18,
      "y": 53,
      "z": -8,
      "name": "Rock_Calcite"
    },
    {
      "x": -18,
      "y": 54,
      "z": -8,
      "name": "Rock_Calcite"
    },
    {
      "x": -18,
      "y": 55,
      "z": -8,
      "name": "Rock_Calcite"
    },
    {
      "x": -18,
      "y": 56,
      "z": -8,
      "name": "Rock_Calcite"
    },
    {
      "x": -18,
      "y": 57,
      "z": -8,
      "name": "Rock_Calcite"
    },
    {
      "x": -18,
      "y": 58,
      "z": -8,
      "name": "Rock_Calcite"
    },
    {
      "x": -18,
      "y": 59,
      "z": -8,
      "name": "Rock_Calcite"
    },
    {
      "x": -18,
      "y": 60,
      "z": -8,
      "name": "Rock_Calcite"
    },
    {
      "x": -18,
      "y": 61,
      "z": -8,
      "name": "Rock_Calcite"
    },
    {
      "x": -18,
      "y": 62,
      "z": -8,
      "name": "Rock_Calcite"
    },
    {
      "x": -18,
      "y": 63,
      "z": -8,
      "name": "Rock_Calcite"
    },
    {
      "x": -18,
      "y": 64,
      "z": -8,
      "name": "Rock_Calcite"
    },
    {
      "x": -18,
      "y": 65,
      "z": -8,
      "name": "Rock_Calcite"
    },
    {
      "x": -18,
      "y": 66,
      "z": -8,
      "name": "Rock_Calcite"
    },
    {
      "x": -18,
      "y": 67,
      "z": -8,
      "name": "Rock_Calcite"
    },
    {
      "x": -18,
      "y": 68,
      "z": -8,
      "name": "Rock_Calcite"
    },
    {
      "x": -18,
      "y": 69,
      "z": -8,
      "name": "Rock_Calcite"
    },
    {
      "x": -18,
      "y": 74,
      "z": -8,
      "name": "Rock_Calcite"
    },
    {
      "x": -18,
      "y": 75,
      "z": -8,
      "name": "Rock_Calcite"
    },
    {
      "x": -18,
      "y": 76,
      "z": -8,
      "name": "Rock_Calcite"
    },
    {
      "x": -18,
      "y": 77,
      "z": -8,
      "name": "Rock_Calcite"
    },
    {
      "x": -18,
      "y": 78,
      "z": -8,
      "name": "Rock_Calcite"
    },
    {
      "x": -18,
      "y": 49,
      "z": -7,
      "name": "Rock_Calcite"
    },
    {
      "x": -18,
      "y": 50,
      "z": -7,
      "name": "Rock_Calcite"
    },
    {
      "x": -18,
      "y": 51,
      "z": -7,
      "name": "Rock_Calcite"
    },
    {
      "x": -18,
      "y": 52,
      "z": -7,
      "name": "Rock_Calcite"
    },
    {
      "x": -18,
      "y": 53,
      "z": -7,
      "name": "Rock_Calcite"
    },
    {
      "x": -18,
      "y": 54,
      "z": -7,
      "name": "Rock_Calcite"
    },
    {
      "x": -18,
      "y": 55,
      "z": -7,
      "name": "Rock_Calcite"
    },
    {
      "x": -18,
      "y": 56,
      "z": -7,
      "name": "Rock_Calcite"
    },
    {
      "x": -18,
      "y": 57,
      "z": -7,
      "name": "Rock_Calcite"
    },
    {
      "x": -18,
      "y": 58,
      "z": -7,
      "name": "Rock_Calcite"
    },
    {
      "x": -18,
      "y": 59,
      "z": -7,
      "name": "Rock_Calcite"
    },
    {
      "x": -18,
      "y": 60,
      "z": -7,
      "name": "Rock_Calcite"
    },
    {
      "x": -18,
      "y": 61,
      "z": -7,
      "name": "Rock_Calcite"
    },
    {
      "x": -18,
      "y": 62,
      "z": -7,
      "name": "Rock_Calcite"
    },
    {
      "x": -18,
      "y": 63,
      "z": -7,
      "name": "Rock_Calcite"
    },
    {
      "x": -18,
      "y": 64,
      "z": -7,
      "name": "Rock_Calcite"
    },
    {
      "x": -18,
      "y": 65,
      "z": -7,
      "name": "Rock_Calcite"
    },
    {
      "x": -18,
      "y": 66,
      "z": -7,
      "name": "Rock_Calcite"
    },
    {
      "x": -18,
      "y": 67,
      "z": -7,
      "name": "Rock_Calcite"
    },
    {
      "x": -18,
      "y": 68,
      "z": -7,
      "name": "Rock_Calcite"
    },
    {
      "x": -18,
      "y": 69,
      "z": -7,
      "name": "Rock_Calcite"
    },
    {
      "x": -18,
      "y": 70,
      "z": -7,
      "name": "Rock_Calcite"
    },
    {
      "x": -18,
      "y": 71,
      "z": -7,
      "name": "Rock_Calcite"
    },
    {
      "x": -18,
      "y": 72,
      "z": -7,
      "name": "Rock_Calcite"
    },
    {
      "x": -18,
      "y": 73,
      "z": -7,
      "name": "Rock_Calcite"
    },
    {
      "x": -18,
      "y": 74,
      "z": -7,
      "name": "Rock_Calcite"
    },
    {
      "x": -18,
      "y": 75,
      "z": -7,
      "name": "Rock_Calcite"
    },
    {
      "x": -18,
      "y": 76,
      "z": -7,
      "name": "Rock_Calcite"
    },
    {
      "x": -18,
      "y": 77,
      "z": -7,
      "name": "Rock_Calcite"
    },
    {
      "x": -18,
      "y": 78,
      "z": -7,
      "name": "Rock_Calcite"
    },
    {
      "x": -18,
      "y": 79,
      "z": -7,
      "name": "Rock_Calcite"
    },
    {
      "x": -18,
      "y": 80,
      "z": -7,
      "name": "Rock_Calcite"
    },
    {
      "x": -18,
      "y": 49,
      "z": -6,
      "name": "Rock_Calcite"
    },
    {
      "x": -18,
      "y": 50,
      "z": -6,
      "name": "Rock_Calcite"
    },
    {
      "x": -18,
      "y": 51,
      "z": -6,
      "name": "Rock_Calcite"
    },
    {
      "x": -18,
      "y": 52,
      "z": -6,
      "name": "Rock_Calcite"
    },
    {
      "x": -18,
      "y": 53,
      "z": -6,
      "name": "Rock_Calcite"
    },
    {
      "x": -18,
      "y": 54,
      "z": -6,
      "name": "Rock_Calcite"
    },
    {
      "x": -18,
      "y": 55,
      "z": -6,
      "name": "Rock_Calcite"
    },
    {
      "x": -18,
      "y": 56,
      "z": -6,
      "name": "Rock_Calcite"
    },
    {
      "x": -18,
      "y": 57,
      "z": -6,
      "name": "Rock_Calcite"
    },
    {
      "x": -18,
      "y": 58,
      "z": -6,
      "name": "Rock_Calcite"
    },
    {
      "x": -18,
      "y": 59,
      "z": -6,
      "name": "Rock_Calcite"
    },
    {
      "x": -18,
      "y": 60,
      "z": -6,
      "name": "Rock_Calcite"
    },
    {
      "x": -18,
      "y": 61,
      "z": -6,
      "name": "Rock_Calcite"
    },
    {
      "x": -18,
      "y": 62,
      "z": -6,
      "name": "Rock_Calcite"
    },
    {
      "x": -18,
      "y": 63,
      "z": -6,
      "name": "Rock_Calcite"
    },
    {
      "x": -18,
      "y": 64,
      "z": -6,
      "name": "Rock_Calcite"
    },
    {
      "x": -18,
      "y": 65,
      "z": -6,
      "name": "Rock_Calcite"
    },
    {
      "x": -18,
      "y": 66,
      "z": -6,
      "name": "Rock_Calcite"
    },
    {
      "x": -18,
      "y": 67,
      "z": -6,
      "name": "Rock_Calcite"
    },
    {
      "x": -18,
      "y": 68,
      "z": -6,
      "name": "Rock_Calcite"
    },
    {
      "x": -18,
      "y": 69,
      "z": -6,
      "name": "Rock_Calcite"
    },
    {
      "x": -18,
      "y": 70,
      "z": -6,
      "name": "Rock_Calcite"
    },
    {
      "x": -18,
      "y": 71,
      "z": -6,
      "name": "Rock_Calcite"
    },
    {
      "x": -18,
      "y": 72,
      "z": -6,
      "name": "Rock_Calcite"
    },
    {
      "x": -18,
      "y": 73,
      "z": -6,
      "name": "Rock_Calcite"
    },
    {
      "x": -18,
      "y": 74,
      "z": -6,
      "name": "Rock_Calcite"
    },
    {
      "x": -18,
      "y": 75,
      "z": -6,
      "name": "Rock_Calcite"
    },
    {
      "x": -18,
      "y": 76,
      "z": -6,
      "name": "Rock_Calcite"
    },
    {
      "x": -18,
      "y": 77,
      "z": -6,
      "name": "Rock_Calcite"
    },
    {
      "x": -18,
      "y": 78,
      "z": -6,
      "name": "Rock_Calcite"
    },
    {
      "x": -18,
      "y": 79,
      "z": -6,
      "name": "Rock_Calcite"
    },
    {
      "x": -18,
      "y": 80,
      "z": -6,
      "name": "Rock_Calcite"
    },
    {
      "x": -18,
      "y": 81,
      "z": -6,
      "name": "Rock_Calcite"
    },
    {
      "x": -18,
      "y": 50,
      "z": -5,
      "name": "Rock_Calcite"
    },
    {
      "x": -18,
      "y": 51,
      "z": -5,
      "name": "Rock_Calcite"
    },
    {
      "x": -18,
      "y": 52,
      "z": -5,
      "name": "Rock_Calcite"
    },
    {
      "x": -18,
      "y": 53,
      "z": -5,
      "name": "Rock_Calcite"
    },
    {
      "x": -18,
      "y": 54,
      "z": -5,
      "name": "Rock_Calcite"
    },
    {
      "x": -18,
      "y": 55,
      "z": -5,
      "name": "Rock_Calcite"
    },
    {
      "x": -18,
      "y": 56,
      "z": -5,
      "name": "Rock_Calcite"
    },
    {
      "x": -18,
      "y": 57,
      "z": -5,
      "name": "Rock_Calcite"
    },
    {
      "x": -18,
      "y": 58,
      "z": -5,
      "name": "Rock_Calcite"
    },
    {
      "x": -18,
      "y": 59,
      "z": -5,
      "name": "Rock_Calcite"
    },
    {
      "x": -18,
      "y": 60,
      "z": -5,
      "name": "Rock_Calcite"
    },
    {
      "x": -18,
      "y": 61,
      "z": -5,
      "name": "Rock_Calcite"
    },
    {
      "x": -18,
      "y": 62,
      "z": -5,
      "name": "Rock_Calcite"
    },
    {
      "x": -18,
      "y": 63,
      "z": -5,
      "name": "Rock_Calcite"
    },
    {
      "x": -18,
      "y": 64,
      "z": -5,
      "name": "Rock_Calcite"
    },
    {
      "x": -18,
      "y": 65,
      "z": -5,
      "name": "Rock_Calcite"
    },
    {
      "x": -18,
      "y": 66,
      "z": -5,
      "name": "Rock_Calcite"
    },
    {
      "x": -18,
      "y": 67,
      "z": -5,
      "name": "Rock_Calcite"
    },
    {
      "x": -18,
      "y": 68,
      "z": -5,
      "name": "Rock_Calcite"
    },
    {
      "x": -18,
      "y": 69,
      "z": -5,
      "name": "Rock_Calcite"
    },
    {
      "x": -18,
      "y": 70,
      "z": -5,
      "name": "Rock_Calcite"
    },
    {
      "x": -18,
      "y": 71,
      "z": -5,
      "name": "Rock_Calcite"
    },
    {
      "x": -18,
      "y": 72,
      "z": -5,
      "name": "Rock_Calcite"
    },
    {
      "x": -18,
      "y": 73,
      "z": -5,
      "name": "Rock_Calcite"
    },
    {
      "x": -18,
      "y": 74,
      "z": -5,
      "name": "Rock_Calcite"
    },
    {
      "x": -18,
      "y": 75,
      "z": -5,
      "name": "Rock_Calcite"
    },
    {
      "x": -18,
      "y": 76,
      "z": -5,
      "name": "Rock_Calcite"
    },
    {
      "x": -18,
      "y": 77,
      "z": -5,
      "name": "Rock_Calcite"
    },
    {
      "x": -18,
      "y": 78,
      "z": -5,
      "name": "Rock_Calcite"
    },
    {
      "x": -18,
      "y": 79,
      "z": -5,
      "name": "Rock_Calcite"
    },
    {
      "x": -18,
      "y": 80,
      "z": -5,
      "name": "Rock_Calcite"
    },
    {
      "x": -18,
      "y": 52,
      "z": -4,
      "name": "Rock_Calcite"
