{
  "version": 8,
  "blockIdVersion": 11,
  "anchorX": 0,
  "anchorY": 0,
  "anchorZ": 0,
  "blocks": [
    {
      "x": -7,
      "y": -22,
      "z": -1,
      "name": "Plant_Leaves_Oak",
      "support": 15
    },
    {
      "x": -7,
      "y": -23,
      "z": 0,
      "name": "Plant_Leaves_Oak",
      "support": 15
    },
    {
      "x": -7,
      "y": -22,
      "z": 0,
      "name": "Plant_Leaves_Oak",
      "support": 15
    },
    {
      "x": -7,
      "y": -23,
      "z": 1,
      "name": "Plant_Leaves_Oak",
      "support": 15
    },
    {
      "x": -7,
      "y": -22,
      "z": 1,
      "name": "Plant_Leaves_Oak",
      "support": 15
    },
    {
      "x": -6,
      "y": -22,
      "z": -3,
      "name": "Plant_Leaves_Oak",
      "support": 15
    },
    {
      "x": -6,
      "y": -22,
      "z": -2,
      "name": "Plant_Leaves_Oak",
      "support": 15
    },
    {
      "x": -6,
      "y": -23,
      "z": -1,
      "name": "Plant_Leaves_Oak",
      "support": 15
    },
    {
      "x": -6,
      "y": -22,
      "z": -1,
      "name": "Plant_Leaves_Oak",
      "support": 15
    },
    {
      "x": -6,
      "y": -23,
      "z": 0,
      "name": "Plant_Leaves_Oak",
      "support": 15
    },
    {
      "x": -6,
      "y": -22,
      "z": 0,
      "name": "Wood_Oak_Branch_Corner",
      "support": 15,
      "rotation": 3
    },
    {
      "x": -6,
      "y": -23,
      "z": 1,
      "name": "Plant_Leaves_Oak",
      "support": 15
    },
    {
      "x": -6,
      "y": -22,
      "z": 1,
      "name": "Plant_Leaves_Oak",
      "support": 15
    },
    {
      "x": -5,
      "y": -23,
      "z": -2,
      "name": "Plant_Leaves_Oak",
      "support": 15
    },
    {
      "x": -5,
      "y": -22,
      "z": -2,
      "name": "Plant_Leaves_Oak",
      "support": 15
    },
    {
      "x": -5,
      "y": -24,
      "z": -1,
      "name": "Plant_Leaves_Oak",
      "support": 15
    },
    {
      "x": -5,
      "y": -23,
      "z": -1,
      "name": "Plant_Leaves_Oak",
      "support": 15
    },
    {
      "x": -5,
      "y": -22,
      "z": -1,
      "name": "Plant_Leaves_Oak",
      "support": 15
    },
    {
      "x": -5,
      "y": -23,
      "z": 0,
      "name": "Plant_Leaves_Oak",
      "support": 15
    },
    {
      "x": -5,
      "y": -22,
      "z": 0,
      "name": "Wood_Oak_Branch_Long",
      "support": 15,
      "rotation": 5
    },
    {
      "x": -5,
      "y": -23,
      "z": 1,
      "name": "Plant_Leaves_Oak",
      "support": 2
    },
    {
      "x": -5,
      "y": -23,
      "z": 2,
      "name": "Plant_Leaves_Oak",
      "support": 15
    },
    {
      "x": -5,
      "y": -23,
      "z": 3,
      "name": "Plant_Leaves_Oak",
      "support": 15
    },
    {
      "x": -4,
      "y": -23,
      "z": -3,
      "name": "Plant_Leaves_Oak",
      "support": 15
    },
    {
      "x": -4,
      "y": -23,
      "z": -2,
      "name": "Plant_Leaves_Oak",
      "support": 15
    },
    {
      "x": -4,
      "y": -24,
      "z": -1,
      "name": "Plant_Leaves_Oak",
      "support": 15
    },
    {
      "x": -4,
      "y": -23,
      "z": -1,
      "name": "Plant_Leaves_Oak",
      "support": 15
    },
    {
      "x": -4,
      "y": -22,
      "z": -1,
      "name": "Plant_Leaves_Oak",
      "support": 15
    },
    {
      "x": -4,
      "y": -24,
      "z": 0,
      "name": "Plant_Leaves_Oak",
      "support": 15
    },
    {
      "x": -4,
      "y": -23,
      "z": 0,
      "name": "Plant_Leaves_Oak"
    },
    {
      "x": -4,
      "y": -22,
      "z": 0,
      "name": "Wood_Oak_Branch_Long",
      "support": 15,
      "rotation": 5
    },
    {
      "x": -4,
      "y": -24,
      "z": 1,
      "name": "Plant_Leaves_Oak",
      "support": 2
    },
    {
      "x": -4,
      "y": -23,
      "z": 1,
      "name": "Plant_Leaves_Oak",
      "support": 1
    },
    {
      "x": -4,
      "y": -23,
      "z": 2,
      "name": "Plant_Leaves_Oak",
      "support": 2
    },
    {
      "x": -4,
      "y": -22,
      "z": 2,
      "name": "Plant_Leaves_Oak",
      "support": 15
    },
    {
      "x": -4,
      "y": -23,
      "z": 3,
      "name": "Plant_Leaves_Oak",
      "support": 15
    },
    {
      "x": -4,
      "y": -22,
      "z": 3,
      "name": "Plant_Leaves_Oak",
      "support": 15
    },
    {
      "x": -4,
      "y": -23,
      "z": 4,
      "name": "Plant_Leaves_Oak",
      "support": 15
    },
    {
      "x": -3,
      "y": -23,
      "z": -5,
      "name": "Plant_Leaves_Oak",
      "support": 15
    },
    {
      "x": -3,
      "y": -23,
      "z": -4,
      "name": "Plant_Leaves_Oak",
      "support": 15
    },
    {
      "x": -3,
      "y": -22,
      "z": -4,
      "name": "Plant_Leaves_Oak",
      "support": 15
    },
    {
      "x": -3,
      "y": -23,
      "z": -3,
      "name": "Plant_Leaves_Oak",
      "support": 15
    },
    {
      "x": -3,
      "y": -23,
      "z": -2,
      "name": "Plant_Leaves_Oak",
      "support": 15
    },
    {
      "x": -3,
      "y": -24,
      "z": -1,
      "name": "Plant_Leaves_Oak",
      "support": 15
    },
    {
      "x": -3,
      "y": -23,
      "z": -1,
      "name": "Plant_Leaves_Oak"
    },
    {
      "x": -3,
      "y": -22,
      "z": -1,
      "name": "Wood_Oak_Branch_Corner",
      "support": 15,
      "rotation": 3
    },
    {
      "x": -3,
      "y": -24,
      "z": 0,
      "name": "Plant_Leaves_Oak",
      "support": 2
    },
    {
      "x": -3,
      "y": -23,
      "z": 0,
      "name": "Plant_Leaves_Oak"
    },
    {
      "x": -3,
      "y": -22,
      "z": 0,
      "name": "Wood_Oak_Trunk",
      "support": 15,
      "rotation": 5
    },
    {
      "x": -3,
      "y": -20,
      "z": 0,
      "name": "Plant_Leaves_Oak",
      "support": 15
    },
    {
      "x": -3,
      "y": -17,
      "z": 0,
      "name": "Plant_Leaves_Oak"
    },
    {
      "x": -3,
      "y": -16,
      "z": 0,
      "name": "Plant_Leaves_Oak",
      "support": 1
    },
    {
      "x": -3,
      "y": -15,
      "z": 0,
      "name": "Plant_Leaves_Oak",
      "support": 2
    },
    {
      "x": -3,
      "y": -24,
      "z": 1,
      "name": "Plant_Leaves_Oak",
      "support": 1
    },
    {
      "x": -3,
      "y": -23,
      "z": 1,
      "name": "Plant_Leaves_Oak"
    },
    {
      "x": -3,
      "y": -22,
      "z": 1,
      "name": "Wood_Oak_Branch_Long",
      "support": 15,
      "rotation": 4
    },
    {
      "x": -3,
      "y": -24,
      "z": 2,
      "name": "Plant_Leaves_Oak",
      "support": 2
    },
    {
      "x": -3,
      "y": -23,
      "z": 2,
      "name": "Plant_Leaves_Oak",
      "support": 15
    },
    {
      "x": -3,
      "y": -22,
      "z": 2,
      "name": "Wood_Oak_Branch_Corner",
      "support": 15
    },
    {
      "x": -3,
      "y": -21,
      "z": 2,
      "name": "Plant_Leaves_Oak",
      "support": 15
    },
    {
      "x": -3,
      "y": -23,
      "z": 3,
      "name": "Plant_Leaves_Oak",
      "support": 15
    },
    {
      "x": -3,
      "y": -22,
      "z": 3,
      "name": "Plant_Leaves_Oak",
      "support": 15
    },
    {
      "x": -3,
      "y": -23,
      "z": 4,
      "name": "Plant_Leaves_Oak",
      "support": 15
    },
    {
      "x": -3,
      "y": -22,
      "z": 4,
      "name": "Plant_Leaves_Oak",
      "support": 15
    },
    {
      "x": -3,
      "y": -23,
      "z": 5,
      "name": "Plant_Leaves_Oak",
      "support": 15
    },
    {
      "x": -2,
      "y": -23,
      "z": -6,
      "name": "Plant_Leaves_Oak",
      "support": 15
    },
    {
      "x": -2,
      "y": -23,
      "z": -5,
      "name": "Plant_Leaves_Oak",
      "support": 15
    },
    {
      "x": -2,
      "y": -23,
      "z": -4,
      "name": "Plant_Leaves_Oak",
      "support": 15
    },
    {
      "x": -2,
      "y": -22,
      "z": -4,
      "name": "Plant_Leaves_Oak",
      "support": 15
    },
    {
      "x": -2,
      "y": -23,
      "z": -3,
      "name": "Plant_Leaves_Oak",
      "support": 15
    },
    {
      "x": -2,
      "y": -22,
      "z": -3,
      "name": "Wood_Oak_Branch_Corner",
      "support": 15,
      "rotation": 3
    },
    {
      "x": -2,
      "y": -23,
      "z": -2,
      "name": "Plant_Leaves_Oak",
      "support": 2
    },
    {
      "x": -2,
      "y": -22,
      "z": -2,
      "name": "Plant_Leaves_Oak",
      "support": 15
    },
    {
      "x": -2,
      "y": -24,
      "z": -1,
      "name": "Plant_Leaves_Oak",
      "support": 2
    },
    {
      "x": -2,
      "y": -23,
      "z": -1,
      "name": "Plant_Leaves_Oak"
    },
    {
      "x": -2,
      "y": -22,
      "z": -1,
      "name": "Wood_Oak_Branch_Long",
      "support": 15,
      "rotation": 5
    },
    {
      "x": -2,
      "y": -17,
      "z": -1,
      "name": "Plant_Leaves_Oak"
    },
    {
      "x": -2,
      "y": -16,
      "z": -1,
      "name": "Plant_Leaves_Oak",
      "support": 1
    },
    {
      "x": -2,
      "y": -24,
      "z": 0,
      "name": "Plant_Leaves_Oak",
      "support": 1
    },
    {
      "x": -2,
      "y": -23,
      "z": 0,
      "name": "Plant_Leaves_Oak"
    },
    {
      "x": -2,
      "y": -22,
      "z": 0,
      "name": "Wood_Oak_Branch_Long",
      "support": 15,
      "rotation": 5
    },
    {
      "x": -2,
      "y": -20,
      "z": 0,
      "name": "Wood_Oak_Branch_Long",
      "support": 15,
      "rotation": 5
    },
    {
      "x": -2,
      "y": -17,
      "z": 0,
      "name": "Wood_Oak_Branch_Long",
      "rotation": 5
    },
    {
      "x": -2,
      "y": -16,
      "z": 0,
      "name": "Plant_Leaves_Oak"
    },
    {
      "x": -2,
      "y": -11,
      "z": 0,
      "name": "Wood_Oak_Branch_Short",
      "rotation": 3
    },
    {
      "x": -2,
      "y": -24,
      "z": 1,
      "name": "Plant_Leaves_Oak",
      "support": 2
    },
    {
      "x": -2,
      "y": -23,
      "z": 1,
      "name": "Plant_Leaves_Oak",
      "support": 15
    },
    {
      "x": -2,
      "y": -17,
      "z": 1,
      "name": "Plant_Leaves_Oak"
    },
    {
      "x": -2,
      "y": -24,
      "z": 2,
      "name": "Plant_Leaves_Oak",
      "support": 2
    },
    {
      "x": -2,
      "y": -23,
      "z": 2,
      "name": "Plant_Leaves_Oak",
      "support": 15
    },
    {
      "x": -2,
      "y": -24,
      "z": 3,
      "name": "Plant_Leaves_Oak",
      "support": 15
    },
    {
      "x": -2,
      "y": -23,
      "z": 3,
      "name": "Plant_Leaves_Oak",
      "support": 15
    },
    {
      "x": -2,
      "y": -22,
      "z": 3,
      "name": "Wood_Oak_Branch_Corner",
      "support": 15,
      "rotation": 3
    },
    {
      "x": -2,
      "y": -21,
      "z": 3,
      "name": "Plant_Leaves_Oak",
      "support": 15
    },
    {
      "x": -2,
      "y": -20,
      "z": 3,
      "name": "Plant_Leaves_Oak",
      "support": 15
    },
    {
      "x": -2,
      "y": -23,
      "z": 4,
      "name": "Plant_Leaves_Oak",
      "support": 15
    },
    {
      "x": -2,
      "y": -22,
      "z": 4,
      "name": "Plant_Leaves_Oak",
      "support": 15
    },
    {
      "x": -2,
      "y": -23,
      "z": 5,
      "name": "Plant_Leaves_Oak",
      "support": 15
    },
    {
      "x": -2,
      "y": -23,
      "z": 6,
      "name": "Plant_Leaves_Oak",
      "support": 15
    },
    {
      "x": -2,
      "y": -23,
      "z": 7,
      "name": "Plant_Leaves_Oak",
      "support": 15
    },
    {
      "x": -1,
      "y": -23,
      "z": -7,
      "name": "Plant_Leaves_Oak",
      "support": 15
    },
    {
      "x": -1,
      "y": -23,
      "z": -6,
      "name": "Plant_Leaves_Oak",
      "support": 15
    },
    {
      "x": -1,
      "y": -22,
      "z": -6,
      "name": "Plant_Leaves_Oak",
      "support": 15
    },
    {
      "x": -1,
      "y": -23,
      "z": -5,
      "name": "Plant_Leaves_Oak",
      "support": 15
    },
    {
      "x": -1,
      "y": -22,
      "z": -5,
      "name": "Plant_Leaves_Oak",
      "support": 15
    },
    {
      "x": -1,
      "y": -20,
      "z": -5,
      "name": "Plant_Leaves_Oak",
      "support": 15
    },
    {
      "x": -1,
      "y": -24,
      "z": -4,
      "name": "Plant_Leaves_Oak",
      "support": 15
    },
    {
      "x": -1,
      "y": -23,
      "z": -4,
      "name": "Plant_Leaves_Oak",
      "support": 15
    },
    {
      "x": -1,
      "y": -22,
      "z": -4,
      "name": "Plant_Leaves_Oak",
      "support": 15
    },
    {
      "x": -1,
      "y": -20,
      "z": -4,
      "name": "Plant_Leaves_Oak",
      "support": 15
    },
    {
      "x": -1,
      "y": -24,
      "z": -3,
      "name": "Plant_Leaves_Oak",
      "support": 15
    },
    {
      "x": -1,
      "y": -23,
      "z": -3,
      "name": "Plant_Leaves_Oak"
    },
    {
      "x": -1,
      "y": -22,
      "z": -3,
      "name": "Wood_Oak_Branch_Long",
      "support": 15,
      "rotation": 5
    },
    {
      "x": -1,
      "y": -21,
      "z": -3,
      "name": "Plant_Leaves_Oak",
      "support": 15
    },
    {
      "x": -1,
      "y": -24,
      "z": -2,
      "name": "Plant_Leaves_Oak",
      "support": 2
    },
    {
      "x": -1,
      "y": -23,
      "z": -2,
      "name": "Plant_Leaves_Oak",
      "support": 1
    },
    {
      "x": -1,
      "y": -23,
      "z": -1,
      "name": "Plant_Leaves_Oak"
    },
    {
      "x": -1,
      "y": -22,
      "z": -1,
      "name": "Wood_Oak_Branch_Corner",
      "support": 15,
      "rotation": 1
    },
    {
      "x": -1,
      "y": -21,
      "z": -1,
      "name": "Wood_Oak_Branch_Long",
      "support": 15
    },
    {
      "x": -1,
      "y": -20,
      "z": -1,
      "name": "Wood_Oak_Branch_Long",
      "support": 15
    },
    {
      "x": -1,
      "y": -19,
      "z": -1,
      "name": "Wood_Oak_Branch_Corner",
      "support": 15,
      "rotation": 9
    },
    {
      "x": -1,
      "y": -17,
      "z": -1,
      "name": "Wood_Oak_Branch_Short",
      "rotation": 2
    },
    {
      "x": -1,
      "y": -5,
      "z": -1,
      "name": "Wood_Oak_Branch_Short",
      "rotation": 3
    },
    {
      "x": -1,
      "y": -24,
      "z": 0,
      "name": "Plant_Leaves_Oak",
      "support": 2
    },
    {
      "x": -1,
      "y": -23,
      "z": 0,
      "name": "Plant_Leaves_Oak",
      "support": 15
    },
    {
      "x": -1,
      "y": -22,
      "z": 0,
      "name": "Wood_Oak_Branch_Long",
      "support": 15,
      "rotation": 5
    },
    {
      "x": -1,
      "y": -20,
      "z": 0,
      "name": "Wood_Oak_Branch_Corner",
      "support": 15,
      "rotation": 1
    },
    {
      "x": -1,
      "y": -19,
      "z": 0,
      "name": "Wood_Oak_Branch_Long",
      "support": 2
    },
    {
      "x": -1,
      "y": -18,
      "z": 0,
      "name": "Wood_Oak_Branch_Long"
    },
    {
      "x": -1,
      "y": -17,
      "z": 0,
      "name": "Wood_Oak_Trunk"
    },
    {
      "x": -1,
      "y": -16,
      "z": 0,
      "name": "Wood_Oak_Trunk"
    },
    {
      "x": -1,
      "y": -15,
      "z": 0,
      "name": "Wood_Oak_Trunk"
    },
    {
      "x": -1,
      "y": -14,
      "z": 0,
      "name": "Wood_Oak_Trunk"
    },
    {
      "x": -1,
      "y": -13,
      "z": 0,
      "name": "Wood_Oak_Trunk"
    },
    {
      "x": -1,
      "y": -12,
      "z": 0,
      "name": "Wood_Oak_Trunk"
    },
    {
      "x": -1,
      "y": -11,
      "z": 0,
      "name": "Wood_Oak_Trunk"
    },
    {
      "x": -1,
      "y": -10,
      "z": 0,
      "name": "Wood_Oak_Trunk"
    },
    {
      "x": -1,
      "y": -9,
      "z": 0,
      "name": "Wood_Oak_Trunk"
    },
    {
      "x": -1,
      "y": -8,
      "z": 0,
      "name": "Wood_Oak_Trunk"
    },
    {
      "x": -1,
      "y": -7,
      "z": 0,
      "name": "Wood_Oak_Trunk"
    },
    {
      "x": -1,
      "y": -6,
      "z": 0,
      "name": "Wood_Oak_Trunk",
      "support": 1
    },
    {
      "x": -1,
      "y": -5,
      "z": 0,
      "name": "Wood_Oak_Trunk"
    },
    {
      "x": -1,
      "y": -4,
      "z": 0,
      "name": "Wood_Oak_Trunk"
    },
    {
      "x": -1,
      "y": -3,
      "z": 0,
      "name": "Wood_Oak_Branch_Long"
    },
    {
      "x": -1,
      "y": -2,
      "z": 0,
      "name": "Wood_Oak_Branch_Long"
    },
    {
      "x": -1,
      "y": -1,
      "z": 0,
      "name": "Wood_Oak_Trunk",
      "support": 1
    },
    {
      "x": -1,
      "y": 0,
      "z": 0,
      "name": "Wood_Oak_Trunk"
    },
    {
      "x": -1,
      "y": 1,
      "z": 0,
      "name": "Wood_Oak_Trunk"
    },
    {
      "x": -1,
      "y": 2,
      "z": 0,
      "name": "Wood_Oak_Trunk"
    },
    {
      "x": -1,
      "y": -24,
      "z": 1,
      "name": "Plant_Leaves_Oak",
      "support": 2
    },
    {
      "x": -1,
      "y": -23,
      "z": 1,
      "name": "Plant_Leaves_Oak",
      "support": 15
    },
    {
      "x": -1,
      "y": -17,
      "z": 1,
      "name": "Wood_Oak_Branch_Short",
      "rotation": 3
    },
    {
      "x": -1,
      "y": -16,
      "z": 1,
      "name": "Wood_Oak_Branch_Long",
      "rotation": 4
    },
    {
      "x": -1,
      "y": -24,
      "z": 2,
      "name": "Plant_Leaves_Oak",
      "support": 2
    },
    {
      "x": -1,
      "y": -23,
      "z": 2,
      "name": "Plant_Leaves_Oak",
      "support": 15
    },
    {
      "x": -1,
      "y": -16,
      "z": 2,
      "name": "Plant_Leaves_Oak"
    },
    {
      "x": -1,
      "y": -15,
      "z": 2,
      "name": "Plant_Leaves_Oak",
      "support": 1
    },
    {
      "x": -1,
      "y": -24,
      "z": 3,
      "name": "Plant_Leaves_Oak",
      "support": 15
    },
    {
      "x": -1,
      "y": -23,
      "z": 3,
      "name": "Plant_Leaves_Oak",
      "support": 15
    },
    {
      "x": -1,
      "y": -22,
      "z": 3,
      "name": "Wood_Oak_Branch_Long",
      "support": 15,
      "rotation": 5
    },
    {
      "x": -1,
      "y": -24,
      "z": 4,
      "name": "Plant_Leaves_Oak"
    },
    {
      "x": -1,
      "y": -23,
      "z": 4,
      "name": "Plant_Leaves_Oak",
      "support": 15
    },
    {
      "x": -1,
      "y": -23,
      "z": 5,
      "name": "Plant_Leaves_Oak",
      "support": 15
    },
    {
      "x": -1,
      "y": -23,
      "z": 6,
      "name": "Plant_Leaves_Oak",
      "support": 15
    },
    {
      "x": -1,
      "y": -22,
      "z": 6,
      "name": "Plant_Leaves_Oak",
      "support": 15
    },
    {
      "x": -1,
      "y": -23,
      "z": 7,
      "name": "Plant_Leaves_Oak",
      "support": 15
    },
    {
      "x": 0,
      "y": -23,
      "z": -7,
      "name": "Plant_Leaves_Oak",
      "support": 15
    },
    {
      "x": 0,
      "y": -22,
      "z": -7,
      "name": "Plant_Leaves_Oak",
      "support": 15
    },
    {
      "x": 0,
      "y": -23,
      "z": -6,
      "name": "Plant_Leaves_Oak",
      "support": 15
    },
    {
      "x": 0,
      "y": -22,
      "z": -6,
      "name": "Plant_Leaves_Oak",
      "support": 15
    },
    {
      "x": 0,
      "y": -23,
      "z": -5,
      "name": "Plant_Leaves_Oak",
      "support": 15
    },
    {
      "x": 0,
      "y": -22,
      "z": -5,
      "name": "Wood_Oak_Branch_Corner",
      "support": 15,
      "rotation": 2
    },
    {
      "x": 0,
      "y": -21,
      "z": -5,
      "name": "Plant_Leaves_Oak",
      "support": 15
    },
    {
      "x": 0,
      "y": -24,
      "z": -4,
      "name": "Plant_Leaves_Oak",
      "support": 15
    },
    {
      "x": 0,
      "y": -23,
      "z": -4,
      "name": "Plant_Leaves_Oak",
      "support": 15
    },
    {
      "x": 0,
      "y": -22,
      "z": -4,
      "name": "Wood_Oak_Branch_Long",
      "support": 15,
      "rotation": 4
    },
    {
      "x": 0,
      "y": -21,
      "z": -4,
      "name": "Wood_Oak_Branch_Corner",
      "support": 15,
      "rotation": 2
    },
    {
      "x": 0,
      "y": -20,
      "z": -4,
      "name": "Plant_Leaves_Oak",
      "support": 15
    },
    {
      "x": 0,
      "y": -19,
      "z": -4,
      "name": "Plant_Leaves_Oak",
      "support": 15
    },
    {
      "x": 0,
      "y": -24,
      "z": -3,
      "name": "Plant_Leaves_Oak",
      "support": 15
    },
    {
      "x": 0,
      "y": -23,
      "z": -3,
      "name": "Plant_Leaves_Oak",
      "support": 15
    },
    {
      "x": 0,
      "y": -22,
      "z": -3,
      "name": "Wood_Oak_Trunk",
      "support": 15,
      "rotation": 4
    },
    {
      "x": 0,
      "y": -21,
      "z": -3,
      "name": "Wood_Oak_Branch_Long",
      "support": 15,
      "rotation": 4
    },
    {
      "x": 0,
      "y": -20,
      "z": -3,
      "name": "Plant_Leaves_Oak",
      "support": 15
    },
    {
      "x": 0,
      "y": -24,
      "z": -2,
      "name": "Plant_Leaves_Oak",
      "support": 2
    },
    {
      "x": 0,
      "y": -23,
      "z": -2,
      "name": "Plant_Leaves_Oak",
      "support": 15
    },
    {
      "x": 0,
      "y": -22,
      "z": -2,
      "name": "Wood_Oak_Branch_Long",
      "support": 15,
      "rotation": 4
    },
    {
      "x": 0,
      "y": -21,
      "z": -2,
      "name": "Wood_Oak_Branch_Long",
      "support": 15,
      "rotation": 4
    },
    {
      "x": 0,
      "y": -13,
      "z": -2,
      "name": "Wood_Oak_Branch_Short",
      "rotation": 2
    },
    {
      "x": 0,
      "y": -24,
      "z": -1,
      "name": "Plant_Leaves_Oak",
      "support": 2
    },
    {
      "x": 0,
      "y": -23,
      "z": -1,
      "name": "Plant_Leaves_Oak",
      "support": 15
    },
    {
      "x": 0,
      "y": -22,
      "z": -1,
      "name": "Wood_Oak_Branch_Long",
      "support": 15,
      "rotation": 4
    },
    {
      "x": 0,
      "y": -21,
      "z": -1,
      "name": "Wood_Oak_Branch_Corner",
      "support": 15
    },
    {
      "x": 0,
      "y": -20,
      "z": -1,
      "name": "Wood_Oak_Branch_Long"
    },
    {
      "x": 0,
      "y": -19,
      "z": -1,
      "name": "Wood_Oak_Trunk",
      "support": 15
    },
    {
      "x": 0,
      "y": -18,
      "z": -1,
      "name": "Wood_Oak_Branch_Long"
    },
    {
      "x": 0,
      "y": -17,
      "z": -1,
      "name": "Wood_Oak_Branch_Long"
    },
    {
      "x": 0,
      "y": -16,
      "z": -1,
      "name": "Wood_Oak_Trunk"
    },
    {
      "x": 0,
      "y": -15,
      "z": -1,
      "name": "Wood_Oak_Trunk"
    },
    {
      "x": 0,
      "y": -14,
      "z": -1,
      "name": "Wood_Oak_Trunk"
    },
    {
      "x": 0,
      "y": -13,
      "z": -1,
      "name": "Wood_Oak_Trunk"
    },
    {
      "x": 0,
      "y": -12,
      "z": -1,
      "name": "Wood_Oak_Trunk"
    },
    {
      "x": 0,
      "y": -11,
      "z": -1,
      "name": "Wood_Oak_Branch_Long",
      "support": 15
    },
    {
      "x": 0,
      "y": -10,
      "z": -1,
      "name": "Wood_Oak_Branch_Long"
    },
    {
      "x": 0,
      "y": -9,
      "z": -1,
      "name": "Wood_Oak_Trunk",
      "support": 15
    },
    {
      "x": 0,
      "y": -8,
      "z": -1,
      "name": "Wood_Oak_Branch_Long"
    },
    {
      "x": 0,
      "y": -7,
      "z": -1,
      "name": "Wood_Oak_Branch_Long"
    },
    {
      "x": 0,
      "y": -6,
      "z": -1,
      "name": "Wood_Oak_Trunk"
    },
    {
      "x": 0,
      "y": -5,
      "z": -1,
      "name": "Wood_Oak_Trunk"
    },
    {
      "x": 0,
      "y": -4,
      "z": -1,
      "name": "Wood_Oak_Trunk"
    },
    {
      "x": 0,
      "y": -3,
      "z": -1,
      "name": "Wood_Oak_Trunk"
    },
    {
      "x": 0,
      "y": -2,
      "z": -1,
      "name": "Wood_Oak_Trunk"
    },
    {
      "x": 0,
      "y": -1,
      "z": -1,
      "name": "Wood_Oak_Trunk"
    },
    {
      "x": 0,
      "y": 0,
      "z": -1,
      "name": "Wood_Oak_Trunk"
    },
    {
      "x": 0,
      "y": 1,
      "z": -1,
      "name": "Wood_Oak_Trunk"
    },
    {
      "x": 0,
      "y": -24,
      "z": 0,
      "name": "Plant_Leaves_Oak",
      "support": 2
    },
    {
      "x": 0,
      "y": -23,
      "z": 0,
      "name": "Plant_Leaves_Oak",
      "support": 15
    },
    {
      "x": 0,
      "y": -22,
      "z": 0,
      "name": "Wood_Oak_Trunk",
      "support": 15
    },
    {
      "x": 0,
      "y": -21,
      "z": 0,
      "name": "Wood_Oak_Branch_Long",
      "support": 15
    },
    {
      "x": 0,
      "y": -20,
      "z": 0,
      "name": "Wood_Oak_Branch_Long"
    },
    {
      "x": 0,
      "y": -19,
      "z": 0,
      "name": "Wood_Oak_Trunk"
    },
    {
      "x": 0,
      "y": -18,
      "z": 0,
      "name": "Wood_Oak_Trunk"
    },
    {
      "x": 0,
      "y": -17,
      "z": 0,
      "name": "Wood_Oak_Trunk"
    },
    {
      "x": 0,
      "y": -16,
      "z": 0,
      "name": "Wood_Oak_Trunk"
    },
    {
      "x": 0,
      "y": -15,
      "z": 0,
      "name": "Wood_Oak_Trunk"
    },
    {
      "x": 0,
      "y": -14,
      "z": 0,
      "name": "Wood_Oak_Trunk"
    },
    {
      "x": 0,
      "y": -13,
      "z": 0,
      "name": "Wood_Oak_Trunk"
    },
    {
      "x": 0,
      "y": -12,
      "z": 0,
      "name": "Wood_Oak_Trunk"
    },
    {
      "x": 0,
      "y": -11,
      "z": 0,
      "name": "Wood_Oak_Trunk"
    },
    {
      "x": 0,
      "y": -10,
      "z": 0,
      "name": "Wood_Oak_Trunk"
    },
    {
      "x": 0,
      "y": -9,
      "z": 0,
      "name": "Wood_Oak_Trunk"
    },
    {
      "x": 0,
      "y": -8,
      "z": 0,
      "name": "Wood_Oak_Trunk"
    },
    {
      "x": 0,
      "y": -7,
      "z": 0,
      "name": "Wood_Oak_Trunk",
      "support": 1
    },
    {
      "x": 0,
      "y": -6,
      "z": 0,
      "name": "Wood_Oak_Trunk"
    },
    {
      "x": 0,
      "y": -5,
      "z": 0,
      "name": "Wood_Oak_Trunk"
    },
    {
      "x": 0,
      "y": -4,
      "z": 0,
      "name": "Wood_Oak_Branch_Long"
    },
    {
      "x": 0,
      "y": -3,
      "z": 0,
      "name": "Wood_Oak_Branch_Long"
    },
    {
      "x": 0,
      "y": -2,
      "z": 0,
      "name": "Wood_Oak_Trunk",
      "support": 1
    },
    {
      "x": 0,
      "y": -1,
      "z": 0,
      "name": "Wood_Oak_Trunk"
    },
    {
      "x": 0,
      "y": 0,
      "z": 0,
      "name": "Wood_Oak_Trunk"
    },
    {
      "x": 0,
      "y": -24,
      "z": 1,
      "name": "Plant_Leaves_Oak",
      "support": 2
    },
    {
      "x": 0,
      "y": -23,
      "z": 1,
      "name": "Plant_Leaves_Oak",
      "support": 15
    },
    {
      "x": 0,
      "y": -22,
      "z": 1,
      "name": "Wood_Oak_Branch_Corner",
      "support": 15,
      "rotation": 2
    },
    {
      "x": 0,
      "y": -21,
      "z": 1,
      "name": "Wood_Oak_Branch_Long",
      "support": 15
    },
    {
      "x": 0,
      "y": -20,
      "z": 1,
      "name": "Wood_Oak_Branch_Long",
      "support": 2
    },
    {
      "x": 0,
      "y": -19,
      "z": 1,
      "name": "Wood_Oak_Branch_Long"
    },
    {
      "x": 0,
      "y": -18,
      "z": 1,
      "name": "Wood_Oak_Trunk"
    },
    {
      "x": 0,
      "y": -17,
      "z": 1,
      "name": "Wood_Oak_Trunk"
    },
    {
      "x": 0,
      "y": -16,
      "z": 1,
      "name": "Wood_Oak_Trunk"
    },
    {
      "x": 0,
      "y": -15,
      "z": 1,
      "name": "Wood_Oak_Trunk"
    },
    {
      "x": 0,
      "y": -14,
      "z": 1,
      "name": "Wood_Oak_Trunk"
    },
    {
      "x": 0,
      "y": -13,
      "z": 1,
      "name": "Wood_Oak_Trunk"
    },
    {
      "x": 0,
      "y": -12,
      "z": 1,
      "name": "Wood_Oak_Branch_Corner",
      "support": 15,
      "rotation": 8
    },
    {
      "x": 0,
      "y": -11,
      "z": 1,
      "name": "Wood_Oak_Branch_Corner",
      "support": 15,
      "rotation": 2
    },
    {
      "x": 0,
      "y": -10,
      "z": 1,
      "name": "Wood_Oak_Trunk"
    },
    {
      "x": 0,
      "y": -9,
      "z": 1,
      "name": "Wood_Oak_Trunk"
    },
    {
      "x": 0,
      "y": -8,
      "z": 1,
      "name": "Wood_Oak_Trunk"
    },
    {
      "x": 0,
      "y": -7,
      "z": 1,
      "name": "Wood_Oak_Trunk"
    },
    {
      "x": 0,
      "y": -6,
      "z": 1,
      "name": "Wood_Oak_Trunk"
    },
    {
      "x": 0,
      "y": -5,
      "z": 1,
      "name": "Wood_Oak_Trunk"
    },
    {
      "x": 0,
      "y": -4,
      "z": 1,
      "name": "Wood_Oak_Trunk"
    },
    {
      "x": 0,
      "y": -3,
      "z": 1,
      "name": "Wood_Oak_Trunk"
    },
    {
      "x": 0,
      "y": -2,
      "z": 1,
      "name": "Wood_Oak_Trunk"
    },
    {
      "x": 0,
      "y": -1,
      "z": 1,
      "name": "Wood_Oak_Trunk"
    },
    {
      "x": 0,
      "y": 0,
      "z": 1,
      "name": "Wood_Oak_Trunk"
    },
    {
      "x": 0,
      "y": -24,
      "z": 2,
      "name": "Plant_Leaves_Oak",
      "support": 15
    },
    {
      "x": 0,
      "y": -23,
      "z": 2,
      "name": "Plant_Leaves_Oak",
      "support": 15
    },
    {
      "x": 0,
      "y": -22,
      "z": 2,
      "name": "Wood_Oak_Branch_Long",
      "support": 15,
      "rotation": 4
    },
    {
      "x": 0,
      "y": -18,
      "z": 2,
      "name": "Wood_Oak_Branch_Short"
    },
    {
      "x": 0,
      "y": -12,
      "z": 2,
      "name": "Wood_Oak_Branch_Corner",
      "support": 15
    },
    {
      "x": 0,
      "y": -11,
      "z": 2,
      "name": "Wood_Oak_Branch_Corner",
      "support": 15,
      "rotation": 10
    },
    {
      "x": 0,
      "y": -7,
      "z": 2,
      "name": "Wood_Oak_Branch_Short"
    },
    {
      "x": 0,
      "y": -24,
      "z": 3,
      "name": "Plant_Leaves_Oak",
      "support": 15
    },
    {
      "x": 0,
      "y": -23,
      "z": 3,
      "name": "Plant_Leaves_Oak",
      "support": 15
    },
    {
      "x": 0,
      "y": -22,
      "z": 3,
      "name": "Wood_Oak_Trunk",
      "support": 15,
      "rotation": 4
    },
    {
      "x": 0,
      "y": -24,
      "z": 4,
      "name": "Plant_Leaves_Oak",
      "support": 15
    },
    {
      "x": 0,
      "y": -23,
      "z": 4,
      "name": "Plant_Leaves_Oak",
      "support": 15
    },
    {
      "x": 0,
      "y": -22,
      "z": 4,
      "name": "Wood_Oak_Branch_Long",
      "support": 15,
      "rotation": 4
    },
    {
      "x": 0,
      "y": -23,
      "z": 5,
      "name": "Plant_Leaves_Oak",
      "support": 15
    },
    {
      "x": 0,
      "y": -22,
      "z": 5,
      "name": "Wood_Oak_Branch_Long",
      "support": 15,
      "rotation": 4
    },
    {
      "x": 0,
      "y": -23,
      "z": 6,
      "name": "Plant_Leaves_Oak",
      "support": 15
    },
    {
      "x": 0,
      "y": -22,
      "z": 6,
      "name": "Wood_Oak_Branch_Corner",
      "support": 15
    },
    {
      "x": 0,
      "y": -23,
      "z": 7,
      "name": "Plant_Leaves_Oak",
      "support": 15
    },
    {
      "x": 0,
      "y": -22,
      "z": 7,
      "name": "Plant_Leaves_Oak",
      "support": 15
    },
    {
      "x": 1,
      "y": -23,
      "z": -7,
      "name": "Plant_Leaves_Oak",
      "support": 15
    },
    {
      "x": 1,
      "y": -23,
      "z": -6,
      "name": "Plant_Leaves_Oak",
      "support": 15
    },
    {
      "x": 1,
      "y": -22,
      "z": -6,
      "name": "Plant_Leaves_Oak",
      "support": 15
    },
    {
      "x": 1,
      "y": -23,
      "z": -5,
      "name": "Plant_Leaves_Oak",
      "support": 15
    },
    {
      "x": 1,
      "y": -21,
      "z": -5,
      "name": "Plant_Leaves_Oak",
      "support": 15
    },
    {
      "x": 1,
      "y": -24,
      "z": -4,
      "name": "Plant_Leaves_Oak",
      "support": 15
    },
    {
      "x": 1,
      "y": -23,
      "z": -4,
      "name": "Plant_Leaves_Oak",
      "support": 15
    },
    {
      "x": 1,
      "y": -21,
      "z": -4,
      "name": "Plant_Leaves_Oak",
      "support": 15
    },
    {
      "x": 1,
      "y": -20,
      "z": -4,
      "name": "Plant_Leaves_Oak",
      "support": 15
    },
    {
      "x": 1,
      "y": -24,
      "z": -3,
      "name": "Plant_Leaves_Oak",
      "support": 15
    },
    {
      "x": 1,
      "y": -23,
      "z": -3,
      "name": "Plant_Leaves_Oak"
    },
    {
      "x": 1,
      "y": -22,
      "z": -3,
      "name": "Wood_Oak_Branch_Long",
      "support": 15,
      "rotation": 5
    },
    {
      "x": 1,
      "y": -21,
      "z": -3,
      "name": "Plant_Leaves_Oak",
      "support": 15
    },
    {
      "x": 1,
      "y": -24,
      "z": -2,
      "name": "Plant_Leaves_Oak",
      "support": 2
    },
    {
      "x": 1,
      "y": -23,
      "z": -2,
      "name": "Plant_Leaves_Oak",
      "support": 2
    },
    {
      "x": 1,
      "y": -24,
      "z": -1,
      "name": "Plant_Leaves_Oak",
      "support": 3
    },
    {
      "x": 1,
      "y": -23,
      "z": -1,
      "name": "Plant_Leaves_Oak",
      "support": 2
    },
    {
      "x": 1,
      "y": -17,
      "z": -1,
      "name": "Plant_Leaves_Oak"
    },
    {
      "x": 1,
      "y": -16,
      "z": -1,
      "name": "Wood_Oak_Branch_Short",
      "rotation": 2
    },
    {
      "x": 1,
      "y": -3,
      "z": -1,
      "name": "Wood_Oak_Branch_Short",
      "rotation": 1
    },
    {
      "x": 1,
      "y": -24,
      "z": 0,
      "name": "Plant_Leaves_Oak",
      "support": 2
    },
    {
      "x": 1,
      "y": -23,
      "z": 0,
      "name": "Plant_Leaves_Oak",
      "support": 15
    },
    {
      "x": 1,
      "y": -22,
      "z": 0,
      "name": "Wood_Oak_Branch_Corner",
      "support": 15,
      "rotation": 1
    },
    {
      "x": 1,
      "y": -21,
      "z": 0,
      "name": "Wood_Oak_Branch_Corner",
      "support": 15,
      "rotation": 3
    },
    {
      "x": 1,
      "y": -20,
      "z": 0,
      "name": "Wood_Oak_Branch_Long",
      "support": 15
    },
    {
      "x": 1,
      "y": -19,
      "z": 0,
      "name": "Wood_Oak_Branch_Long"
    },
    {
      "x": 1,
      "y": -18,
      "z": 0,
      "name": "Wood_Oak_Trunk"
    },
    {
      "x": 1,
      "y": -17,
      "z": 0,
      "name": "Wood_Oak_Trunk"
    },
    {
      "x": 1,
      "y": -16,
      "z": 0,
      "name": "Wood_Oak_Trunk"
    },
    {
      "x": 1,
      "y": -15,
      "z": 0,
      "name": "Wood_Oak_Trunk"
    },
    {
      "x": 1,
      "y": -14,
      "z": 0,
      "name": "Wood_Oak_Trunk"
    },
    {
      "x": 1,
      "y": -13,
      "z": 0,
      "name": "Wood_Oak_Trunk"
    },
    {
      "x": 1,
      "y": -12,
      "z": 0,
      "name": "Wood_Oak_Trunk"
    },
    {
      "x": 1,
      "y": -11,
      "z": 0,
      "name": "Wood_Oak_Trunk"
    },
    {
      "x": 1,
      "y": -10,
      "z": 0,
      "name": "Wood_Oak_Trunk"
    },
    {
      "x": 1,
      "y": -9,
      "z": 0,
      "name": "Wood_Oak_Trunk"
    },
    {
      "x": 1,
      "y": -8,
      "z": 0,
      "name": "Wood_Oak_Trunk"
    },
    {
      "x": 1,
      "y": -7,
      "z": 0,
      "name": "Wood_Oak_Trunk"
    },
    {
      "x": 1,
      "y": -6,
      "z": 0,
      "name": "Wood_Oak_Trunk"
    },
    {
      "x": 1,
      "y": -5,
      "z": 0,
      "name": "Wood_Oak_Trunk"
    },
    {
      "x": 1,
      "y": -4,
      "z": 0,
      "name": "Wood_Oak_Trunk"
    },
    {
      "x": 1,
      "y": -3,
      "z": 0,
      "name": "Wood_Oak_Trunk"
    },
    {
      "x": 1,
      "y": -2,
      "z": 0,
      "name": "Wood_Oak_Trunk"
    },
    {
      "x": 1,
      "y": -1,
      "z": 0,
      "name": "Wood_Oak_Trunk"
    },
    {
      "x": 1,
      "y": 0,
      "z": 0,
      "name": "Wood_Oak_Trunk"
    },
    {
      "x": 1,
      "y": 1,
      "z": 0,
      "name": "Wood_Oak_Trunk"
    },
    {
      "x": 1,
      "y": 2,
      "z": 0,
      "name": "Wood_Oak_Trunk"
    },
    {
      "x": 1,
      "y": 3,
      "z": 0,
      "name": "Wood_Oak_Trunk"
    },
    {
      "x": 1,
      "y": -24,
      "z": 1,
      "name": "Plant_Leaves_Oak",
      "support": 2
    },
    {
      "x": 1,
      "y": -23,
      "z": 1,
      "name": "Plant_Leaves_Oak",
      "support": 15
    },
    {
      "x": 1,
      "y": -17,
      "z": 1,
      "name": "Wood_Oak_Branch_Corner"
    },
    {
      "x": 1,
      "y": -16,
      "z": 1,
      "name": "Plant_Leaves_Oak"
    },
    {
      "x": 1,
      "y": -15,
      "z": 1,
      "name": "Plant_Leaves_Oak"
    },
    {
      "x": 1,
      "y": -24,
      "z": 2,
      "name": "Plant_Leaves_Oak",
      "support": 15
    },
    {
      "x": 1,
      "y": -23,
      "z": 2,
      "name": "Plant_Leaves_Oak",
      "support": 15
    },
    {
      "x": 1,
      "y": -24,
      "z": 3,
      "name": "Plant_Leaves_Oak",
      "support": 15
    },
    {
      "x": 1,
      "y": -23,
      "z": 3,
      "name": "Plant_Leaves_Oak",
      "support": 15
    },
    {
      "x": 1,
      "y": -22,
      "z": 3,
      "name": "Wood_Oak_Branch_Long",
      "support": 15,
      "rotation": 5
    },
    {
      "x": 1,
      "y": -23,
      "z": 4,
      "name": "Plant_Leaves_Oak",
      "support": 15
    },
    {
      "x": 1,
      "y": -23,
      "z": 5,
      "name": "Plant_Leaves_Oak",
      "support": 15
    },
    {
      "x": 1,
      "y": -22,
      "z": 5,
      "name": "Plant_Leaves_Oak",
      "support": 15
    },
    {
      "x": 1,
      "y": -23,
      "z": 6,
      "name": "Plant_Leaves_Oak",
      "support": 15
    },
    {
      "x": 1,
      "y": -22,
      "z": 6,
      "name": "Plant_Leaves_Oak",
      "support": 15
    },
    {
      "x": 1,
      "y": -23,
      "z": 7,
      "name": "Plant_Leaves_Oak",
      "support": 15
    },
    {
      "x": 1,
      "y": -22,
      "z": 7,
      "name": "Plant_Leaves_Oak",
      "support": 15
    },
    {
      "x": 1,
      "y": -21,
      "z": 7,
      "name": "Plant_Leaves_Oak",
      "support": 15
    },
    {
      "x": 2,
      "y": -23,
      "z": -7,
      "name": "Plant_Leaves_Oak",
      "support": 15
    },
    {
      "x": 2,
      "y": -22,
      "z": -7,
      "name": "Plant_Leaves_Oak",
      "support": 15
    },
    {
      "x": 2,
      "y": -21,
      "z": -7,
      "name": "Plant_Leaves_Oak",
      "support": 15
    },
    {
      "x": 2,
      "y": -23,
      "z": -6,
      "name": "Plant_Leaves_Oak",
      "support": 15
    },
    {
      "x": 2,
      "y": -22,
      "z": -6,
      "name": "Wood_Oak_Branch_Corner",
      "support": 15,
      "rotation": 2
    },
    {
      "x": 2,
      "y": -23,
      "z": -5,
      "name": "Plant_Leaves_Oak",
      "support": 15
    },
    {
      "x": 2,
      "y": -22,
      "z": -5,
      "name": "Wood_Oak_Branch_Long",
      "support": 15,
      "rotation": 4
    },
    {
      "x": 2,
      "y": -23,
      "z": -4,
      "name": "Plant_Leaves_Oak",
      "support": 15
    },
    {
      "x": 2,
      "y": -22,
      "z": -4,
      "name": "Wood_Oak_Branch_Long",
      "support": 15,
      "rotation": 4
    },
    {
      "x": 2,
      "y": -24,
      "z": -3,
      "name": "Plant_Leaves_Oak",
      "support": 15
    },
    {
      "x": 2,
      "y": -23,
      "z": -3,
      "name": "Plant_Leaves_Oak"
    },
    {
      "x": 2,
      "y": -22,
      "z": -3,
      "name": "Wood_Oak_Trunk",
      "support": 15,
      "rotation": 5
    },
    {
      "x": 2,
      "y": -24,
      "z": -2,
      "name": "Plant_Leaves_Oak",
      "support": 15
    },
    {
      "x": 2,
      "y": -23,
      "z": -2,
      "name": "Plant_Leaves_Oak",
      "support": 1
    },
    {
      "x": 2,
      "y": -22,
      "z": -2,
      "name": "Plant_Leaves_Oak",
      "support": 15
    },
    {
      "x": 2,
      "y": -24,
      "z": -1,
      "name": "Plant_Leaves_Oak",
      "support": 2
    },
    {
      "x": 2,
      "y": -23,
      "z": -1,
      "name": "Plant_Leaves_Oak",
      "support": 2
    },
    {
      "x": 2,
      "y": -24,
      "z": 0,
      "name": "Plant_Leaves_Oak",
      "support": 2
    },
    {
      "x": 2,
      "y": -23,
      "z": 0,
      "name": "Plant_Leaves_Oak",
      "support": 15
    },
    {
      "x": 2,
      "y": -21,
      "z": 0,
      "name": "Wood_Oak_Branch_Long",
      "support": 15,
      "rotation": 5
    },
    {
      "x": 2,
      "y": -18,
      "z": 0,
      "name": "Wood_Oak_Branch_Short",
      "support": 2,
      "rotation": 1
    },
    {
      "x": 2,
      "y": -12,
      "z": 0,
      "name": "Wood_Oak_Branch_Short",
      "rotation": 1
    },
    {
      "x": 2,
      "y": -24,
      "z": 1,
      "name": "Plant_Leaves_Oak",
      "support": 2
    },
    {
      "x": 2,
      "y": -23,
      "z": 1,
      "name": "Plant_Leaves_Oak",
      "support": 15
    },
    {
      "x": 2,
      "y": -24,
      "z": 2,
      "name": "Plant_Leaves_Oak",
      "support": 2
    },
    {
      "x": 2,
      "y": -23,
      "z": 2,
      "name": "Plant_Leaves_Oak",
      "support": 15
    },
    {
      "x": 2,
      "y": -24,
      "z": 3,
      "name": "Plant_Leaves_Oak",
      "support": 2
    },
    {
      "x": 2,
      "y": -23,
      "z": 3,
      "name": "Plant_Leaves_Oak",
      "support": 15
    },
    {
      "x": 2,
      "y": -22,
      "z": 3,
      "name": "Wood_Oak_Branch_Long",
      "support": 15,
      "rotation": 5
    },
    {
      "x": 2,
      "y": -24,
      "z": 4,
      "name": "Plant_Leaves_Oak",
      "support": 15
    },
    {
      "x": 2,
      "y": -23,
      "z": 4,
      "name": "Plant_Leaves_Oak",
      "support": 15
    },
    {
      "x": 2,
      "y": -23,
      "z": 5,
      "name": "Plant_Leaves_Oak",
      "support": 15
    },
    {
      "x": 2,
      "y": -23,
      "z": 6,
      "name": "Plant_Leaves_Oak",
      "support": 15
    },
    {
      "x": 3,
      "y": -23,
      "z": -7,
      "name": "Plant_Leaves_Oak",
      "support": 15
    },
    {
      "x": 3,
      "y": -22,
      "z": -7,
      "name": "Plant_Leaves_Oak",
      "support": 15
    },
    {
      "x": 3,
      "y": -23,
      "z": -6,
      "name": "Plant_Leaves_Oak",
      "support": 15
    },
    {
      "x": 3,
      "y": -22,
      "z": -6,
      "name": "Plant_Leaves_Oak",
      "support": 15
    },
    {
      "x": 3,
      "y": -23,
      "z": -5,
      "name": "Plant_Leaves_Oak",
      "support": 15
    },
    {
      "x": 3,
      "y": -22,
      "z": -5,
      "name": "Plant_Leaves_Oak",
      "support": 15
    },
    {
      "x": 3,
      "y": -23,
      "z": -4,
      "name": "Plant_Leaves_Oak",
      "support": 15
    },
    {
      "x": 3,
      "y": -23,
      "z": -3,
      "name": "Plant_Leaves_Oak",
      "support": 15
    },
    {
      "x": 3,
      "y": -22,
      "z": -3,
      "name": "Plant_Leaves_Oak",
      "support": 15
    },
    {
      "x": 3,
      "y": -23,
      "z": -2,
      "name": "Plant_Leaves_Oak"
    },
    {
      "x": 3,
      "y": -22,
      "z": -2,
      "name": "Wood_Oak_Branch_Corner",
      "support": 15,
      "rotation": 2
    },
    {
      "x": 3,
      "y": -21,
      "z": -2,
      "name": "Plant_Leaves_Oak",
      "support": 15
    },
    {
      "x": 3,
      "y": -24,
      "z": -1,
      "name": "Plant_Leaves_Oak",
      "support": 1
    },
    {
      "x": 3,
      "y": -23,
      "z": -1,
      "name": "Plant_Leaves_Oak"
    },
    {
      "x": 3,
      "y": -22,
      "z": -1,
      "name": "Wood_Oak_Branch_Long",
      "support": 15,
      "rotation": 4
    },
    {
      "x": 3,
      "y": -24,
      "z": 0,
      "name": "Plant_Leaves_Oak",
      "support": 1
    },
    {
      "x": 3,
      "y": -23,
      "z": 0,
      "name": "Plant_Leaves_Oak"
    },
    {
      "x": 3,
      "y": -22,
      "z": 0,
      "name": "Wood_Oak_Branch_Corner",
      "support": 15
    },
    {
      "x": 3,
      "y": -21,
      "z": 0,
      "name": "Wood_Oak_Trunk",
      "support": 15,
      "rotation": 5
    },
    {
      "x": 3,
      "y": -24,
      "z": 1,
      "name": "Plant_Leaves_Oak",
      "support": 2
    },
    {
      "x": 3,
      "y": -23,
      "z": 1,
      "name": "Plant_Leaves_Oak",
      "support": 15
    },
    {
      "x": 3,
      "y": -23,
      "z": 2,
      "name": "Plant_Leaves_Oak",
      "support": 15
    },
    {
      "x": 3,
      "y": -23,
      "z": 3,
      "name": "Plant_Leaves_Oak",
      "support": 15
    },
    {
      "x": 3,
      "y": -22,
      "z": 3,
      "name": "Wood_Oak_Branch_Corner",
      "support": 15,
      "rotation": 1
    },
    {
      "x": 3,
      "y": -23,
      "z": 4,
      "name": "Plant_Leaves_Oak",
      "support": 15
    },
    {
      "x": 3,
      "y": -22,
      "z": 4,
      "name": "Plant_Leaves_Oak",
      "support": 15
    },
    {
      "x": 3,
      "y": -23,
      "z": 5,
      "name": "Plant_Leaves_Oak",
      "support": 15
    },
    {
      "x": 4,
      "y": -23,
      "z": -6,
      "name": "Plant_Leaves_Oak",
      "support": 15
    },
    {
      "x": 4,
      "y": -23,
      "z": -5,
      "name": "Plant_Leaves_Oak",
      "support": 15
    },
    {
      "x": 4,
      "y": -23,
      "z": -4,
      "name": "Plant_Leaves_Oak",
      "support": 15
    },
    {
      "x": 4,
      "y": -23,
      "z": -3,
      "name": "Plant_Leaves_Oak",
      "support": 15
    },
    {
      "x": 4,
      "y": -23,
      "z": -2,
      "name": "Plant_Leaves_Oak",
      "support": 15
    },
    {
      "x": 4,
      "y": -22,
      "z": -2,
      "name": "Plant_Leaves_Oak",
      "support": 15
    },
    {
      "x": 4,
      "y": -23,
      "z": -1,
      "name": "Plant_Leaves_Oak",
      "support": 1
    },
    {
      "x": 4,
      "y": -22,
      "z": -1,
      "name": "Plant_Leaves_Oak",
      "support": 15
    },
    {
      "x": 4,
      "y": -23,
      "z": 0,
      "name": "Plant_Leaves_Oak",
      "support": 1
    },
    {
      "x": 4,
      "y": -21,
      "z": 0,
      "name": "Wood_Oak_Branch_Long",
      "support": 15,
      "rotation": 5
    },
    {
      "x": 4,
      "y": -23,
      "z": 1,
      "name": "Plant_Leaves_Oak",
      "support": 2
    },
    {
      "x": 4,
      "y": -23,
      "z": 2,
      "name": "Plant_Leaves_Oak",
      "support": 15
    },
    {
      "x": 4,
      "y": -23,
      "z": 3,
      "name": "Plant_Leaves_Oak",
      "support": 15
    },
    {
      "x": 4,
      "y": -22,
      "z": 3,
      "name": "Plant_Leaves_Oak",
      "support": 15
    },
    {
      "x": 4,
      "y": -21,
      "z": 3,
      "name": "Plant_Leaves_Oak",
      "support": 15
    },
    {
      "x": 4,
      "y": -23,
      "z": 4,
      "name": "Plant_Leaves_Oak",
      "support": 15
    },
    {
      "x": 4,
      "y": -22,
      "z": 4,
      "name": "Plant_Leaves_Oak",
      "support": 15
    },
    {
      "x": 5,
      "y": -23,
      "z": -3,
      "name": "Plant_Leaves_Oak",
      "support": 15
    },
    {
      "x": 5,
      "y": -23,
      "z": -2,
      "name": "Plant_Leaves_Oak",
      "support": 15
    },
    {
      "x": 5,
      "y": -23,
      "z": -1,
      "name": "Plant_Leaves_Oak",
      "support": 15
    },
    {
      "x": 5,
      "y": -22,
      "z": -1,
      "name": "Plant_Leaves_Oak",
      "support": 15
    },
    {
      "x": 5,
      "y": -21,
      "z": -1,
      "name": "Plant_Leaves_Oak",
      "support": 15
    },
    {
      "x": 5,
      "y": -23,
      "z": 0,
      "name": "Plant_Leaves_Oak",
      "support": 2
    },
    {
      "x": 5,
      "y": -22,
      "z": 0,
      "name": "Plant_Leaves_Oak",
      "support": 15
    },
    {
      "x": 5,
      "y": -21,
      "z": 0,
      "name": "Wood_Oak_Branch_Long",
      "support": 15,
      "rotation": 5
    },
    {
      "x": 5,
      "y": -23,
      "z": 1,
      "name": "Plant_Leaves_Oak",
      "support": 2
    },
    {
      "x": 5,
      "y": -22,
      "z": 1,
      "name": "Plant_Leaves_Oak",
      "support": 15
    },
    {
      "x": 5,
      "y": -23,
      "z": 2,
      "name": "Plant_Leaves_Oak",
      "support": 2
    },
    {
      "x": 5,
      "y": -22,
      "z": 2,
      "name": "Plant_Leaves_Oak",
      "support": 15
    },
    {
      "x": 6,
      "y": -23,
      "z": -2,
      "name": "Plant_Leaves_Oak",
      "support": 15
    },
    {
      "x": 6,
      "y": -22,
      "z": -2,
      "name": "Plant_Leaves_Oak",
      "support": 15
    },
    {
      "x": 6,
      "y": -22,
      "z": -1,
      "name": "Plant_Leaves_Oak",
      "support": 15
    },
    {
      "x": 6,
      "y": -21,
      "z": -1,
      "name": "Plant_Leaves_Oak",
      "support": 15
    },
    {
      "x": 6,
      "y": -22,
      "z": 0,
      "name": "Plant_Leaves_Oak",
      "support": 15
    },
    {
      "x": 6,
      "y": -21,
      "z": 0,
      "name": "Wood_Oak_Branch_Corner",
      "support": 15,
      "rotation": 1
    },
    {
      "x": 6,
      "y": -20,
      "z": 0,
      "name": "Plant_Leaves_Oak",
      "support": 15
    },
    {
      "x": 6,
      "y": -19,
      "z": 0,
      "name": "Plant_Leaves_Oak",
      "support": 15
    },
    {
      "x": 6,
      "y": -22,
      "z": 1,
      "name": "Plant_Leaves_Oak",
      "support": 15
    },
    {
      "x": 6,
      "y": -21,
      "z": 1,
      "name": "Plant_Leaves_Oak",
      "support": 15
    },
    {
      "x": 7,
      "y": -21,
      "z": -1,
      "name": "Plant_Leaves_Oak",
      "support": 15
    },
    {
      "x": 7,
      "y": -21,
      "z": 0,
      "name": "Plant_Leaves_Oak",
      "support": 15
    }
  ]
}